Workbook

Sheet 사용안내
A1: 전공의·인턴 파견 모니터링 사용 안내
A3: [시트 구분] — 탭 색: 파랑=입력, 초록=출력(자동, 입력 금지), 회색=설정
A4: • 입력_기본자료 / 입력_인턴근무계획 / 입력_파견수련계획: 각 업로드 양식을 그대로 붙여넣는 시트 (오른쪽 초록 머리글 열은 자동 계산)
A5: • 입력_구리근무자명단: 구리병원이 보내는 '전공의(모.자 파견) 근무자 명단'을 양식 그대로(A1부터) 붙여넣는 시트
A6: • 입력_전공의명단: 사번·입사장소·비고만 입력 (파란 글씨 칸). 나머지 열은 자동
A7: • 출력_서울급여: 급여 기준월(기본=이번 달)에 서울병원이 급여를 지급할 사람 목록과 판정 근거, 판정 불가(⚠) 목록
A8: • 출력_구리근무자: 구리 근무자명단을 급여 기준월로 해석한 결과(이름·과·근무일·구리독자)와 전공의명단 연결 상태
A9: • 출력_요약 / 출력_인턴현황: 집계·현황 (자동)
A10: • 설정_코드표: 병원·진료과·파견근거·약칭 목록, 설정값(급여 기준월·15일 기준·종료 임박 기준)
A12: [전체 흐름]
A13: 1) 기본자료 2) 인턴근무계획 3) 파견수련계획 — 세 시트에 각 양식 그대로 붙여넣기 4) 전공의명단에 사번·입사장소만 입력 5) 출력 시트(서울급여·요약·인턴현황)에서 확인
A15: [기본자료 업로드]
... A64: • 개인정보(생년월일·면허번호 등)가 포함되므로 파일 암호 설정과 접근 권한 관리를 권장합니다.

Sheet 입력_기본자료
A1: 현재근무 여부 | B1: 사번 | C1: 이름 | D1: 수련과목 | E1: 연차 | F1: 근무지 | G1: 수련개시일 | H1: 전공의등록번호 | I1: 의사면허번호 | J1: 성별 | K1: 생년월일 | L1: 비고
A2: 재직 | B2: 2261212 | C2: 김ㅇㅇ | D2: 가정의학과 | E2: 레지던트1 | F2: 서울 | G2: 20260301 | H2: 11-1111 | I2: 111111 | J2: 여 | K2: 19999999
A3: 재직 | B3: 2261213 | C3: 이ㅇㅇ | D3: 내과 | E3: 레지던트2 | F3: 서울 | G3: 20250301 | H3: 11-1112 | I3: 111112 | J3: 남 | K3: 19950702
A4: 재직 | B4: 2261214 | C4: 박ㅇㅇ | D4: 내과 | E4: 레지던트3 | F4: 서울 | G4: 20240301 | H4: 21-1111 | I4: 111113 | J4: 여 | K4: 19970125
A5: 재직 | B5: 2261215 | C5: 최ㅇㅇ | D5: 산부인과 | E5: 레지던트3 | F5: 서울 | G5: 20240301 | H5: 11-1114 | I5: 111114 | J5: 남 | K5: 19961109
A6: 재직 | B6: 2261216 | C6: 정ㅇㅇ | D6: 마취통증의학과 | E6: 레지던트2 | F6: 구리 | G6: 20250301 | H6: 11-1115 | I6: 111115 | J6: 여 | K6: 19980530
A7: 재직 | B7: 222222 | C7: 김ㅇㅇ | D7: 인턴 | E7: 인턴 | F7: 서울 | G7: 20260301 | H7: 22-2222 | I7: 222222 | J7: 여 | K7: 19990101
A8: 재직 | B8: 222223 | C8: 이ㅇㅇ | D8: 인턴 | E8: 인턴 | F8: 서울 | G8: 20260301 | H8: 22-2223 | I8: 222223 | J8: 남 | K8: 19990202
A9: 재직 | B9: 222224 | C9: 박ㅇㅇ | D9: 인턴 | E9: 인턴 | F9: 구리 | G9: 20260301 | H9: 22-2224 | I9: 222224 | J9: 남 | K9: 19990303

Sheet 입력_인턴근무계획
B1: 2026년도 하반기 인턴근무계획표(9~2월) | M1: ↓ 자동 정규화 (수정 금지) — '병원 진료과'로 통일, 인식 불가는 ⚠ 표시
B2: 순번 | C2: 이름 | D2: 사번 | E2: 9월 | F2: 10월 | G2: 11월 | H2: 12월 | I2: 1월 | J2: 2월 | K2: 비고 | M2: =TRIM(E$2&"")&" 정규화" | N2: =TRIM(F$2&"")&" 정규화" | O2: =TRIM(G$2&"")&" 정규화" | P2: =TRIM(H$2&"")&" 정규화" | Q2: =TRIM(I$2&"")&" 정규화" | R2: =TRIM(J$2&"")&" 정규화" | S2: 입사일(비고) | T2: 입력오류(건)
B3: 1 | C3: 김ㅇㅇ | D3: 222222 | E3: 구리 안과 | F3: 구리 내과 | G3: 서울 핵방 | H3: 서울 재활의학과 | I3: 제주 산부 | J3: 서울 소아과 | K3: 2026.03 | M3: =IFERROR(IF(TRIM(E3&"")="","",IF(AND(ISNUMBER(FIND(" ",TRIM(E3&""))),ISNUMBER(MATCH(LEFT(TRIM(E3&""),FIND(" ",TRIM(E3&""))-1),설정_코드표!$J$2:$J$101,0)),ISNUMBER(MATCH(TRIM(RIGHT(SUBSTITUTE(TRIM(E3&"")," ",REPT(" ",60)),60)),설정_코드표!$F$2:$F$101,0))),INDEX(설정_코드표!$K$2:$K$101,MATCH(LEFT(TRIM(E3&""),FIND(" ",TRIM(E3&""))-1),설정_코드표!$J$2:$J$101,0))&" "&INDEX(설정_코드표!$G$2:$G$101,MATCH(TRIM(RIGHT(SUBSTITUTE(TRIM(E3&"")," ",REPT(" ",60)),60)),설정_코드표!$F$2:$F$101,0)),"⚠"&TRIM(E3&""))),"⚠"&TRIM(E3&"")) | N3: =IFERROR(IF(TRIM(F3&"")="","",IF(AND(ISNUMBER(FIND(" ",TRIM(F3&""))),ISNUMBER(MATCH(LEFT(TRIM(F3&""),FIND(" ",TRIM(F3&""))-1),설정_코드표!$J$2:$J$101,0)),ISNUMBER(MATCH(TRIM(RIGHT(SUBSTITUTE(TRIM(F3&"")," ",REPT(" ",60)),60)),설정_코드표!$F$2:$F$101,0))),INDEX(설정_코드표!$K$2:$K$101,MATCH(LEFT(TRIM(F3&""),FIND(" ",TRIM(F3&""))-1),설정_코드표!$J$2:$J$101,0))&" "&INDEX(설정_코드표!$G$2:$G$101,MATCH(TRIM(RIGHT(SUBSTITUTE(TRIM(F3&"")," ",REPT(" ",60)),60)),설정_코드표!$F$2:$F$101,0)),"⚠"&TRIM(F3&""))),"⚠"&TRIM(F3&"")) | O3: =IFERROR(IF(TRIM(G3&"")="","",IF(AND(ISNUMBER(FIND(" ",TRIM(G3&""))),ISNUMBER(MATCH(LEFT(TRIM(G3&""),FIND(" ",TRIM(G3&""))-1),설정_코드표!$J$2:$J$101,0)),ISNUMBER(MATCH(TRIM(RIGHT(SUBSTITUTE(TRIM(G3&"")," ",REPT(" ",60)),60)),설정_코드표!$F$2:$F$101,0))),INDEX(설정_코드표!$K$2:$K$101,MATCH(LEFT(TRIM(G3&""),FIND(" ",TRIM(G3&""))-1),설정_코드표!$J$2:$J$101,0))&" "&INDEX(설정_코드표!$G$2:$G$101,MATCH(TRIM(RIGHT(SUBSTITUTE(TRIM(G3&"")," ",REPT(" ",60)),60)),설정_코드표!$F$2:$F$101,0)),"⚠"&TRIM(G3&""))),"⚠"&TRIM(G3&"")) | P3: =IFERROR(IF(TRIM(H3&"")="","",IF(AND(ISNUMBER(FIND(" ",TRIM(H3&""))),ISNUMBER(MATCH(LEFT(TRIM(H3&""),FIND(" ",TRIM(H3&""))-1),설정_코드표!$J$2:$J$101,0)),ISNUMBER(MATCH(TRIM(RIGHT(SUBSTITUTE(TRIM(H3&"")," ",REPT(" ",60)),60)),설정_코드표!$F$2:$F$101,0))),INDEX(설정_코드표!$K$2:$K$101,MATCH(LEFT(TRIM(H3&""),FIND(" ",TRIM(H3&""))-1),설정_코드표!$J$2:$J$101,0))&" "&INDEX(설정_코드표!$G$2:$G$101,MATCH(TRIM(RIGHT(SUBSTITUTE(TRIM(H3&"")," ",REPT(" ",60)),60)),설정_코드표!$F$2:$F$101,0)),"⚠"&TRIM(H3&""))),"⚠"&TRIM(H3&"")) | Q3: =IFERROR(IF(TRIM(I3&"")="","",IF(AND(ISNUMBER(FIND(" ",TRIM(I3&""))),ISNUMBER(MATCH(LEFT(TRIM(I3&""),FIND(" ",TRIM(I3&""))-1),설정_코드표!$J$2:$J$101,0)),ISNUMBER(MATCH(TRIM(RIGHT(SUBSTITUTE(TRIM(I3&"")," ",REPT(" ",60)),60)),설정_코드표!$F$2:$F$101,0))),INDEX(설정_코드표!$K$2:$K$101,MATCH(LEFT(TRIM(I3&""),FIND(" ",TRIM(I3&""))-1),설정_코드표!$J$2:$J$101,0))&" "&INDEX(설정_코드표!$G$2:$G$101,MATCH(TRIM(RIGHT(SUBSTITUTE(TRIM(I3&"")," ",REPT(" ",60)),60)),설정_코드표!$F$2:$F$101,0)),"⚠"&TRIM(I3&""))),"⚠"&TRIM(I3&"")) | R3: =IFERROR(IF(TRIM(J3&"")="","",IF(AND(ISNUMBER(FIND(" ",TRIM(J3&""))),ISNUMBER(MATCH(LEFT(TRIM(J3&""),FIND(" ",TRIM(J3&""))-1),설정_코드표!$J$2:$J$101,0)),ISNUMBER(MATCH(TRIM(RIGHT(SUBSTITUTE(TRIM(J3&"")," ",REPT(" ",60)),60)),설정_코드표!$F$2:$F$101,0))),INDEX(설정_코드표!$K$2:$K$101,MATCH(LEFT(TRIM(J3&""),FIND(" ",TRIM(J3&""))-1),설정_코드표!$J$2:$J$101,0))&" "&INDEX(설정_코드표!$G$2:$G$101,MATCH(TRIM(RIGHT(SUBSTITUTE(TRIM(J3&"")," ",REPT(" ",60)),60)),설정_코드표!$F$2:$F$101,0)),"⚠"&TRIM(J3&""))),"⚠"&TRIM(J3&"")) | S3: =IF(K3="","",IFERROR(IF(AND(ROUND((VALUE(K3&"")-INT(VALUE(K3&"")))*100,0)>=1,ROUND((VALUE(K3&"")-INT(VALUE(K3&"")))*100,0)<=12,INT(VALUE(K3&""))>=1900),DATE(INT(VALUE(K3&"")),ROUND((VALUE(K3&"")-INT(VALUE(K3&"")))*100,0),1),K3&""),K3&"")) | T3: =COUNTIF(M3:R3,"⚠*")
B4: 2 | C4: 이ㅇㅇ | D4: 222223 | E4: 서울 내과 | F4: 서울 외과 | G4: 구리 통합 | H4: 인천 산부인과 | I4: 제주 에스중앙 내과 | J4: 서울 가정의학과 | K4: 2026.03 | M4: =IFERROR(IF(TRIM(E4&"")="","",IF(AND(ISNUMBER(FIND(" ",TRIM(E4&""))),ISNUMBER(MATCH(LEFT(TRIM(E4&""),FIND(" ",TRIM(E4&""))-1),설정_코드표!$J$2:$J$101,0)),ISNUMBER(MATCH(TRIM(RIGHT(SUBSTITUTE(TRIM(E4&"")," ",REPT(" ",60)),60)),설정_코드표!$F$2:$F$101,0))),INDEX(설정_코드표!$K$2:$K$101,MATCH(LEFT(TRIM(E4&""),FIND(" ",TRIM(E4&""))-1),설정_코드표!$J$2:$J$101,0))&" "&INDEX(설정_코드표!$G$2:$G$101,MATCH(TRIM(RIGHT(SUBSTITUTE(TRIM(E4&"")," ",REPT(" ",60)),60)),설정_코드표!$F$2:$F$101,0)),"⚠"&TRIM(E4&""))),"⚠"&TRIM(E4&"")) | N4: =IFERROR(IF(TRIM(F4&"")="","",IF(AND(ISNUMBER(FIND(" ",TRIM(F4&""))),ISNUMBER(MATCH(LEFT(TRIM(F4&""),FIND(" ",TRIM(F4&""))-1),설정_코드표!$J$2:$J$101,0)),ISNUMBER(MATCH(TRIM(RIGHT(SUBSTITUTE(TRIM(F4&"")," ",REPT(" ",60)),60)),설정_코드표!$F$2:$F$101,0))),INDEX(설정_코드표!$K$2:$K$101,MATCH(LEFT(TRIM(F4&""),FIND(" ",TRIM(F4&""))-1),설정_코드표!$J$2:$J$101,0))&" "&INDEX(설정_코드표!$G$2:$G$101,MATCH(TRIM(RIGHT(SUBSTITUTE(TRIM(F4&"")," ",REPT(" ",60)),60)),설정_코드표!$F$2:$F$101,0)),"⚠"&TRIM(F4&""))),"⚠"&TRIM(F4&"")) | O4: =IFERROR(IF(TRIM(G4&"")="","",IF(AND(ISNUMBER(FIND(" ",TRIM(G4&""))),ISNUMBER(MATCH(LEFT(TRIM(G4&""),FIND(" ",TRIM(G4&""))-1),설정_코드표!$J$2:$J$101,0)),ISNUMBER(MATCH(TRIM(RIGHT(SUBSTITUTE(TRIM(G4&"")," ",REPT(" ",60)),60)),설정_코드표!$F$2:$F$101,0))),INDEX(설정_코드표!$K$2:$K$101,MATCH(LEFT(TRIM(G4&""),FIND(" ",TRIM(G4&""))-1),설정_코드표!$J$2:$J$101,0))&" "&INDEX(설정_코드표!$G$2:$G$101,MATCH(TRIM(RIGHT(SUBSTITUTE(TRIM(G4&"")," ",REPT(" ",60)),60)),설정_코드표!$F$2:$F$101,0)),"⚠"&TRIM(G4&""))),"⚠"&TRIM(G4&"")) | P4: =IFERROR(IF(TRIM(H4&"")="","",IF(AND(ISNUMBER(FIND(" ",TRIM(H4&""))),ISNUMBER(MATCH(LEFT(TRIM(H4&""),FIND(" ",TRIM(H4&""))-1),설정_코드표!$J$2:$J$101,0)),ISNUMBER(MATCH(TRIM(RIGHT(SUBSTITUTE(TRIM(H4&"")," ",REPT(" ",60)),60)),설정_코드표!$F$2:$F$101,0))),INDEX(설정_코드표!$K$2:$K$101,MATCH(LEFT(TRIM(H4&""),FIND(" ",TRIM(H4&""))-1),설정_코드표!$J$2:$J$101,0))&" "&INDEX(설정_코드표!$G$2:$G$101,MATCH(TRIM(RIGHT(SUBSTITUTE(TRIM(H4&"")," ",REPT(" ",60)),60)),설정_코드표!$F$2:$F$101,0)),"⚠"&TRIM(H4&""))),"⚠"&TRIM(H4&"")) | Q4: =IFERROR(IF(TRIM(I4&"")="","",IF(AND(ISNUMBER(FIND(" ",TRIM(I4&""))),ISNUMBER(MATCH(LEFT(TRIM(I4&""),FIND(" ",TRIM(I4&""))-1),설정_코드표!$J$2:$J$101,0)),ISNUMBER(MATCH(TRIM(RIGHT(SUBSTITUTE(TRIM(I4&"")," ",REPT(" ",60)),60)),설정_코드표!$F$2:$F$101,0))),INDEX(설정_코드표!$K$2:$K$101,MATCH(LEFT(TRIM(I4&""),FIND(" ",TRIM(I4&""))-1),설정_코드표!$J$2:$J$101,0))&" "&INDEX(설정_코드표!$G$2:$G$101,MATCH(TRIM(RIGHT(SUBSTITUTE(TRIM(I4&"")," ",REPT(" ",60)),60)),설정_코드표!$F$2:$F$101,0)),"⚠"&TRIM(I4&""))),"⚠"&TRIM(I4&"")) | R4: =IFERROR(IF(TRIM(J4&"")="","",IF(AND(ISNUMBER(FIND(" ",TRIM(J4&""))),ISNUMBER(MATCH(LEFT(TRIM(J4&""),FIND(" ",TRIM(J4&""))-1),설정_코드표!$J$2:$J$101,0)),ISNUMBER(MATCH(TRIM(RIGHT(SUBSTITUTE(TRIM(J4&"")," ",REPT(" ",60)),60)),설정_코드표!$F$2:$F$101,0))),INDEX(설정_코드표!$K$2:$K$101,MATCH(LEFT(TRIM(J4&""),FIND(" ",TRIM(J4&""))-1),설정_코드표!$J$2:$J$101,0))&" "&INDEX(설정_코드표!$G$2:$G$101,MATCH(TRIM(RIGHT(SUBSTITUTE(TRIM(J4&"")," ",REPT(" ",60)),60)),설정_코드표!$F$2:$F$101,0)),"⚠"&TRIM(J4&""))),"⚠"&TRIM(J4&"")) | S4: =IF(K4="","",IFERROR(IF(AND(ROUND((VALUE(K4&"")-INT(VALUE(K4&"")))*100,0)>=1,ROUND((VALUE(K4&"")-INT(VALUE(K4&"")))*100,0)<=12,INT(VALUE(K4&""))>=1900),DATE(INT(VALUE(K4&"")),ROUND((VALUE(K4&"")-INT(VALUE(K4&"")))*100,0),1),K4&""),K4&"")) | T4: =COUNTIF(M4:R4,"⚠*")
B5: 3 | C5: 박ㅇㅇ | D5: 222224 | E5: 제주 외과 | F5: 서울 내과 | G5: 서울 응급 | H5: 구리 내과 | I5: 서울 소아과 | J5: 제주 산부 | K5: 2026.03 | M5: =IFERROR(IF(TRIM(E5&"")="","",IF(AND(ISNUMBER(FIND(" ",TRIM(E5&""))),ISNUMBER(MATCH(LEFT(TRIM(E5&""),FIND(" ",TRIM(E5&""))-1),설정_코드표!$J$2:$J$101,0)),ISNUMBER(MATCH(TRIM(RIGHT(SUBSTITUTE(TRIM(E5&"")," ",REPT(" ",60)),60)),설정_코드표!$F$2:$F$101,0))),INDEX(설정_코드표!$K$2:$K$101,MATCH(LEFT(TRIM(E5&""),FIND(" ",TRIM(E5&""))-1),설정_코드표!$J$2:$J$101,0))&" "&INDEX(설정_코드표!$G$2:$G$101,MATCH(TRIM(RIGHT(SUBSTITUTE(TRIM(E5&"")," ",REPT(" ",60)),60)),설정_코드표!$F$2:$F$101,0)),"⚠"&TRIM(E5&""))),"⚠"&TRIM(E5&"")) | N5: =IFERROR(IF(TRIM(F5&"")="","",IF(AND(ISNUMBER(FIND(" ",TRIM(F5&""))),ISNUMBER(MATCH(LEFT(TRIM(F5&""),FIND(" ",TRIM(F5&""))-1),설정_코드표!$J$2:$J$101,0)),ISNUMBER(MATCH(TRIM(RIGHT(SUBSTITUTE(TRIM(F5&"")," ",REPT(" ",60)),60)),설정_코드표!$F$2:$F$101,0))),INDEX(설정_코드표!$K$2:$K$101,MATCH(LEFT(TRIM(F5&""),FIND(" ",TRIM(F5&""))-1),설정_코드표!$J$2:$J$101,0))&" "&INDEX(설정_코드표!$G$2:$G$101,MATCH(TRIM(RIGHT(SUBSTITUTE(TRIM(F5&"")," ",REPT(" ",60)),60)),설정_코드표!$F$2:$F$101,0)),"⚠"&TRIM(F5&""))),"⚠"&TRIM(F5&"")) | O5: =IFERROR(IF(TRIM(G5&"")="","",IF(AND(ISNUMBER(FIND(" ",TRIM(G5&""))),ISNUMBER(MATCH(LEFT(TRIM(G5&""),FIND(" ",TRIM(G5&""))-1),설정_코드표!$J$2:$J$101,0)),ISNUMBER(MATCH(TRIM(RIGHT(SUBSTITUTE(TRIM(G5&"")," ",REPT(" ",60)),60)),설정_코드표!$F$2:$F$101,0))),INDEX(설정_코드표!$K$2:$K$101,MATCH(LEFT(TRIM(G5&""),FIND(" ",TRIM(G5&""))-1),설정_코드표!$J$2:$J$101,0))&" "&INDEX(설정_코드표!$G$2:$G$101,MATCH(TRIM(RIGHT(SUBSTITUTE(TRIM(G5&"")," ",REPT(" ",60)),60)),설정_코드표!$F$2:$F$101,0)),"⚠"&TRIM(G5&""))),"⚠"&TRIM(G5&"")) | P5: =IFERROR(IF(TRIM(H5&"")="","",IF(AND(ISNUMBER(FIND(" ",TRIM(H5&""))),ISNUMBER(MATCH(LEFT(TRIM(H5&""),FIND(" ",TRIM(H5&""))-1),설정_코드표!$J$2:$J$101,0)),ISNUMBER(MATCH(TRIM(RIGHT(SUBSTITUTE(TRIM(H5&"")," ",REPT(" ",60)),60)),설정_코드표!$F$2:$F$101,0))),INDEX(설정_코드표!$K$2:$K$101,MATCH(LEFT(TRIM(H5&""),FIND(" ",TRIM(H5&""))-1),설정_코드표!$J$2:$J$101,0))&" "&INDEX(설정_코드표!$G$2:$G$101,MATCH(TRIM(RIGHT(SUBSTITUTE(TRIM(H5&"")," ",REPT(" ",60)),60)),설정_코드표!$F$2:$F$101,0)),"⚠"&TRIM(H5&""))),"⚠"&TRIM(H5&"")) | Q5: =IFERROR(IF(TRIM(I5&"")="","",IF(AND(ISNUMBER(FIND(" ",TRIM(I5&""))),ISNUMBER(MATCH(LEFT(TRIM(I5&""),FIND(" ",TRIM(I5&""))-1),설정_코드표!$J$2:$J$101,0)),ISNUMBER(MATCH(TRIM(RIGHT(SUBSTITUTE(TRIM(I5&"")," ",REPT(" ",60)),60)),설정_코드표!$F$2:$F$101,0))),INDEX(설정_코드표!$K$2:$K$101,MATCH(LEFT(TRIM(I5&""),FIND(" ",TRIM(I5&""))-1),설정_코드표!$J$2:$J$101,0))&" "&INDEX(설정_코드표!$G$2:$G$101,MATCH(TRIM(RIGHT(SUBSTITUTE(TRIM(I5&"")," ",REPT(" ",60)),60)),설정_코드표!$F$2:$F$101,0)),"⚠"&TRIM(I5&""))),"⚠"&TRIM(I5&"")) | R5: =IFERROR(IF(TRIM(J5&"")="","",IF(AND(ISNUMBER(FIND(" ",TRIM(J5&""))),ISNUMBER(MATCH(LEFT(TRIM(J5&""),FIND(" ",TRIM(J5&""))-1),설정_코드표!$J$2:$J$101,0)),ISNUMBER(MATCH(TRIM(RIGHT(SUBSTITUTE(TRIM(J5&"")," ",REPT(" ",60)),60)),설정_코드표!$F$2:$F$101,0))),INDEX(설정_코드표!$K$2:$K$101,MATCH(LEFT(TRIM(J5&""),FIND(" ",TRIM(J5&""))-1),설정_코드표!$J$2:$J$101,0))&" "&INDEX(설정_코드표!$G$2:$G$101,MATCH(TRIM(RIGHT(SUBSTITUTE(TRIM(J5&"")," ",REPT(" ",60)),60)),설정_코드표!$F$2:$F$101,0)),"⚠"&TRIM(J5&""))),"⚠"&TRIM(J5&"")) | S5: =IF(K5="","",IFERROR(IF(AND(ROUND((VALUE(K5&"")-INT(VALUE(K5&"")))*100,0)>=1,ROUND((VALUE(K5&"")-INT(VALUE(K5&"")))*100,0)<=12,INT(VALUE(K5&""))>=1900),DATE(INT(VALUE(K5&"")),ROUND((VALUE(K5&"")-INT(VALUE(K5&"")))*100,0),1),K5&""),K5&"")) | T5: =COUNTIF(M5:R5,"⚠*")
M6: =IFERROR(IF(TRIM(E6&"")="","",IF(AND(ISNUMBER(FIND(" ",TRIM(E6&""))),ISNUMBER(MATCH(LEFT(TRIM(E6&""),FIND(" ",TRIM(E6&""))-1),설정_코드표!$J$2:$J$101,0)),ISNUMBER(MATCH(TRIM(RIGHT(SUBSTITUTE(TRIM(E6&"")," ",REPT(" ",60)),60)),설정_코드표!$F$2:$F$101,0))),INDEX(설정_코드표!$K$2:$K$101,MATCH(LEFT(TRIM(E6&""),FIND(" ",TRIM(E6&""))-1),설정_코드표!$J$2:$J$101,0))&" "&INDEX(설정_코드표!$G$2:$G$101,MATCH(TRIM(RIGHT(SUBSTITUTE(TRIM(E6&"")," ",REPT(" ",60)),60)),설정_코드표!$F$2:$F$101,0)),"⚠"&TRIM(E6&""))),"⚠"&TRIM(E6&"")) | N6: =IFERROR(IF(TRIM(F6&"")="","",IF(AND(ISNUMBER(FIND(" ",TRIM(F6&""))),ISNUMBER(MATCH(LEFT(TRIM(F6&""),FIND(" ",TRIM(F6&""))-1),설정_코드표!$J$2:$J$101,0)),ISNUMBER(MATCH(TRIM(RIGHT(SUBSTITUTE(TRIM(F6&"")," ",REPT(" ",60)),60)),설정_코드표!$F$2:$F$101,0))),INDEX(설정_코드표!$K$2:$K$101,MATCH(LEFT(TRIM(F6&""),FIND(" ",TRIM(F6&""))-1),설정_코드표!$J$2:$J$101,0))&" "&INDEX(설정_코드표!$G$2:$G$101,MATCH(TRIM(RIGHT(SUBSTITUTE(TRIM(F6&"")," ",REPT(" ",60)),60)),설정_코드표!$F$2:$F$101,0)),"⚠"&TRIM(F6&""))),"⚠"&TRIM(F6&"")) | O6: =IFERROR(IF(TRIM(G6&"")="","",IF(AND(ISNUMBER(FIND(" ",TRIM(G6&""))),ISNUMBER(MATCH(LEFT(TRIM(G6&""),FIND(" ",TRIM(G6&""))-1),설정_코드표!$J$2:$J$101,0)),ISNUMBER(MATCH(TRIM(RIGHT(SUBSTITUTE(TRIM(G6&"")," ",REPT(" ",60)),60)),설정_코드표!$F$2:$F$101,0))),INDEX(설정_코드표!$K$2:$K$101,MATCH(LEFT(TRIM(G6&""),FIND(" ",TRIM(G6&""))-1),설정_코드표!$J$2:$J$101,0))&" "&INDEX(설정_코드표!$G$2:$G$101,MATCH(TRIM(RIGHT(SUBSTITUTE(TRIM(G6&"")," ",REPT(" ",60)),60)),설정_코드표!$F$2:$F$101,0)),"⚠"&TRIM(G6&""))),"⚠"&TRIM(G6&"")) | P6: =IFERROR(IF(TRIM(H6&"")="","",IF(AND(ISNUMBER(FIND(" ",TRIM(H6&""))),ISNUMBER(MATCH(LEFT(TRIM(H6&""),FIND(" ",TRIM(H6&""))-1),설정_코드표!$J$2:$J$101,0)),ISNUMBER(MATCH(TRIM(RIGHT(SUBSTITUTE(TRIM(H6&"")," ",REPT(" ",60)),60)),설정_코드표!$F$2:$F$101,0))),INDEX(설정_코드표!$K$2:$K$101,MATCH(LEFT(TRIM(H6&""),FIND(" ",TRIM(H6&""))-1),설정_코드표!$J$2:$J$101,0))&" "&INDEX(설정_코드표!$G$2:$G$101,MATCH(TRIM(RIGHT(SUBSTITUTE(TRIM(H6&"")," ",REPT(" ",60)),60)),설정_코드표!$F$2:$F$101,0)),"⚠"&TRIM(H6&""))),"⚠"&TRIM(H6&"")) | Q6: =IFERROR(IF(TRIM(I6&"")="","",IF(AND(ISNUMBER(FIND(" ",TRIM(I6&""))),ISNUMBER(MATCH(LEFT(TRIM(I6&""),FIND(" ",TRIM(I6&""))-1),설정_코드표!$J$2:$J$101,0)),ISNUMBER(MATCH(TRIM(RIGHT(SUBSTITUTE(TRIM(I6&"")," ",REPT(" ",60)),60)),설정_코드표!$F$2:$F$101,0))),INDEX(설정_코드표!$K$2:$K$101,MATCH(LEFT(TRIM(I6&""),FIND(" ",TRIM(I6&""))-1),설정_코드표!$J$2:$J$101,0))&" "&INDEX(설정_코드표!$G$2:$G$101,MATCH(TRIM(RIGHT(SUBSTITUTE(TRIM(I6&"")," ",REPT(" ",60)),60)),설정_코드표!$F$2:$F$101,0)),"⚠"&TRIM(I6&""))),"⚠"&TRIM(I6&"")) | R6: =IFERROR(IF(TRIM(J6&"")="","",IF(AND(ISNUMBER(FIND(" ",TRIM(J6&""))),ISNUMBER(MATCH(LEFT(TRIM(J6&""),FIND(" ",TRIM(J6&""))-1),설정_코드표!$J$2:$J$101,0)),ISNUMBER(MATCH(TRIM(RIGHT(SUBSTITUTE(TRIM(J6&"")," ",REPT(" ",60)),60)),설정_코드표!$F$2:$F$101,0))),INDEX(설정_코드표!$K$2:$K$101,MATCH(LEFT(TRIM(J6&""),FIND(" ",TRIM(J6&""))-1),설정_코드표!$J$2:$J$101,0))&" "&INDEX(설정_코드표!$G$2:$G$101,MATCH(TRIM(RIGHT(SUBSTITUTE(TRIM(J6&"")," ",REPT(" ",60)),60)),설정_코드표!$F$2:$F$101,0)),"⚠"&TRIM(J6&""))),"⚠"&TRIM(J6&"")) | S6: =IF(K6="","",IFERROR(IF(AND(ROUND((VALUE(K6&"")-INT(VALUE(K6&"")))*100,0)>=1,ROUND((VALUE(K6&"")-INT(VALUE(K6&"")))*100,0)<=12,INT(VALUE(K6&""))>=1900),DATE(INT(VALUE(K6&"")),ROUND((VALUE(K6&"")-INT(VALUE(K6&"")))*100,0),1),K6&""),K6&"")) | T6: =COUNTIF(M6:R6,"⚠*")
M7: =IFERROR(IF(TRIM(E7&"")="","",IF(AND(ISNUMBER(FIND(" ",TRIM(E7&""))),ISNUMBER(MATCH(LEFT(TRIM(E7&""),FIND(" ",TRIM(E7&""))-1),설정_코드표!$J$2:$J$101,0)),ISNUMBER(MATCH(TRIM(RIGHT(SUBSTITUTE(TRIM(E7&"")," ",REPT(" ",60)),60)),설정_코드표!$F$2:$F$101,0))),INDEX(설정_코드표!$K$2:$K$101,MATCH(LEFT(TRIM(E7&""),FIND(" ",TRIM(E7&""))-1),설정_코드표!$J$2:$J$101,0))&" "&INDEX(설정_코드표!$G$2:$G$101,MATCH(TRIM(RIGHT(SUBSTITUTE(TRIM(E7&"")," ",REPT(" ",60)),60)),설정_코드표!$F$2:$F$101,0)),"⚠"&TRIM(E7&""))),"⚠"&TRIM(E7&"")) | N7: =IFERROR(IF(TRIM(F7&"")="","",IF(AND(ISNUMBER(FIND(" ",TRIM(F7&""))),ISNUMBER(MATCH(LEFT(TRIM(F7&""),FIND(" ",TRIM(F7&""))-1),설정_코드표!$J$2:$J$101,0)),ISNUMBER(MATCH(TRIM(RIGHT(SUBSTITUTE(TRIM(F7&"")," ",REPT(" ",60)),60)),설정_코드표!$F$2:$F$101,0))),INDEX(설정_코드표!$K$2:$K$101,MATCH(LEFT(TRIM(F7&""),FIND(" ",TRIM(F7&""))-1),설정_코드표!$J$2:$J$101,0))&" "&INDEX(설정_코드표!$G$2:$G$101,MATCH(TRIM(RIGHT(SUBSTITUTE(TRIM(F7&"")," ",REPT(" ",60)),60)),설정_코드표!$F$2:$F$101,0)),"⚠"&TRIM(F7&""))),"⚠"&TRIM(F7&"")) | O7: =IFERROR(IF(TRIM(G7&"")="","",IF(AND(ISNUMBER(FIND(" ",TRIM(G7&""))),ISNUMBER(MATCH(LEFT(TRIM(G7&""),FIND(" ",TRIM(G7&""))-1),설정_코드표!$J$2:$J$101,0)),ISNUMBER(MATCH(TRIM(RIGHT(SUBSTITUTE(TRIM(G7&"")," ",REPT(" ",60)),60)),설정_코드표!$F$2:$F$101,0))),INDEX(설정_코드표!$K$2:$K$101,MATCH(LEFT(TRIM(G7&""),FIND(" ",TRIM(G7&""))-1),설정_코드표!$J$2:$J$101,0))&" "&INDEX(설정_코드표!$G$2:$G$101,MATCH(TRIM(RIGHT(SUBSTITUTE(TRIM(G7&"")," ",REPT(" ",60)),60)),설정_코드표!$F$2:$F$101,0)),"⚠"&TRIM(G7&""))),"⚠"&TRIM(G7&"")) | P7: =IFERROR(IF(TRIM(H7&"")="","",IF(AND(ISNUMBER(FIND(" ",TRIM(H7&""))),ISNUMBER(MATCH(LEFT(TRIM(H7&""),FIND(" ",TRIM(H7&""))-1),설정_코드표!$J$2:$J$101,0)),ISNUMBER(MATCH(TRIM(RIGHT(SUBSTITUTE(TRIM(H7&"")," ",REPT(" ",60)),60)),설정_코드표!$F$2:$F$101,0))),INDEX(설정_코드표!$K$2:$K$101,MATCH(LEFT(TRIM(H7&""),FIND(" ",TRIM(H7&""))-1),설정_코드표!$J$2:$J$101,0))&" "&INDEX(설정_코드표!$G$2:$G$101,MATCH(TRIM(RIGHT(SUBSTITUTE(TRIM(H7&"")," ",REPT(" ",60)),60)),설정_코드표!$F$2:$F$101,0)),"⚠"&TRIM(H7&""))),"⚠"&TRIM(H7&"")) | Q7: =IFERROR(IF(TRIM(I7&"")="","",IF(AND(ISNUMBER(FIND(" ",TRIM(I7&""))),ISNUMBER(MATCH(LEFT(TRIM(I7&""),FIND(" ",TRIM(I7&""))-1),설정_코드표!$J$2:$J$101,0)),ISNUMBER(MATCH(TRIM(RIGHT(SUBSTITUTE(TRIM(I7&"")," ",REPT(" ",60)),60)),설정_코드표!$F$2:$F$101,0))),INDEX(설정_코드표!$K$2:$K$101,MATCH(LEFT(TRIM(I7&""),FIND(" ",TRIM(I7&""))-1),설정_코드표!$J$2:$J$101,0))&" "&INDEX(설정_코드표!$G$2:$G$101,MATCH(TRIM(RIGHT(SUBSTITUTE(TRIM(I7&"")," ",REPT(" ",60)),60)),설정_코드표!$F$2:$F$101,0)),"⚠"&TRIM(I7&""))),"⚠"&TRIM(I7&"")) | R7: =IFERROR(IF(TRIM(J7&"")="","",IF(AND(ISNUMBER(FIND(" ",TRIM(J7&""))),ISNUMBER(MATCH(LEFT(TRIM(J7&""),FIND(" ",TRIM(J7&""))-1),설정_코드표!$J$2:$J$101,0)),ISNUMBER(MATCH(TRIM(RIGHT(SUBSTITUTE(TRIM(J7&"")," ",REPT(" ",60)),60)),설정_코드표!$F$2:$F$101,0))),INDEX(설정_코드표!$K$2:$K$101,MATCH(LEFT(TRIM(J7&""),FIND(" ",TRIM(J7&""))-1),설정_코드표!$J$2:$J$101,0))&" "&INDEX(설정_코드표!$G$2:$G$101,MATCH(TRIM(RIGHT(SUBSTITUTE(TRIM(J7&"")," ",REPT(" ",60)),60)),설정_코드표!$F$2:$F$101,0)),"⚠"&TRIM(J7&""))),"⚠"&TRIM(J7&"")) | S7: =IF(K7="","",IFERROR(IF(AND(ROUND((VALUE(K7&"")-INT(VALUE(K7&"")))*100,0)>=1,ROUND((VALUE(K7&"")-INT(VALUE(K7&"")))*100,0)<=12,INT(VALUE(K7&""))>=1900),DATE(INT(VALUE(K7&"")),ROUND((VALUE(K7&"")-INT(VALUE(K7&"")))*100,0),1),K7&""),K7&"")) | T7: =COUNTIF(M7:R7,"⚠*")
M8: =IFERROR(IF(TRIM(E8&"")="","",IF(AND(ISNUMBER(FIND(" ",TRIM(E8&""))),ISNUMBER(MATCH(LEFT(TRIM(E8&""),FIND(" ",TRIM(E8&""))-1),설정_코드표!$J$2:$J$101,0)),ISNUMBER(MATCH(TRIM(RIGHT(SUBSTITUTE(TRIM(E8&"")," ",REPT(" ",60)),60)),설정_코드표!$F$2:$F$101,0))),INDEX(설정_코드표!$K$2:$K$101,MATCH(LEFT(TRIM(E8&""),FIND(" ",TRIM(E8&""))-1),설정_코드표!$J$2:$J$101,0))&" "&INDEX(설정_코드표!$G$2:$G$101,MATCH(TRIM(RIGHT(SUBSTITUTE(TRIM(E8&"")," ",REPT(" ",60)),60)),설정_코드표!$F$2:$F$101,0)),"⚠"&TRIM(E8&""))),"⚠"&TRIM(E8&"")) | N8: =IFERROR(IF(TRIM(F8&"")="","",IF(AND(ISNUMBER(FIND(" ",TRIM(F8&""))),ISNUMBER(MATCH(LEFT(TRIM(F8&""),FIND(" ",TRIM(F8&""))-1),설정_코드표!$J$2:$J$101,0)),ISNUMBER(MATCH(TRIM(RIGHT(SUBSTITUTE(TRIM(F8&"")," ",REPT(" ",60)),60)),설정_코드표!$F$2:$F$101,0))),INDEX(설정_코드표!$K$2:$K$101,MATCH(LEFT(TRIM(F8&""),FIND(" ",TRIM(F8&""))-1),설정_코드표!$J$2:$J$101,0))&" "&INDEX(설정_코드표!$G$2:$G$101,MATCH(TRIM(RIGHT(SUBSTITUTE(TRIM(F8&"")," ",REPT(" ",60)),60)),설정_코드표!$F$2:$F$101,0)),"⚠"&TRIM(F8&""))),"⚠"&TRIM(F8&"")) | O8: =IFERROR(IF(TRIM(G8&"")="","",IF(AND(ISNUMBER(FIND(" ",TRIM(G8&""))),ISNUMBER(MATCH(LEFT(TRIM(G8&""),FIND(" ",TRIM(G8&""))-1),설정_코드표!$J$2:$J$101,0)),ISNUMBER(MATCH(TRIM(RIGHT(SUBSTITUTE(TRIM(G8&"")," ",REPT(" ",60)),60)),설정_코드표!$F$2:$F$101,0))),INDEX(설정_코드표!$K$2:$K$101,MATCH(LEFT(TRIM(G8&""),FIND(" ",TRIM(G8&""))-1),설정_코드표!$J$2:$J$101,0))&" "&INDEX(설정_코드표!$G$2:$G$101,MATCH(TRIM(RIGHT(SUBSTITUTE(TRIM(G8&"")," ",REPT(" ",60)),60)),설정_코드표!$F$2:$F$101,0)),"⚠"&TRIM(G8&""))),"⚠"&TRIM(G8&"")) | P8: =IFERROR(IF(TRIM(H8&"")="","",IF(AND(ISNUMBER(FIND(" ",TRIM(H8&""))),ISNUMBER(MATCH(LEFT(TRIM(H8&""),FIND(" ",TRIM(H8&""))-1),설정_코드표!$J$2:$J$101,0)),ISNUMBER(MATCH(TRIM(RIGHT(SUBSTITUTE(TRIM(H8&"")," ",REPT(" ",60)),60)),설정_코드표!$F$2:$F$101,0))),INDEX(설정_코드표!$K$2:$K$101,MATCH(LEFT(TRIM(H8&""),FIND(" ",TRIM(H8&""))-1),설정_코드표!$J$2:$J$101,0))&" "&INDEX(설정_코드표!$G$2:$G$101,MATCH(TRIM(RIGHT(SUBSTITUTE(TRIM(H8&"")," ",REPT(" ",60)),60)),설정_코드표!$F$2:$F$101,0)),"⚠"&TRIM(H8&""))),"⚠"&TRIM(H8&"")) | Q8: =IFERROR(IF(TRIM(I8&"")="","",IF(AND(ISNUMBER(FIND(" ",TRIM(I8&""))),ISNUMBER(MATCH(LEFT(TRIM(I8&""),FIND(" ",TRIM(I8&""))-1),설정_코드표!$J$2:$J$101,0)),ISNUMBER(MATCH(TRIM(RIGHT(SUBSTITUTE(TRIM(I8&"")," ",REPT(" ",60)),60)),설정_코드표!$F$2:$F$101,0))),INDEX(설정_코드표!$K$2:$K$101,MATCH(LEFT(TRIM(I8&""),FIND(" ",TRIM(I8&""))-1),설정_코드표!$J$2:$J$101,0))&" "&INDEX(설정_코드표!$G$2:$G$101,MATCH(TRIM(RIGHT(SUBSTITUTE(TRIM(I8&"")," ",REPT(" ",60)),60)),설정_코드표!$F$2:$F$101,0)),"⚠"&TRIM(I8&""))),"⚠"&TRIM(I8&"")) | R8: =IFERROR(IF(TRIM(J8&"")="","",IF(AND(ISNUMBER(FIND(" ",TRIM(J8&""))),ISNUMBER(MATCH(LEFT(TRIM(J8&""),FIND(" ",TRIM(J8&""))-1),설정_코드표!$J$2:$J$101,0)),ISNUMBER(MATCH(TRIM(RIGHT(SUBSTITUTE(TRIM(J8&"")," ",REPT(" ",60)),60)),설정_코드표!$F$2:$F$101,0))),INDEX(설정_코드표!$K$2:$K$101,MATCH(LEFT(TRIM(J8&""),FIND(" ",TRIM(J8&""))-1),설정_코드표!$J$2:$J$101,0))&" "&INDEX(설정_코드표!$G$2:$G$101,MATCH(TRIM(RIGHT(SUBSTITUTE(TRIM(J8&"")," ",REPT(" ",60)),60)),설정_코드표!$F$2:$F$101,0)),"⚠"&TRIM(J8&""))),"⚠"&TRIM(J8&"")) | S8: =IF(K8="","",IFERROR(IF(AND(ROUND((VALUE(K8&"")-INT(VALUE(K8&"")))*100,0)>=1,ROUND((VALUE(K8&"")-INT(VALUE(K8&"")))*100,0)<=12,INT(VALUE(K8&""))>=1900),DATE(INT(VALUE(K8&"")),ROUND((VALUE(K8&"")-INT(VALUE(K8&"")))*100,0),1),K8&""),K8&"")) | T8: =COUNTIF(M8:R8,"⚠*")
M9: =IFERROR(IF(TRIM(E9&"")="","",IF(AND(ISNUMBER(FIND(" ",TRIM(E9&""))),ISNUMBER(MATCH(LEFT(TRIM(E9&""),FIND(" ",TRIM(E9&""))-1),설정_코드표!$J$2:$J$101,0)),ISNUMBER(MATCH(TRIM(RIGHT(SUBSTITUTE(TRIM(E9&"")," ",REPT(" ",60)),60)),설정_코드표!$F$2:$F$101,0))),INDEX(설정_코드표!$K$2:$K$101,MATCH(LEFT(TRIM(E9&""),FIND(" ",TRIM(E9&""))-1),설정_코드표!$J$2:$J$101,0))&" "&INDEX(설정_코드표!$G$2:$G$101,MATCH(TRIM(RIGHT(SUBSTITUTE(TRIM(E9&"")," ",REPT(" ",60)),60)),설정_코드표!$F$2:$F$101,0)),"⚠"&TRIM(E9&""))),"⚠"&TRIM(E9&"")) | N9: =IFERROR(IF(TRIM(F9&"")="","",IF(AND(ISNUMBER(FIND(" ",TRIM(F9&""))),ISNUMBER(MATCH(LEFT(TRIM(F9&""),FIND(" ",TRIM(F9&""))-1),설정_코드표!$J$2:$J$101,0)),ISNUMBER(MATCH(TRIM(RIGHT(SUBSTITUTE(TRIM(F9&"")," ",REPT(" ",60)),60)),설정_코드표!$F$2:$F$101,0))),INDEX(설정_코드표!$K$2:$K$101,MATCH(LEFT(TRIM(F9&""),FIND(" ",TRIM(F9&""))-1),설정_코드표!$J$2:$J$101,0))&" "&INDEX(설정_코드표!$G$2:$G$101,MATCH(TRIM(RIGHT(SUBSTITUTE(TRIM(F9&"")," ",REPT(" ",60)),60)),설정_코드표!$F$2:$F$101,0)),"⚠"&TRIM(F9&""))),"⚠"&TRIM(F9&"")) | O9: =IFERROR(IF(TRIM(G9&"")="","",IF(AND(ISNUMBER(FIND(" ",TRIM(G9&""))),ISNUMBER(MATCH(LEFT(TRIM(G9&""),FIND(" ",TRIM(G9&""))-1),설정_코드표!$J$2:$J$101,0)),ISNUMBER(MATCH(TRIM(RIGHT(SUBSTITUTE(TRIM(G9&"")," ",REPT(" ",60)),60)),설정_코드표!$F$2:$F$101,0))),INDEX(설정_코드표!$K$2:$K$101,MATCH(LEFT(TRIM(G9&""),FIND(" ",TRIM(G9&""))-1),설정_코드표!$J$2:$J$101,0))&" "&INDEX(설정_코드표!$G$2:$G$101,MATCH(TRIM(RIGHT(SUBSTITUTE(TRIM(G9&"")," ",REPT(" ",60)),60)),설정_코드표!$F$2:$F$101,0)),"⚠"&TRIM(G9&""))),"⚠"&TRIM(G9&"")) | P9: =IFERROR(IF(TRIM(H9&"")="","",IF(AND(ISNUMBER(FIND(" ",TRIM(H9&""))),ISNUMBER(MATCH(LEFT(TRIM(H9&""),FIND(" ",TRIM(H9&""))-1),설정_코드표!$J$2:$J$101,0)),ISNUMBER(MATCH(TRIM(RIGHT(SUBSTITUTE(TRIM(H9&"")," ",REPT(" ",60)),60)),설정_코드표!$F$2:$F$101,0))),INDEX(설정_코드표!$K$2:$K$101,MATCH(LEFT(TRIM(H9&""),FIND(" ",TRIM(H9&""))-1),설정_코드표!$J$2:$J$101,0))&" "&INDEX(설정_코드표!$G$2:$G$101,MATCH(TRIM(RIGHT(SUBSTITUTE(TRIM(H9&"")," ",REPT(" ",60)),60)),설정_코드표!$F$2:$F$101,0)),"⚠"&TRIM(H9&""))),"⚠"&TRIM(H9&"")) | Q9: =IFERROR(IF(TRIM(I9&"")="","",IF(AND(ISNUMBER(FIND(" ",TRIM(I9&""))),ISNUMBER(MATCH(LEFT(TRIM(I9&""),FIND(" ",TRIM(I9&""))-1),설정_코드표!$J$2:$J$101,0)),ISNUMBER(MATCH(TRIM(RIGHT(SUBSTITUTE(TRIM(I9&"")," ",REPT(" ",60)),60)),설정_코드표!$F$2:$F$101,0))),INDEX(설정_코드표!$K$2:$K$101,MATCH(LEFT(TRIM(I9&""),FIND(" ",TRIM(I9&""))-1),설정_코드표!$J$2:$J$101,0))&" "&INDEX(설정_코드표!$G$2:$G$101,MATCH(TRIM(RIGHT(SUBSTITUTE(TRIM(I9&"")," ",REPT(" ",60)),60)),설정_코드표!$F$2:$F$101,0)),"⚠"&TRIM(I9&""))),"⚠"&TRIM(I9&"")) | R9: =IFERROR(IF(TRIM(J9&"")="","",IF(AND(ISNUMBER(FIND(" ",TRIM(J9&""))),ISNUMBER(MATCH(LEFT(TRIM(J9&""),FIND(" ",TRIM(J9&""))-1),설정_코드표!$J$2:$J$101,0)),ISNUMBER(MATCH(TRIM(RIGHT(SUBSTITUTE(TRIM(J9&"")," ",REPT(" ",60)),60)),설정_코드표!$F$2:$F$101,0))),INDEX(설정_코드표!$K$2:$K$101,MATCH(LEFT(TRIM(J9&""),FIND(" ",TRIM(J9&""))-1),설정_코드표!$J$2:$J$101,0))&" "&INDEX(설정_코드표!$G$2:$G$101,MATCH(TRIM(RIGHT(SUBSTITUTE(TRIM(J9&"")," ",REPT(" ",60)),60)),설정_코드표!$F$2:$F$101,0)),"⚠"&TRIM(J9&""))),"⚠"&TRIM(J9&"")) | S9: =IF(K9="","",IFERROR(IF(AND(ROUND((VALUE(K9&"")-INT(VALUE(K9&"")))*100,0)>=1,ROUND((VALUE(K9&"")-INT(VALUE(K9&"")))*100,0)<=12,INT(VALUE(K9&""))>=1900),DATE(INT(VALUE(K9&"")),ROUND((VALUE(K9&"")-INT(VALUE(K9&"")))*100,0),1),K9&""),K9&"")) | T9: =COUNTIF(M9:R9,"⚠*")
M10: =IFERROR(IF(TRIM(E10&"")="","",IF(AND(ISNUMBER(FIND(" ",TRIM(E10&""))),ISNUMBER(MATCH(LEFT(TRIM(E10&""),FIND(" ",TRIM(E10&""))-1),설정_코드표!$J$2:$J$101,0)),ISNUMBER(MATCH(TRIM(RIGHT(SUBSTITUTE(TRIM(E10&"")," ",REPT(" ",60)),60)),설정_코드표!$F$2:$F$101,0))),INDEX(설정_코드표!$K$2:$K$101,MATCH(LEFT(TRIM(E10&""),FIND(" ",TRIM(E10&""))-1),설정_코드표!$J$2:$J$101,0))&" "&INDEX(설정_코드표!$G$2:$G$101,MATCH(TRIM(RIGHT(SUBSTITUTE(TRIM(E10&"")," ",REPT(" ",60)),60)),설정_코드표!$F$2:$F$101,0)),"⚠"&TRIM(E10&""))),"⚠"&TRIM(E10&"")) | N10: =IFERROR(IF(TRIM(F10&"")="","",IF(AND(ISNUMBER(FIND(" ",TRIM(F10&""))),ISNUMBER(MATCH(LEFT(TRIM(F10&""),FIND(" ",TRIM(F10&""))-1),설정_코드표!$J$2:$J$101,0)),ISNUMBER(MATCH(TRIM(RIGHT(SUBSTITUTE(TRIM(F10&"")," ",REPT(" ",60)),60)),설정_코드표!$F$2:$F$101,0))),INDEX(설정_코드표!$K$2:$K$101,MATCH(LEFT(TRIM(F10&""),FIND(" ",TRIM(F10&""))-1),설정_코드표!$J$2:$J$101,0))&" "&INDEX(설정_코드표!$G$2:$G$101,MATCH(TRIM(RIGHT(SUBSTITUTE(TRIM(F10&"")," ",REPT(" ",60)),60)),설정_코드표!$F$2:$F$101,0)),"⚠"&TRIM(F10&""))),"⚠"&TRIM(F10&"")) | O10: =IFERROR(IF(TRIM(G10&"")="","",IF(AND(ISNUMBER(FIND(" ",TRIM(G10&""))),ISNUMBER(MATCH(LEFT(TRIM(G10&""),FIND(" ",TRIM(G10&""))-1),설정_코드표!$J$2:$J$101,0)),ISNUMBER(MATCH(TRIM(RIGHT(SUBSTITUTE(TRIM(G10&"")," ",REPT(" ",60)),60)),설정_코드표!$F$2:$F$101,0))),INDEX(설정_코드표!$K$2:$K$101,MATCH(LEFT(TRIM(G10&""),FIND(" ",TRIM(G10&""))-1),설정_코드표!$J$2:$J$101,0))&" "&INDEX(설정_코드표!$G$2:$G$101,MATCH(TRIM(RIGHT(SUBSTITUTE(TRIM(G10&"")," ",REPT(" ",60)),60)),설정_코드표!$F$2:$F$101,0)),"⚠"&TRIM(G10&""))),"⚠"&TRIM(G10&"")) | P10: =IFERROR(IF(TRIM(H10&"")="","",IF(AND(ISNUMBER(FIND(" ",TRIM(H10&""))),ISNUMBER(MATCH(LEFT(TRIM(H10&""),FIND(" ",TRIM(H10&""))-1),설정_코드표!$J$2:$J$101,0)),ISNUMBER(MATCH(TRIM(RIGHT(SUBSTITUTE(TRIM(H10&"")," ",REPT(" ",60)),60)),설정_코드표!$F$2:$F$101,0))),INDEX(설정_코드표!$K$2:$K$101,MATCH(LEFT(TRIM(H10&""),FIND(" ",TRIM(H10&""))-1),설정_코드표!$J$2:$J$101,0))&" "&INDEX(설정_코드표!$G$2:$G$101,MATCH(TRIM(RIGHT(SUBSTITUTE(TRIM(H10&"")," ",REPT(" ",60)),60)),설정_코드표!$F$2:$F$101,0)),"⚠"&TRIM(H10&""))),"⚠"&TRIM(H10&"")) | Q10: =IFERROR(IF(TRIM(I10&"")="","",IF(AND(ISNUMBER(FIND(" ",TRIM(I10&""))),ISNUMBER(MATCH(LEFT(TRIM(I10&""),FIND(" ",TRIM(I10&""))-1),설정_코드표!$J$2:$J$101,0)),ISNUMBER(MATCH(TRIM(RIGHT(SUBSTITUTE(TRIM(I10&"")," ",REPT(" ",60)),60)),설정_코드표!$F$2:$F$101,0))),INDEX(설정_코드표!$K$2:$K$101,MATCH(LEFT(TRIM(I10&""),FIND(" ",TRIM(I10&""))-1),설정_코드표!$J$2:$J$101,0))&" "&INDEX(설정_코드표!$G$2:$G$101,MATCH(TRIM(RIGHT(SUBSTITUTE(TRIM(I10&"")," ",REPT(" ",60)),60)),설정_코드표!$F$2:$F$101,0)),"⚠"&TRIM(I10&""))),"⚠"&TRIM(I10&"")) | R10: =IFERROR(IF(TRIM(J10&"")="","",IF(AND(ISNUMBER(FIND(" ",TRIM(J10&""))),ISNUMBER(MATCH(LEFT(TRIM(J10&""),FIND(" ",TRIM(J10&""))-1),설정_코드표!$J$2:$J$101,0)),ISNUMBER(MATCH(TRIM(RIGHT(SUBSTITUTE(TRIM(J10&"")," ",REPT(" ",60)),60)),설정_코드표!$F$2:$F$101,0))),INDEX(설정_코드표!$K$2:$K$101,MATCH(LEFT(TRIM(J10&""),FIND(" ",TRIM(J10&""))-1),설정_코드표!$J$2:$J$101,0))&" "&INDEX(설정_코드표!$G$2:$G$101,MATCH(TRIM(RIGHT(SUBSTITUTE(TRIM(J10&"")," ",REPT(" ",60)),60)),설정_코드표!$F$2:$F$101,0)),"⚠"&TRIM(J10&""))),"⚠"&TRIM(J10&"")) | S10: =IF(K10="","",IFERROR(IF(AND(ROUND((VALUE(K10&"")-INT(VALUE(K10&"")))*100,0)>=1,ROUND((VALUE(K10&"")-INT(VALUE(K10&"")))*100,0)<=12,INT(VALUE(K10&""))>=1900),DATE(INT(VALUE(K10&"")),ROUND((VALUE(K10&"")-INT(VALUE(K10&"")))*100,0),1),K10&""),K10&"")) | T10: =COUNTIF(M10:R10,"⚠*")
M11: =IFERROR(IF(TRIM(E11&"")="","",IF(AND(ISNUMBER(FIND(" ",TRIM(E11&""))),ISNUMBER(MATCH(LEFT(TRIM(E11&""),FIND(" ",TRIM(E11&""))-1),설정_코드표!$J$2:$J$101,0)),ISNUMBER(MATCH(TRIM(RIGHT(SUBSTITUTE(TRIM(E11&"")," ",REPT(" ",60)),60)),설정_코드표!$F$2:$F$101,0))),INDEX(설정_코드표!$K$2:$K$101,MATCH(LEFT(TRIM(E11&""),FIND(" ",TRIM(E11&""))-1),설정_코드표!$J$2:$J$101,0))&" "&INDEX(설정_코드표!$G$2:$G$101,MATCH(TRIM(RIGHT(SUBSTITUTE(TRIM(E11&"")," ",REPT(" ",60)),60)),설정_코드표!$F$2:$F$101,0)),"⚠"&TRIM(E11&""))),"⚠"&TRIM(E11&"")) | N11: =IFERROR(IF(TRIM(F11&"")="","",IF(AND(ISNUMBER(FIND(" ",TRIM(F11&""))),ISNUMBER(MATCH(LEFT(TRIM(F11&""),FIND(" ",TRIM(F11&""))-1),설정_코드표!$J$2:$J$101,0)),ISNUMBER(MATCH(TRIM(RIGHT(SUBSTITUTE(TRIM(F11&"")," ",REPT(" ",60)),60)),설정_코드표!$F$2:$F$101,0))),INDEX(설정_코드표!$K$2:$K$101,MATCH(LEFT(TRIM(F11&""),FIND(" ",TRIM(F11&""))-1),설정_코드표!$J$2:$J$101,0))&" "&INDEX(설정_코드표!$G$2:$G$101,MATCH(TRIM(RIGHT(SUBSTITUTE(TRIM(F11&"")," ",REPT(" ",60)),60)),설정_코드표!$F$2:$F$101,0)),"⚠"&TRIM(F11&""))),"⚠"&TRIM(F11&"")) | O11: =IFERROR(IF(TRIM(G11&"")="","",IF(AND(ISNUMBER(FIND(" ",TRIM(G11&""))),ISNUMBER(MATCH(LEFT(TRIM(G11&""),FIND(" ",TRIM(G11&""))-1),설정_코드표!$J$2:$J$101,0)),ISNUMBER(MATCH(TRIM(RIGHT(SUBSTITUTE(TRIM(G11&"")," ",REPT(" ",60)),60)),설정_코드표!$F$2:$F$101,0))),INDEX(설정_코드표!$K$2:$K$101,MATCH(LEFT(TRIM(G11&""),FIND(" ",TRIM(G11&""))-1),설정_코드표!$J$2:$J$101,0))&" "&INDEX(설정_코드표!$G$2:$G$101,MATCH(TRIM(RIGHT(SUBSTITUTE(TRIM(G11&"")," ",REPT(" ",60)),60)),설정_코드표!$F$2:$F$101,0)),"⚠"&TRIM(G11&""))),"⚠"&TRIM(G11&"")) | P11: =IFERROR(IF(TRIM(H11&"")="","",IF(AND(ISNUMBER(FIND(" ",TRIM(H11&""))),ISNUMBER(MATCH(LEFT(TRIM(H11&""),FIND(" ",TRIM(H11&""))-1),설정_코드표!$J$2:$J$101,0)),ISNUMBER(MATCH(TRIM(RIGHT(SUBSTITUTE(TRIM(H11&"")," ",REPT(" ",60)),60)),설정_코드표!$F$2:$F$101,0))),INDEX(설정_코드표!$K$2:$K$101,MATCH(LEFT(TRIM(H11&""),FIND(" ",TRIM(H11&""))-1),설정_코드표!$J$2:$J$101,0))&" "&INDEX(설정_코드표!$G$2:$G$101,MATCH(TRIM(RIGHT(SUBSTITUTE(TRIM(H11&"")," ",REPT(" ",60)),60)),설정_코드표!$F$2:$F$101,0)),"⚠"&TRIM(H11&""))),"⚠"&TRIM(H11&"")) | Q11: =IFERROR(IF(TRIM(I11&"")="","",IF(AND(ISNUMBER(FIND(" ",TRIM(I11&""))),ISNUMBER(MATCH(LEFT(TRIM(I11&""),FIND(" ",TRIM(I11&""))-1),설정_코드표!$J$2:$J$101,0)),ISNUMBER(MATCH(TRIM(RIGHT(SUBSTITUTE(TRIM(I11&"")," ",REPT(" ",60)),60)),설정_코드표!$F$2:$F$101,0))),INDEX(설정_코드표!$K$2:$K$101,MATCH(LEFT(TRIM(I11&""),FIND(" ",TRIM(I11&""))-1),설정_코드표!$J$2:$J$101,0))&" "&INDEX(설정_코드표!$G$2:$G$101,MATCH(TRIM(RIGHT(SUBSTITUTE(TRIM(I11&"")," ",REPT(" ",60)),60)),설정_코드표!$F$2:$F$101,0)),"⚠"&TRIM(I11&""))),"⚠"&TRIM(I11&"")) | R11: =IFERROR(IF(TRIM(J11&"")="","",IF(AND(ISNUMBER(FIND(" ",TRIM(J11&""))),ISNUMBER(MATCH(LEFT(TRIM(J11&""),FIND(" ",TRIM(J11&""))-1),설정_코드표!$J$2:$J$101,0)),ISNUMBER(MATCH(TRIM(RIGHT(SUBSTITUTE(TRIM(J11&"")," ",REPT(" ",60)),60)),설정_코드표!$F$2:$F$101,0))),INDEX(설정_코드표!$K$2:$K$101,MATCH(LEFT(TRIM(J11&""),FIND(" ",TRIM(J11&""))-1),설정_코드표!$J$2:$J$101,0))&" "&INDEX(설정_코드표!$G$2:$G$101,MATCH(TRIM(RIGHT(SUBSTITUTE(TRIM(J11&"")," ",REPT(" ",60)),60)),설정_코드표!$F$2:$F$101,0)),"⚠"&TRIM(J11&""))),"⚠"&TRIM(J11&"")) | S11: =IF(K11="","",IFERROR(IF(AND(ROUND((VALUE(K11&"")-INT(VALUE(K11&"")))*100,0)>=1,ROUND((VALUE(K11&"")-INT(VALUE(K11&"")))*100,0)<=12,INT(VALUE(K11&""))>=1900),DATE(INT(VALUE(K11&"")),ROUND((VALUE(K11&"")-INT(VALUE(K11&"")))*100,0),1),K11&""),K11&"")) | T11: =COUNTIF(M11:R11,"⚠*")
M12: =IFERROR(IF(TRIM(E12&"")="","",IF(AND(ISNUMBER(FIND(" ",TRIM(E12&""))),ISNUMBER(MATCH(LEFT(TRIM(E12&""),FIND(" ",TRIM(E12&""))-1),설정_코드표!$J$2:$J$101,0)),ISNUMBER(MATCH(TRIM(RIGHT(SUBSTITUTE(TRIM(E12&"")," ",REPT(" ",60)),60)),설정_코드표!$F$2:$F$101,0))),INDEX(설정_코드표!$K$2:$K$101,MATCH(LEFT(TRIM(E12&""),FIND(" ",TRIM(E12&""))-1),설정_코드표!$J$2:$J$101,0))&" "&INDEX(설정_코드표!$G$2:$G$101,MATCH(TRIM(RIGHT(SUBSTITUTE(TRIM(E12&"")," ",REPT(" ",60)),60)),설정_코드표!$F$2:$F$101,0)),"⚠"&TRIM(E12&""))),"⚠"&TRIM(E12&"")) | N12: =IFERROR(IF(TRIM(F12&"")="","",IF(AND(ISNUMBER(FIND(" ",TRIM(F12&""))),ISNUMBER(MATCH(LEFT(TRIM(F12&""),FIND(" ",TRIM(F12&""))-1),설정_코드표!$J$2:$J$101,0)),ISNUMBER(MATCH(TRIM(RIGHT(SUBSTITUTE(TRIM(F12&"")," ",REPT(" ",60)),60)),설정_코드표!$F$2:$F$101,0))),INDEX(설정_코드표!$K$2:$K$101,MATCH(LEFT(TRIM(F12&""),FIND(" ",TRIM(F12&""))-1),설정_코드표!$J$2:$J$101,0))&" "&INDEX(설정_코드표!$G$2:$G$101,MATCH(TRIM(RIGHT(SUBSTITUTE(TRIM(F12&"")," ",REPT(" ",60)),60)),설정_코드표!$F$2:$F$101,0)),"⚠"&TRIM(F12&""))),"⚠"&TRIM(F12&"")) | O12: =IFERROR(IF(TRIM(G12&"")="","",IF(AND(ISNUMBER(FIND(" ",TRIM(G12&""))),ISNUMBER(MATCH(LEFT(TRIM(G12&""),FIND(" ",TRIM(G12&""))-1),설정_코드표!$J$2:$J$101,0)),ISNUMBER(MATCH(TRIM(RIGHT(SUBSTITUTE(TRIM(G12&"")," ",REPT(" ",60)),60)),설정_코드표!$F$2:$F$101,0))),INDEX(설정_코드표!$K$2:$K$101,MATCH(LEFT(TRIM(G12&""),FIND(" ",TRIM(G12&""))-1),설정_코드표!$J$2:$J$101,0))&" "&INDEX(설정_코드표!$G$2:$G$101,MATCH(TRIM(RIGHT(SUBSTITUTE(TRIM(G12&"")," ",REPT(" ",60)),60)),설정_코드표!$F$2:$F$101,0)),"⚠"&TRIM(G12&""))),"⚠"&TRIM(G12&"")) | P12: =IFERROR(IF(TRIM(H12&"")="","",IF(AND(ISNUMBER(FIND(" ",TRIM(H12&""))),ISNUMBER(MATCH(LEFT(TRIM(H12&""),FIND(" ",TRIM(H12&""))-1),설정_코드표!$J$2:$J$101,0)),ISNUMBER(MATCH(TRIM(RIGHT(SUBSTITUTE(TRIM(H12&"")," ",REPT(" ",60)),60)),설정_코드표!$F$2:$F$101,0))),INDEX(설정_코드표!$K$2:$K$101,MATCH(LEFT(TRIM(H12&""),FIND(" ",TRIM(H12&""))-1),설정_코드표!$J$2:$J$101,0))&" "&INDEX(설정_코드표!$G$2:$G$101,MATCH(TRIM(RIGHT(SUBSTITUTE(TRIM(H12&"")," ",REPT(" ",60)),60)),설정_코드표!$F$2:$F$101,0)),"⚠"&TRIM(H12&""))),"⚠"&TRIM(H12&"")) | Q12: =IFERROR(IF(TRIM(I12&"")="","",IF(AND(ISNUMBER(FIND(" ",TRIM(I12&""))),ISNUMBER(MATCH(LEFT(TRIM(I12&""),FIND(" ",TRIM(I12&""))-1),설정_코드표!$J$2:$J$101,0)),ISNUMBER(MATCH(TRIM(RIGHT(SUBSTITUTE(TRIM(I12&"")," ",REPT(" ",60)),60)),설정_코드표!$F$2:$F$101,0))),INDEX(설정_코드표!$K$2:$K$101,MATCH(LEFT(TRIM(I12&""),FIND(" ",TRIM(I12&""))-1),설정_코드표!$J$2:$J$101,0))&" "&INDEX(설정_코드표!$G$2:$G$101,MATCH(TRIM(RIGHT(SUBSTITUTE(TRIM(I12&"")," ",REPT(" ",60)),60)),설정_코드표!$F$2:$F$101,0)),"⚠"&TRIM(I12&""))),"⚠"&TRIM(I12&"")) | R12: =IFERROR(IF(TRIM(J12&"")="","",IF(AND(ISNUMBER(FIND(" ",TRIM(J12&""))),ISNUMBER(MATCH(LEFT(TRIM(J12&""),FIND(" ",TRIM(J12&""))-1),설정_코드표!$J$2:$J$101,0)),ISNUMBER(MATCH(TRIM(RIGHT(SUBSTITUTE(TRIM(J12&"")," ",REPT(" ",60)),60)),설정_코드표!$F$2:$F$101,0))),INDEX(설정_코드표!$K$2:$K$101,MATCH(LEFT(TRIM(J12&""),FIND(" ",TRIM(J12&""))-1),설정_코드표!$J$2:$J$101,0))&" "&INDEX(설정_코드표!$G$2:$G$101,MATCH(TRIM(RIGHT(SUBSTITUTE(TRIM(J12&"")," ",REPT(" ",60)),60)),설정_코드표!$F$2:$F$101,0)),"⚠"&TRIM(J12&""))),"⚠"&TRIM(J12&"")) | S12: =IF(K12="","",IFERROR(IF(AND(ROUND((VALUE(K12&"")-INT(VALUE(K12&"")))*100,0)>=1,ROUND((VALUE(K12&"")-INT(VALUE(K12&"")))*100,0)<=12,INT(VALUE(K12&""))>=1900),DATE(INT(VALUE(K12&"")),ROUND((VALUE(K12&"")-INT(VALUE(K12&"")))*100,0),1),K12&""),K12&"")) | T12: =COUNTIF(M12:R12,"⚠*")
M13: =IFERROR(IF(TRIM(E13&"")="","",IF(AND(ISNUMBER(FIND(" ",TRIM(E13&""))),ISNUMBER(MATCH(LEFT(TRIM(E13&""),FIND(" ",TRIM(E13&""))-1),설정_코드표!$J$2:$J$101,0)),ISNUMBER(MATCH(TRIM(RIGHT(SUBSTITUTE(TRIM(E13&"")," ",REPT(" ",60)),60)),설정_코드표!$F$2:$F$101,0))),INDEX(설정_코드표!$K$2:$K$101,MATCH(LEFT(TRIM(E13&""),FIND(" ",TRIM(E13&""))-1),설정_코드표!$J$2:$J$101,0))&" "&INDEX(설정_코드표!$G$2:$G$101,MATCH(TRIM(RIGHT(SUBSTITUTE(TRIM(E13&"")," ",REPT(" ",60)),60)),설정_코드표!$F$2:$F$101,0)),"⚠"&TRIM(E13&""))),"⚠"&TRIM(E13&"")) | N13: =IFERROR(IF(TRIM(F13&"")="","",IF(AND(ISNUMBER(FIND(" ",TRIM(F13&""))),ISNUMBER(MATCH(LEFT(TRIM(F13&""),FIND(" ",TRIM(F13&""))-1),설정_코드표!$J$2:$J$101,0)),ISNUMBER(MATCH(TRIM(RIGHT(SUBSTITUTE(TRIM(F13&"")," ",REPT(" ",60)),60)),설정_코드표!$F$2:$F$101,0))),INDEX(설정_코드표!$K$2:$K$101,MATCH(LEFT(TRIM(F13&""),FIND(" ",TRIM(F13&""))-1),설정_코드표!$J$2:$J$101,0))&" "&INDEX(설정_코드표!$G$2:$G$101,MATCH(TRIM(RIGHT(SUBSTITUTE(TRIM(F13&"")," ",REPT(" ",60)),60)),설정_코드표!$F$2:$F$101,0)),"⚠"&TRIM(F13&""))),"⚠"&TRIM(F13&"")) | O13: =IFERROR(IF(TRIM(G13&"")="","",IF(AND(ISNUMBER(FIND(" ",TRIM(G13&""))),ISNUMBER(MATCH(LEFT(TRIM(G13&""),FIND(" ",TRIM(G13&""))-1),설정_코드표!$J$2:$J$101,0)),ISNUMBER(MATCH(TRIM(RIGHT(SUBSTITUTE(TRIM(G13&"")," ",REPT(" ",60)),60)),설정_코드표!$F$2:$F$101,0))),INDEX(설정_코드표!$K$2:$K$101,MATCH(LEFT(TRIM(G13&""),FIND(" ",TRIM(G13&""))-1),설정_코드표!$J$2:$J$101,0))&" "&INDEX(설정_코드표!$G$2:$G$101,MATCH(TRIM(RIGHT(SUBSTITUTE(TRIM(G13&"")," ",REPT(" ",60)),60)),설정_코드표!$F$2:$F$101,0)),"⚠"&TRIM(G13&""))),"⚠"&TRIM(G13&"")) | P13: =IFERROR(IF(TRIM(H13&"")="","",IF(AND(ISNUMBER(FIND(" ",TRIM(H13&""))),ISNUMBER(MATCH(LEFT(TRIM(H13&""),FIND(" ",TRIM(H13&""))-1),설정_코드표!$J$2:$J$101,0)),ISNUMBER(MATCH(TRIM(RIGHT(SUBSTITUTE(TRIM(H13&"")," ",REPT(" ",60)),60)),설정_코드표!$F$2:$F$101,0))),INDEX(설정_코드표!$K$2:$K$101,MATCH(LEFT(TRIM(H13&""),FIND(" ",TRIM(H13&""))-1),설정_코드표!$J$2:$J$101,0))&" "&INDEX(설정_코드표!$G$2:$G$101,MATCH(TRIM(RIGHT(SUBSTITUTE(TRIM(H13&"")," ",REPT(" ",60)),60)),설정_코드표!$F$2:$F$101,0)),"⚠"&TRIM(H13&""))),"⚠"&TRIM(H13&"")) | Q13: =IFERROR(IF(TRIM(I13&"")="","",IF(AND(ISNUMBER(FIND(" ",TRIM(I13&""))),ISNUMBER(MATCH(LEFT(TRIM(I13&""),FIND(" ",TRIM(I13&""))-1),설정_코드표!$J$2:$J$101,0)),ISNUMBER(MATCH(TRIM(RIGHT(SUBSTITUTE(TRIM(I13&"")," ",REPT(" ",60)),60)),설정_코드표!$F$2:$F$101,0))),INDEX(설정_코드표!$K$2:$K$101,MATCH(LEFT(TRIM(I13&""),FIND(" ",TRIM(I13&""))-1),설정_코드표!$J$2:$J$101,0))&" "&INDEX(설정_코드표!$G$2:$G$101,MATCH(TRIM(RIGHT(SUBSTITUTE(TRIM(I13&"")," ",REPT(" ",60)),60)),설정_코드표!$F$2:$F$101,0)),"⚠"&TRIM(I13&""))),"⚠"&TRIM(I13&"")) | R13: =IFERROR(IF(TRIM(J13&"")="","",IF(AND(ISNUMBER(FIND(" ",TRIM(J13&""))),ISNUMBER(MATCH(LEFT(TRIM(J13&""),FIND(" ",TRIM(J13&""))-1),설정_코드표!$J$2:$J$101,0)),ISNUMBER(MATCH(TRIM(RIGHT(SUBSTITUTE(TRIM(J13&"")," ",REPT(" ",60)),60)),설정_코드표!$F$2:$F$101,0))),INDEX(설정_코드표!$K$2:$K$101,MATCH(LEFT(TRIM(J13&""),FIND(" ",TRIM(J13&""))-1),설정_코드표!$J$2:$J$101,0))&" "&INDEX(설정_코드표!$G$2:$G$101,MATCH(TRIM(RIGHT(SUBSTITUTE(TRIM(J13&"")," ",REPT(" ",60)),60)),설정_코드표!$F$2:$F$101,0)),"⚠"&TRIM(J13&""))),"⚠"&TRIM(J13&"")) | S13: =IF(K13="","",IFERROR(IF(AND(ROUND((VALUE(K13&"")-INT(VALUE(K13&"")))*100,0)>=1,ROUND((VALUE(K13&"")-INT(VALUE(K13&"")))*100,0)<=12,INT(VALUE(K13&""))>=1900),DATE(INT(VALUE(K13&"")),ROUND((VALUE(K13&"")-INT(VALUE(K13&"")))*100,0),1),K13&""),K13&"")) | T13: =COUNTIF(M13:R13,"⚠*")
M14: =IFERROR(IF(TRIM(E14&"")="","",IF(AND(ISNUMBER(FIND(" ",TRIM(E14&""))),ISNUMBER(MATCH(LEFT(TRIM(E14&""),FIND(" ",TRIM(E14&""))-1),설정_코드표!$J$2:$J$101,0)),ISNUMBER(MATCH(TRIM(RIGHT(SUBSTITUTE(TRIM(E14&"")," ",REPT(" ",60)),60)),설정_코드표!$F$2:$F$101,0))),INDEX(설정_코드표!$K$2:$K$101,MATCH(LEFT(TRIM(E14&""),FIND(" ",TRIM(E14&""))-1),설정_코드표!$J$2:$J$101,0))&" "&INDEX(설정_코드표!$G$2:$G$101,MATCH(TRIM(RIGHT(SUBSTITUTE(TRIM(E14&"")," ",REPT(" ",60)),60)),설정_코드표!$F$2:$F$101,0)),"⚠"&TRIM(E14&""))),"⚠"&TRIM(E14&"")) | N14: =IFERROR(IF(TRIM(F14&"")="","",IF(AND(ISNUMBER(FIND(" ",TRIM(F14&""))),ISNUMBER(MATCH(LEFT(TRIM(F14&""),FIND(" ",TRIM(F14&""))-1),설정_코드표!$J$2:$J$101,0)),ISNUMBER(MATCH(TRIM(RIGHT(SUBSTITUTE(TRIM(F14&"")," ",REPT(" ",60)),60)),설정_코드표!$F$2:$F$101,0))),INDEX(설정_코드표!$K$2:$K$101,MATCH(LEFT(TRIM(F14&""),FIND(" ",TRIM(F14&""))-1),설정_코드표!$J$2:$J$101,0))&" "&INDEX(설정_코드표!$G$2:$G$101,MATCH(TRIM(RIGHT(SUBSTITUTE(TRIM(F14&"")," ",REPT(" ",60)),60)),설정_코드표!$F$2:$F$101,0)),"⚠"&TRIM(F14&""))),"⚠"&TRIM(F14&"")) | O14: =IFERROR(IF(TRIM(G14&"")="","",IF(AND(ISNUMBER(FIND(" ",TRIM(G14&""))),ISNUMBER(MATCH(LEFT(TRIM(G14&""),FIND(" ",TRIM(G14&""))-1),설정_코드표!$J$2:$J$101,0)),ISNUMBER(MATCH(TRIM(RIGHT(SUBSTITUTE(TRIM(G14&"")," ",REPT(" ",60)),60)),설정_코드표!$F$2:$F$101,0))),INDEX(설정_코드표!$K$2:$K$101,MATCH(LEFT(TRIM(G14&""),FIND(" ",TRIM(G14&""))-1),설정_코드표!$J$2:$J$101,0))&" "&INDEX(설정_코드표!$G$2:$G$101,MATCH(TRIM(RIGHT(SUBSTITUTE(TRIM(G14&"")," ",REPT(" ",60)),60)),설정_코드표!$F$2:$F$101,0)),"⚠"&TRIM(G14&""))),"⚠"&TRIM(G14&"")) | P14: =IFERROR(IF(TRIM(H14&"")="","",IF(AND(ISNUMBER(FIND(" ",TRIM(H14&""))),ISNUMBER(MATCH(LEFT(TRIM(H14&""),FIND(" ",TRIM(H14&""))-1),설정_코드표!$J$2:$J$101,0)),ISNUMBER(MATCH(TRIM(RIGHT(SUBSTITUTE(TRIM(H14&"")," ",REPT(" ",60)),60)),설정_코드표!$F$2:$F$101,0))),INDEX(설정_코드표!$K$2:$K$101,MATCH(LEFT(TRIM(H14&""),FIND(" ",TRIM(H14&""))-1),설정_코드표!$J$2:$J$101,0))&" "&INDEX(설정_코드표!$G$2:$G$101,MATCH(TRIM(RIGHT(SUBSTITUTE(TRIM(H14&"")," ",REPT(" ",60)),60)),설정_코드표!$F$2:$F$101,0)),"⚠"&TRIM(H14&""))),"⚠"&TRIM(H14&"")) | Q14: =IFERROR(IF(TRIM(I14&"")="","",IF(AND(ISNUMBER(FIND(" ",TRIM(I14&""))),ISNUMBER(MATCH(LEFT(TRIM(I14&""),FIND(" ",TRIM(I14&""))-1),설정_코드표!$J$2:$J$101,0)),ISNUMBER(MATCH(TRIM(RIGHT(SUBSTITUTE(TRIM(I14&"")," ",REPT(" ",60)),60)),설정_코드표!$F$2:$F$101,0))),INDEX(설정_코드표!$K$2:$K$101,MATCH(LEFT(TRIM(I14&""),FIND(" ",TRIM(I14&""))-1),설정_코드표!$J$2:$J$101,0))&" "&INDEX(설정_코드표!$G$2:$G$101,MATCH(TRIM(RIGHT(SUBSTITUTE(TRIM(I14&"")," ",REPT(" ",60)),60)),설정_코드표!$F$2:$F$101,0)),"⚠"&TRIM(I14&""))),"⚠"&TRIM(I14&"")) | R14: =IFERROR(IF(TRIM(J14&"")="","",IF(AND(ISNUMBER(FIND(" ",TRIM(J14&""))),ISNUMBER(MATCH(LEFT(TRIM(J14&""),FIND(" ",TRIM(J14&""))-1),설정_코드표!$J$2:$J$101,0)),ISNUMBER(MATCH(TRIM(RIGHT(SUBSTITUTE(TRIM(J14&"")," ",REPT(" ",60)),60)),설정_코드표!$F$2:$F$101,0))),INDEX(설정_코드표!$K$2:$K$101,MATCH(LEFT(TRIM(J14&""),FIND(" ",TRIM(J14&""))-1),설정_코드표!$J$2:$J$101,0))&" "&INDEX(설정_코드표!$G$2:$G$101,MATCH(TRIM(RIGHT(SUBSTITUTE(TRIM(J14&"")," ",REPT(" ",60)),60)),설정_코드표!$F$2:$F$101,0)),"⚠"&TRIM(J14&""))),"⚠"&TRIM(J14&"")) | S14: =IF(K14="","",IFERROR(IF(AND(ROUND((VALUE(K14&"")-INT(VALUE(K14&"")))*100,0)>=1,ROUND((VALUE(K14&"")-INT(VALUE(K14&"")))*100,0)<=12,INT(VALUE(K14&""))>=1900),DATE(INT(VALUE(K14&"")),ROUND((VALUE(K14&"")-INT(VALUE(K14&"")))*100,0),1),K14&""),K14&"")) | T14: =COUNTIF(M14:R14,"⚠*")
M15: =IFERROR(IF(TRIM(E15&"")="","",IF(AND(ISNUMBER(FIND(" ",TRIM(E15&""))),ISNUMBER(MATCH(LEFT(TRIM(E15&""),FIND(" ",TRIM(E15&""))-1),설정_코드표!$J$2:$J$101,0)),ISNUMBER(MATCH(TRIM(RIGHT(SUBSTITUTE(TRIM(E15&"")," ",REPT(" ",60)),60)),설정_코드표!$F$2:$F$101,0))),INDEX(설정_코드표!$K$2:$K$101,MATCH(LEFT(TRIM(E15&""),FIND(" ",TRIM(E15&""))-1),설정_코드표!$J$2:$J$101,0))&" "&INDEX(설정_코드표!$G$2:$G$101,MATCH(TRIM(RIGHT(SUBSTITUTE(TRIM(E15&"")," ",REPT(" ",60)),60)),설정_코드표!$F$2:$F$101,0)),"⚠"&TRIM(E15&""))),"⚠"&TRIM(E15&"")) | N15: =IFERROR(IF(TRIM(F15&"")="","",IF(AND(ISNUMBER(FIND(" ",TRIM(F15&""))),ISNUMBER(MATCH(LEFT(TRIM(F15&""),FIND(" ",TRIM(F15&""))-1),설정_코드표!$J$2:$J$101,0)),ISNUMBER(MATCH(TRIM(RIGHT(SUBSTITUTE(TRIM(F15&"")," ",REPT(" ",60)),60)),설정_코드표!$F$2:$F$101,0))),INDEX(설정_코드표!$K$2:$K$101,MATCH(LEFT(TRIM(F15&""),FIND(" ",TRIM(F15&""))-1),설정_코드표!$J$2:$J$101,0))&" "&INDEX(설정_코드표!$G$2:$G$101,MATCH(TRIM(RIGHT(SUBSTITUTE(TRIM(F15&"")," ",REPT(" ",60)),60)),설정_코드표!$F$2:$F$101,0)),"⚠"&TRIM(F15&""))),"⚠"&TRIM(F15&"")) | O15: =IFERROR(IF(TRIM(G15&"")="","",IF(AND(ISNUMBER(FIND(" ",TRIM(G15&""))),ISNUMBER(MATCH(LEFT(TRIM(G15&""),FIND(" ",TRIM(G15&""))-1),설정_코드표!$J$2:$J$101,0)),ISNUMBER(MATCH(TRIM(RIGHT(SUBSTITUTE(TRIM(G15&"")," ",REPT(" ",60)),60)),설정_코드표!$F$2:$F$101,0))),INDEX(설정_코드표!$K$2:$K$101,MATCH(LEFT(TRIM(G15&""),FIND(" ",TRIM(G15&""))-1),설정_코드표!$J$2:$J$101,0))&" "&INDEX(설정_코드표!$G$2:$G$101,MATCH(TRIM(RIGHT(SUBSTITUTE(TRIM(G15&"")," ",REPT(" ",60)),60)),설정_코드표!$F$2:$F$101,0)),"⚠"&TRIM(G15&""))),"⚠"&TRIM(G15&"")) | P15: =IFERROR(IF(TRIM(H15&"")="","",IF(AND(ISNUMBER(FIND(" ",TRIM(H15&""))),ISNUMBER(MATCH(LEFT(TRIM(H15&""),FIND(" ",TRIM(H15&""))-1),설정_코드표!$J$2:$J$101,0)),ISNUMBER(MATCH(TRIM(RIGHT(SUBSTITUTE(TRIM(H15&"")," ",REPT(" ",60)),60)),설정_코드표!$F$2:$F$101,0))),INDEX(설정_코드표!$K$2:$K$101,MATCH(LEFT(TRIM(H15&""),FIND(" ",TRIM(H15&""))-1),설정_코드표!$J$2:$J$101,0))&" "&INDEX(설정_코드표!$G$2:$G$101,MATCH(TRIM(RIGHT(SUBSTITUTE(TRIM(H15&"")," ",REPT(" ",60)),60)),설정_코드표!$F$2:$F$101,0)),"⚠"&TRIM(H15&""))),"⚠"&TRIM(H15&"")) | Q15: =IFERROR(IF(TRIM(I15&"")="","",IF(AND(ISNUMBER(FIND(" ",TRIM(I15&""))),ISNUMBER(MATCH(LEFT(TRIM(I15&""),FIND(" ",TRIM(I15&""))-1),설정_코드표!$J$2:$J$101,0)),ISNUMBER(MATCH(TRIM(RIGHT(SUBSTITUTE(TRIM(I15&"")," ",REPT(" ",60)),60)),설정_코드표!$F$2:$F$101,0))),INDEX(설정_코드표!$K$2:$K$101,MATCH(LEFT(TRIM(I15&""),FIND(" ",TRIM(I15&""))-1),설정_코드표!$J$2:$J$101,0))&" "&INDEX(설정_코드표!$G$2:$G$101,MATCH(TRIM(RIGHT(SUBSTITUTE(TRIM(I15&"")," ",REPT(" ",60)),60)),설정_코드표!$F$2:$F$101,0)),"⚠"&TRIM(I15&""))),"⚠"&TRIM(I15&"")) | R15: =IFERROR(IF(TRIM(J15&"")="","",IF(AND(ISNUMBER(FIND(" ",TRIM(J15&""))),ISNUMBER(MATCH(LEFT(TRIM(J15&""),FIND(" ",TRIM(J15&""))-1),설정_코드표!$J$2:$J$101,0)),ISNUMBER(MATCH(TRIM(RIGHT(SUBSTITUTE(TRIM(J15&"")," ",REPT(" ",60)),60)),설정_코드표!$F$2:$F$101,0))),INDEX(설정_코드표!$K$2:$K$101,MATCH(LEFT(TRIM(J15&""),FIND(" ",TRIM(J15&""))-1),설정_코드표!$J$2:$J$101,0))&" "&INDEX(설정_코드표!$G$2:$G$101,MATCH(TRIM(RIGHT(SUBSTITUTE(TRIM(J15&"")," ",REPT(" ",60)),60)),설정_코드표!$F$2:$F$101,0)),"⚠"&TRIM(J15&""))),"⚠"&TRIM(J15&"")) | S15: =IF(K15="","",IFERROR(IF(AND(ROUND((VALUE(K15&"")-INT(VALUE(K15&"")))*100,0)>=1,ROUND((VALUE(K15&"")-INT(VALUE(K15&"")))*100,0)<=12,INT(VALUE(K15&""))>=1900),DATE(INT(VALUE(K15&"")),ROUND((VALUE(K15&"")-INT(VALUE(K15&"")))*100,0),1),K15&""),K15&"")) | T15: =COUNTIF(M15:R15,"⚠*")
M16: =IFERROR(IF(TRIM(E16&"")="","",IF(AND(ISNUMBER(FIND(" ",TRIM(E16&""))),ISNUMBER(MATCH(LEFT(TRIM(E16&""),FIND(" ",TRIM(E16&""))-1),설정_코드표!$J$2:$J$101,0)),ISNUMBER(MATCH(TRIM(RIGHT(SUBSTITUTE(TRIM(E16&"")," ",REPT(" ",60)),60)),설정_코드표!$F$2:$F$101,0))),INDEX(설정_코드표!$K$2:$K$101,MATCH(LEFT(TRIM(E16&""),FIND(" ",TRIM(E16&""))-1),설정_코드표!$J$2:$J$101,0))&" "&INDEX(설정_코드표!$G$2:$G$101,MATCH(TRIM(RIGHT(SUBSTITUTE(TRIM(E16&"")," ",REPT(" ",60)),60)),설정_코드표!$F$2:$F$101,0)),"⚠"&TRIM(E16&""))),"⚠"&TRIM(E16&"")) | N16: =IFERROR(IF(TRIM(F16&"")="","",IF(AND(ISNUMBER(FIND(" ",TRIM(F16&""))),ISNUMBER(MATCH(LEFT(TRIM(F16&""),FIND(" ",TRIM(F16&""))-1),설정_코드표!$J$2:$J$101,0)),ISNUMBER(MATCH(TRIM(RIGHT(SUBSTITUTE(TRIM(F16&"")," ",REPT(" ",60)),60)),설정_코드표!$F$2:$F$101,0))),INDEX(설정_코드표!$K$2:$K$101,MATCH(LEFT(TRIM(F16&""),FIND(" ",TRIM(F16&""))-1),설정_코드표!$J$2:$J$101,0))&" "&INDEX(설정_코드표!$G$2:$G$101,MATCH(TRIM(RIGHT(SUBSTITUTE(TRIM(F16&"")," ",REPT(" ",60)),60)),설정_코드표!$F$2:$F$101,0)),"⚠"&TRIM(F16&""))),"⚠"&TRIM(F16&"")) | O16: =IFERROR(IF(TRIM(G16&"")="","",IF(AND(ISNUMBER(FIND(" ",TRIM(G16&""))),ISNUMBER(MATCH(LEFT(TRIM(G16&""),FIND(" ",TRIM(G16&""))-1),설정_코드표!$J$2:$J$101,0)),ISNUMBER(MATCH(TRIM(RIGHT(SUBSTITUTE(TRIM(G16&"")," ",REPT(" ",60)),60)),설정_코드표!$F$2:$F$101,0))),INDEX(설정_코드표!$K$2:$K$101,MATCH(LEFT(TRIM(G16&""),FIND(" ",TRIM(G16&""))-1),설정_코드표!$J$2:$J$101,0))&" "&INDEX(설정_코드표!$G$2:$G$101,MATCH(TRIM(RIGHT(SUBSTITUTE(TRIM(G16&"")," ",REPT(" ",60)),60)),설정_코드표!$F$2:$F$101,0)),"⚠"&TRIM(G16&""))),"⚠"&TRIM(G16&"")) | P16: =IFERROR(IF(TRIM(H16&"")="","",IF(AND(ISNUMBER(FIND(" ",TRIM(H16&""))),ISNUMBER(MATCH(LEFT(TRIM(H16&""),FIND(" ",TRIM(H16&""))-1),설정_코드표!$J$2:$J$101,0)),ISNUMBER(MATCH(TRIM(RIGHT(SUBSTITUTE(TRIM(H16&"")," ",REPT(" ",60)),60)),설정_코드표!$F$2:$F$101,0))),INDEX(설정_코드표!$K$2:$K$101,MATCH(LEFT(TRIM(H16&""),FIND(" ",TRIM(H16&""))-1),설정_코드표!$J$2:$J$101,0))&" "&INDEX(설정_코드표!$G$2:$G$101,MATCH(TRIM(RIGHT(SUBSTITUTE(TRIM(H16&"")," ",REPT(" ",60)),60)),설정_코드표!$F$2:$F$101,0)),"⚠"&TRIM(H16&""))),"⚠"&TRIM(H16&"")) | Q16: =IFERROR(IF(TRIM(I16&"")="","",IF(AND(ISNUMBER(FIND(" ",TRIM(I16&""))),ISNUMBER(MATCH(LEFT(TRIM(I16&""),FIND(" ",TRIM(I16&""))-1),설정_코드표!$J$2:$J$101,0)),ISNUMBER(MATCH(TRIM(RIGHT(SUBSTITUTE(TRIM(I16&"")," ",REPT(" ",60)),60)),설정_코드표!$F$2:$F$101,0))),INDEX(설정_코드표!$K$2:$K$101,MATCH(LEFT(TRIM(I16&""),FIND(" ",TRIM(I16&""))-1),설정_코드표!$J$2:$J$101,0))&" "&INDEX(설정_코드표!$G$2:$G$101,MATCH(TRIM(RIGHT(SUBSTITUTE(TRIM(I16&"")," ",REPT(" ",60)),60)),설정_코드표!$F$2:$F$101,0)),"⚠"&TRIM(I16&""))),"⚠"&TRIM(I16&"")) | R16: =IFERROR(IF(TRIM(J16&"")="","",IF(AND(ISNUMBER(FIND(" ",TRIM(J16&""))),ISNUMBER(MATCH(LEFT(TRIM(J16&""),FIND(" ",TRIM(J16&""))-1),설정_코드표!$J$2:$J$101,0)),ISNUMBER(MATCH(TRIM(RIGHT(SUBSTITUTE(TRIM(J16&"")," ",REPT(" ",60)),60)),설정_코드표!$F$2:$F$101,0))),INDEX(설정_코드표!$K$2:$K$101,MATCH(LEFT(TRIM(J16&""),FIND(" ",TRIM(J16&""))-1),설정_코드표!$J$2:$J$101,0))&" "&INDEX(설정_코드표!$G$2:$G$101,MATCH(TRIM(RIGHT(SUBSTITUTE(TRIM(J16&"")," ",REPT(" ",60)),60)),설정_코드표!$F$2:$F$101,0)),"⚠"&TRIM(J16&""))),"⚠"&TRIM(J16&"")) | S16: =IF(K16="","",IFERROR(IF(AND(ROUND((VALUE(K16&"")-INT(VALUE(K16&"")))*100,0)>=1,ROUND((VALUE(K16&"")-INT(VALUE(K16&"")))*100,0)<=12,INT(VALUE(K16&""))>=1900),DATE(INT(VALUE(K16&"")),ROUND((VALUE(K16&"")-INT(VALUE(K16&"")))*100,0),1),K16&""),K16&"")) | T16: =COUNTIF(M16:R16,"⚠*")
M17: =IFERROR(IF(TRIM(E17&"")="","",IF(AND(ISNUMBER(FIND(" ",TRIM(E17&""))),ISNUMBER(MATCH(LEFT(TRIM(E17&""),FIND(" ",TRIM(E17&""))-1),설정_코드표!$J$2:$J$101,0)),ISNUMBER(MATCH(TRIM(RIGHT(SUBSTITUTE(TRIM(E17&"")," ",REPT(" ",60)),60)),설정_코드표!$F$2:$F$101,0))),INDEX(설정_코드표!$K$2:$K$101,MATCH(LEFT(TRIM(E17&""),FIND(" ",TRIM(E17&""))-1),설정_코드표!$J$2:$J$101,0))&" "&INDEX(설정_코드표!$G$2:$G$101,MATCH(TRIM(RIGHT(SUBSTITUTE(TRIM(E17&"")," ",REPT(" ",60)),60)),설정_코드표!$F$2:$F$101,0)),"⚠"&TRIM(E17&""))),"⚠"&TRIM(E17&"")) | N17: =IFERROR(IF(TRIM(F17&"")="","",IF(AND(ISNUMBER(FIND(" ",TRIM(F17&""))),ISNUMBER(MATCH(LEFT(TRIM(F17&""),FIND(" ",TRIM(F17&""))-1),설정_코드표!$J$2:$J$101,0)),ISNUMBER(MATCH(TRIM(RIGHT(SUBSTITUTE(TRIM(F17&"")," ",REPT(" ",60)),60)),설정_코드표!$F$2:$F$101,0))),INDEX(설정_코드표!$K$2:$K$101,MATCH(LEFT(TRIM(F17&""),FIND(" ",TRIM(F17&""))-1),설정_코드표!$J$2:$J$101,0))&" "&INDEX(설정_코드표!$G$2:$G$101,MATCH(TRIM(RIGHT(SUBSTITUTE(TRIM(F17&"")," ",REPT(" ",60)),60)),설정_코드표!$F$2:$F$101,0)),"⚠"&TRIM(F17&""))),"⚠"&TRIM(F17&"")) | O17: =IFERROR(IF(TRIM(G17&"")="","",IF(AND(ISNUMBER(FIND(" ",TRIM(G17&""))),ISNUMBER(MATCH(LEFT(TRIM(G17&""),FIND(" ",TRIM(G17&""))-1),설정_코드표!$J$2:$J$101,0)),ISNUMBER(MATCH(TRIM(RIGHT(SUBSTITUTE(TRIM(G17&"")," ",REPT(" ",60)),60)),설정_코드표!$F$2:$F$101,0))),INDEX(설정_코드표!$K$2:$K$101,MATCH(LEFT(TRIM(G17&""),FIND(" ",TRIM(G17&""))-1),설정_코드표!$J$2:$J$101,0))&" "&INDEX(설정_코드표!$G$2:$G$101,MATCH(TRIM(RIGHT(SUBSTITUTE(TRIM(G17&"")," ",REPT(" ",60)),60)),설정_코드표!$F$2:$F$101,0)),"⚠"&TRIM(G17&""))),"⚠"&TRIM(G17&"")) | P17: =IFERROR(IF(TRIM(H17&"")="","",IF(AND(ISNUMBER(FIND(" ",TRIM(H17&""))),ISNUMBER(MATCH(LEFT(TRIM(H17&""),FIND(" ",TRIM(H17&""))-1),설정_코드표!$J$2:$J$101,0)),ISNUMBER(MATCH(TRIM(RIGHT(SUBSTITUTE(TRIM(H17&"")," ",REPT(" ",60)),60)),설정_코드표!$F$2:$F$101,0))),INDEX(설정_코드표!$K$2:$K$101,MATCH(LEFT(TRIM(H17&""),FIND(" ",TRIM(H17&""))-1),설정_코드표!$J$2:$J$101,0))&" "&INDEX(설정_코드표!$G$2:$G$101,MATCH(TRIM(RIGHT(SUBSTITUTE(TRIM(H17&"")," ",REPT(" ",60)),60)),설정_코드표!$F$2:$F$101,0)),"⚠"&TRIM(H17&""))),"⚠"&TRIM(H17&"")) | Q17: =IFERROR(IF(TRIM(I17&"")="","",IF(AND(ISNUMBER(FIND(" ",TRIM(I17&""))),ISNUMBER(MATCH(LEFT(TRIM(I17&""),FIND(" ",TRIM(I17&""))-1),설정_코드표!$J$2:$J$101,0)),ISNUMBER(MATCH(TRIM(RIGHT(SUBSTITUTE(TRIM(I17&"")," ",REPT(" ",60)),60)),설정_코드표!$F$2:$F$101,0))),INDEX(설정_코드표!$K$2:$K$101,MATCH(LEFT(TRIM(I17&""),FIND(" ",TRIM(I17&""))-1),설정_코드표!$J$2:$J$101,0))&" "&INDEX(설정_코드표!$G$2:$G$101,MATCH(TRIM(RIGHT(SUBSTITUTE(TRIM(I17&"")," ",REPT(" ",60)),60)),설정_코드표!$F$2:$F$101,0)),"⚠"&TRIM(I17&""))),"⚠"&TRIM(I17&"")) | R17: =IFERROR(IF(TRIM(J17&"")="","",IF(AND(ISNUMBER(FIND(" ",TRIM(J17&""))),ISNUMBER(MATCH(LEFT(TRIM(J17&""),FIND(" ",TRIM(J17&""))-1),설정_코드표!$J$2:$J$101,0)),ISNUMBER(MATCH(TRIM(RIGHT(SUBSTITUTE(TRIM(J17&"")," ",REPT(" ",60)),60)),설정_코드표!$F$2:$F$101,0))),INDEX(설정_코드표!$K$2:$K$101,MATCH(LEFT(TRIM(J17&""),FIND(" ",TRIM(J17&""))-1),설정_코드표!$J$2:$J$101,0))&" "&INDEX(설정_코드표!$G$2:$G$101,MATCH(TRIM(RIGHT(SUBSTITUTE(TRIM(J17&"")," ",REPT(" ",60)),60)),설정_코드표!$F$2:$F$101,0)),"⚠"&TRIM(J17&""))),"⚠"&TRIM(J17&"")) | S17: =IF(K17="","",IFERROR(IF(AND(ROUND((VALUE(K17&"")-INT(VALUE(K17&"")))*100,0)>=1,ROUND((VALUE(K17&"")-INT(VALUE(K17&"")))*100,0)<=12,INT(VALUE(K17&""))>=1900),DATE(INT(VALUE(K17&"")),ROUND((VALUE(K17&"")-INT(VALUE(K17&"")))*100,0),1),K17&""),K17&"")) | T17: =COUNTIF(M17:R17,"⚠*")
... M402: =IFERROR(IF(TRIM(E402&"")="","",IF(AND(ISNUMBER(FIND(" ",TRIM(E402&""))),ISNUMBER(MATCH(LEFT(TRIM(E402&""),FIND(" ",TRIM(E402&""))-1),설정_코드표!$J$2:$J$101,0)),ISNUMBER(MATCH(TRIM(RIGHT(SUBSTITUTE(TRIM(E402&"")," ",REPT(" ",60)),60)),설정_코드표!$F$2:$F$101,0))),INDEX(설정_코드표!$K$2:$K$101,MATCH(LEFT(TRIM(E402&""),FIND(" ",TRIM(E402&""))-1),설정_코드표!$J$2:$J$101,0))&" "&INDEX(설정_코드표!$G$2:$G$101,MATCH(TRIM(RIGHT(SUBSTITUTE(TRIM(E402&"")," ",REPT(" ",60)),60)),설정_코드표!$F$2:$F$101,0)),"⚠"&TRIM(E402&""))),"⚠"&TRIM(E402&"")) | N402: =IFERROR(IF(TRIM(F402&"")="","",IF(AND(ISNUMBER(FIND(" ",TRIM(F402&""))),ISNUMBER(MATCH(LEFT(TRIM(F402&""),FIND(" ",TRIM(F402&""))-1),설정_코드표!$J$2:$J$101,0)),ISNUMBER(MATCH(TRIM(RIGHT(SUBSTITUTE(TRIM(F402&"")," ",REPT(" ",60)),60)),설정_코드표!$F$2:$F$101,0))),INDEX(설정_코드표!$K$2:$K$101,MATCH(LEFT(TRIM(F402&""),FIND(" ",TRIM(F402&""))-1),설정_코드표!$J$2:$J$101,0))&" "&INDEX(설정_코드표!$G$2:$G$101,MATCH(TRIM(RIGHT(SUBSTITUTE(TRIM(F402&"")," ",REPT(" ",60)),60)),설정_코드표!$F$2:$F$101,0)),"⚠"&TRIM(F402&""))),"⚠"&TRIM(F402&"")) | O402: =IFERROR(IF(TRIM(G402&"")="","",IF(AND(ISNUMBER(FIND(" ",TRIM(G402&""))),ISNUMBER(MATCH(LEFT(TRIM(G402&""),FIND(" ",TRIM(G402&""))-1),설정_코드표!$J$2:$J$101,0)),ISNUMBER(MATCH(TRIM(RIGHT(SUBSTITUTE(TRIM(G402&"")," ",REPT(" ",60)),60)),설정_코드표!$F$2:$F$101,0))),INDEX(설정_코드표!$K$2:$K$101,MATCH(LEFT(TRIM(G402&""),FIND(" ",TRIM(G402&""))-1),설정_코드표!$J$2:$J$101,0))&" "&INDEX(설정_코드표!$G$2:$G$101,MATCH(TRIM(RIGHT(SUBSTITUTE(TRIM(G402&"")," ",REPT(" ",60)),60)),설정_코드표!$F$2:$F$101,0)),"⚠"&TRIM(G402&""))),"⚠"&TRIM(G402&"")) | P402: =IFERROR(IF(TRIM(H402&"")="","",IF(AND(ISNUMBER(FIND(" ",TRIM(H402&""))),ISNUMBER(MATCH(LEFT(TRIM(H402&""),FIND(" ",TRIM(H402&""))-1),설정_코드표!$J$2:$J$101,0)),ISNUMBER(MATCH(TRIM(RIGHT(SUBSTITUTE(TRIM(H402&"")," ",REPT(" ",60)),60)),설정_코드표!$F$2:$F$101,0))),INDEX(설정_코드표!$K$2:$K$101,MATCH(LEFT(TRIM(H402&""),FIND(" ",TRIM(H402&""))-1),설정_코드표!$J$2:$J$101,0))&" "&INDEX(설정_코드표!$G$2:$G$101,MATCH(TRIM(RIGHT(SUBSTITUTE(TRIM(H402&"")," ",REPT(" ",60)),60)),설정_코드표!$F$2:$F$101,0)),"⚠"&TRIM(H402&""))),"⚠"&TRIM(H402&"")) | Q402: =IFERROR(IF(TRIM(I402&"")="","",IF(AND(ISNUMBER(FIND(" ",TRIM(I402&""))),ISNUMBER(MATCH(LEFT(TRIM(I402&""),FIND(" ",TRIM(I402&""))-1),설정_코드표!$J$2:$J$101,0)),ISNUMBER(MATCH(TRIM(RIGHT(SUBSTITUTE(TRIM(I402&"")," ",REPT(" ",60)),60)),설정_코드표!$F$2:$F$101,0))),INDEX(설정_코드표!$K$2:$K$101,MATCH(LEFT(TRIM(I402&""),FIND(" ",TRIM(I402&""))-1),설정_코드표!$J$2:$J$101,0))&" "&INDEX(설정_코드표!$G$2:$G$101,MATCH(TRIM(RIGHT(SUBSTITUTE(TRIM(I402&"")," ",REPT(" ",60)),60)),설정_코드표!$F$2:$F$101,0)),"⚠"&TRIM(I402&""))),"⚠"&TRIM(I402&"")) | R402: =IFERROR(IF(TRIM(J402&"")="","",IF(AND(ISNUMBER(FIND(" ",TRIM(J402&""))),ISNUMBER(MATCH(LEFT(TRIM(J402&""),FIND(" ",TRIM(J402&""))-1),설정_코드표!$J$2:$J$101,0)),ISNUMBER(MATCH(TRIM(RIGHT(SUBSTITUTE(TRIM(J402&"")," ",REPT(" ",60)),60)),설정_코드표!$F$2:$F$101,0))),INDEX(설정_코드표!$K$2:$K$101,MATCH(LEFT(TRIM(J402&""),FIND(" ",TRIM(J402&""))-1),설정_코드표!$J$2:$J$101,0))&" "&INDEX(설정_코드표!$G$2:$G$101,MATCH(TRIM(RIGHT(SUBSTITUTE(TRIM(J402&"")," ",REPT(" ",60)),60)),설정_코드표!$F$2:$F$101,0)),"⚠"&TRIM(J402&""))),"⚠"&TRIM(J402&"")) | S402: =IF(K402="","",IFERROR(IF(AND(ROUND((VALUE(K402&"")-INT(VALUE(K402&"")))*100,0)>=1,ROUND((VALUE(K402&"")-INT(VALUE(K402&"")))*100,0)<=12,INT(VALUE(K402&""))>=1900),DATE(INT(VALUE(K402&"")),ROUND((VALUE(K402&"")-INT(VALUE(K402&"")))*100,0),1),K402&""),K402&"")) | T402: =COUNTIF(M402:R402,"⚠*")

Sheet 입력_파견수련계획
A1: 연번 | B1: 모병원명 | C1: 수련 종별 (I/R) | D1: 수련 과목 | E1: 연차 | F1: 성명 | G1: 전공의 등록번호 | H1: 파견시작일 | I1: 파견종료일 | J1: 파견일수 | K1: 파견병원 | L1: 파견 과목 | M1: 파견근거 (모자/통합수련) | N1: 비고 | Q1: ↓ 자동 계산 (수정 금지) — 병원/과목은 코드표 기준으로 통일, 인식 불가는 ⚠ 표시
Q3: 키(등록번호) | R3: 모병원(정규화) | S3: 파견병원(정규화) | T3: 파견근거(정규화) | U3: 파견과목(정규화) | V3: 파견일수(계산) | W3: 급여기준월 겹침일수 | X3: 상태 | Y3: 키|상태 | Z3: 키|기준월 | AA3: 입력 오류 | AB3: 비고 다기관 시작 | AC3: 비고 다기관 종료 | AD3: 비고 다기관 기준월 겹침일수 | AE3: 키|다기관
A4: =IF(F4="","",ROW()-3) | B4: 한양대학교병원 | C4: R | D4: 내과 | E4: 3 | F4: 박ㅇㅇ | G4: 21-1111 | H4: 46144 | I4: 46265 | J4: =IF(AND(ISNUMBER(H4),ISNUMBER(I4)),I4-H4+1,"") | K4: 한양대구리병원 | L4: 내과 | M4: 모자 | O4: 2026.09.01-2026.09.30 다기관 파견 | Q4: =IF(TRIM(G4&"")="","",TRIM(G4&"")) | R4: =IF(TRIM(B4&"")="","",IFERROR(INDEX(설정_코드표!$K$2:$K$101,MATCH(TRIM(B4&""),설정_코드표!$J$2:$J$101,0)),"⚠"&TRIM(B4&""))) | S4: =IF(TRIM(K4&"")="","",IFERROR(INDEX(설정_코드표!$K$2:$K$101,MATCH(TRIM(K4&""),설정_코드표!$J$2:$J$101,0)),"⚠"&TRIM(K4&""))) | T4: =IF(TRIM(M4&"")="","",IF(ISNUMBER(MATCH(TRIM(M4&""),설정_코드표!$C$2:$C$11,0)),TRIM(M4&""),"⚠"&TRIM(M4&""))) | U4: =IF(TRIM(L4&"")="","",IFERROR(INDEX(설정_코드표!$G$2:$G$101,MATCH(TRIM(L4&""),설정_코드표!$F$2:$F$101,0)),"⚠"&TRIM(L4&""))) | V4: =IF(AND(ISNUMBER(H4),ISNUMBER(I4)),I4-H4+1,"") | W4: =IF(ISNUMBER(H4),MAX(0,MIN(IF(ISNUMBER(I4),I4,EOMONTH(출력_요약!$B$3,0)),EOMONTH(출력_요약!$B$3,0))-MAX(H4,출력_요약!$B$3)+1),0) | X4: =IF(OR(NOT(ISNUMBER(H4)),Q4=""),"",IF(TODAY()<H4,"파견예정",IF(AND(ISNUMBER(I4),TODAY()>I4),"파견종료","파견중"))) | Y4: =IF(OR(Q4="",X4=""),"",Q4&"|"&X4) | Z4: =IF(AND(Q4<>"",W4>0),Q4&"|월","") | AA4: =IF(COUNTA(B4:I4,K4:N4)=0,"",IF(Q4="","등록번호 없음",IF(LEFT(R4,1)="⚠","모병원명 미등록",IF(S4="","파견병원 입력",IF(LEFT(S4,1)="⚠","파견병원명 미등록",IF(LEFT(U4,1)="⚠","파견과목 미등록",IF(OR(T4="",LEFT(T4,1)="⚠"),"파견근거 확인",IF(NOT(AND(ISNUMBER(H4),ISNUMBER(I4))),"날짜 형식/누락",IF(I4<H4,"종료일<시작일",""))))))))) | AB4: =IF(ISNUMBER(SEARCH("다기관",TRIM(N4&" "&O4))),IFERROR(DATE(VALUE(MID(TRIM(N4&" "&O4),1,4)),VALUE(MID(TRIM(N4&" "&O4),6,2)),VALUE(MID(TRIM(N4&" "&O4),9,2))),IF(ISNUMBER(H4),H4,"")),"") | AC4: =IF(ISNUMBER(SEARCH("다기관",TRIM(N4&" "&O4))),IFERROR(DATE(VALUE(MID(TRIM(N4&" "&O4),12,4)),VALUE(MID(TRIM(N4&" "&O4),17,2)),VALUE(MID(TRIM(N4&" "&O4),20,2))),IF(ISNUMBER(I4),I4,"")),"") | AD4: =IF(AND(ISNUMBER(AB4),ISNUMBER(AC4)),MAX(0,MIN(AC4,EOMONTH(출력_요약!$B$3,0))-MAX(AB4,출력_요약!$B$3)+1),0) | AE4: =IF(AND(Q4<>"",ISNUMBER(AB4)),Q4&"|다기관","")
A5: =IF(F5="","",ROW()-3) | B5: 한양대학교병원 | C5: R | D5: 내과 | E5: 3 | F5: 박ㅇㅇ | G5: 21-1111 | H5: 46296 | I5: 46326 | J5: =IF(AND(ISNUMBER(H5),ISNUMBER(I5)),I5-H5+1,"") | K5: 한양대구리병원 | L5: 내과 | M5: 모자 | Q5: =IF(TRIM(G5&"")="","",TRIM(G5&"")) | R5: =IF(TRIM(B5&"")="","",IFERROR(INDEX(설정_코드표!$K$2:$K$101,MATCH(TRIM(B5&""),설정_코드표!$J$2:$J$101,0)),"⚠"&TRIM(B5&""))) | S5: =IF(TRIM(K5&"")="","",IFERROR(INDEX(설정_코드표!$K$2:$K$101,MATCH(TRIM(K5&""),설정_코드표!$J$2:$J$101,0)),"⚠"&TRIM(K5&""))) | T5: =IF(TRIM(M5&"")="","",IF(ISNUMBER(MATCH(TRIM(M5&""),설정_코드표!$C$2:$C$11,0)),TRIM(M5&""),"⚠"&TRIM(M5&""))) | U5: =IF(TRIM(L5&"")="","",IFERROR(INDEX(설정_코드표!$G$2:$G$101,MATCH(TRIM(L5&""),설정_코드표!$F$2:$F$101,0)),"⚠"&TRIM(L5&""))) | V5: =IF(AND(ISNUMBER(H5),ISNUMBER(I5)),I5-H5+1,"") | W5: =IF(ISNUMBER(H5),MAX(0,MIN(IF(ISNUMBER(I5),I5,EOMONTH(출력_요약!$B$3,0)),EOMONTH(출력_요약!$B$3,0))-MAX(H5,출력_요약!$B$3)+1),0) | X5: =IF(OR(NOT(ISNUMBER(H5)),Q5=""),"",IF(TODAY()<H5,"파견예정",IF(AND(ISNUMBER(I5),TODAY()>I5),"파견종료","파견중"))) | Y5: =IF(OR(Q5="",X5=""),"",Q5&"|"&X5) | Z5: =IF(AND(Q5<>"",W5>0),Q5&"|월","") | AA5: =IF(COUNTA(B5:I5,K5:N5)=0,"",IF(Q5="","등록번호 없음",IF(LEFT(R5,1)="⚠","모병원명 미등록",IF(S5="","파견병원 입력",IF(LEFT(S5,1)="⚠","파견병원명 미등록",IF(LEFT(U5,1)="⚠","파견과목 미등록",IF(OR(T5="",LEFT(T5,1)="⚠"),"파견근거 확인",IF(NOT(AND(ISNUMBER(H5),ISNUMBER(I5))),"날짜 형식/누락",IF(I5<H5,"종료일<시작일",""))))))))) | AB5: =IF(ISNUMBER(SEARCH("다기관",TRIM(N5&" "&O5))),IFERROR(DATE(VALUE(MID(TRIM(N5&" "&O5),1,4)),VALUE(MID(TRIM(N5&" "&O5),6,2)),VALUE(MID(TRIM(N5&" "&O5),9,2))),IF(ISNUMBER(H5),H5,"")),"") | AC5: =IF(ISNUMBER(SEARCH("다기관",TRIM(N5&" "&O5))),IFERROR(DATE(VALUE(MID(TRIM(N5&" "&O5),12,4)),VALUE(MID(TRIM(N5&" "&O5),17,2)),VALUE(MID(TRIM(N5&" "&O5),20,2))),IF(ISNUMBER(I5),I5,"")),"") | AD5: =IF(AND(ISNUMBER(AB5),ISNUMBER(AC5)),MAX(0,MIN(AC5,EOMONTH(출력_요약!$B$3,0))-MAX(AB5,출력_요약!$B$3)+1),0) | AE5: =IF(AND(Q5<>"",ISNUMBER(AB5)),Q5&"|다기관","")
