Workbook
Name 급여기준월: '설정_코드표'!$P$9
Name 판정기준일: '설정_코드표'!$P$10
Name 기준월키: TEXT(급여기준월,"yyyy-mm")
Name 전월키: TEXT(EDATE(급여기준월,-1),"yyyy-mm")
Name 익월키: TEXT(EDATE(급여기준월,1),"yyyy-mm")
Name 병원목록: 병원표[병원]
Name 진료과목록: 진료과표[근무과]
Name 병원표기목록: 병원약칭표[표기]
Name 과약칭목록: 과약칭표[약칭]
Name 구리_키: '출력_구리근무자'!$K$6:$K$20005
Name 구리_이름: '출력_구리근무자'!$D$6:$D$20005
Name 구리_근무일: '출력_구리근무자'!$H$6:$H$20005
Name 구리_독자: '출력_구리근무자'!$J$6:$J$20005
Name 구리_시작: '출력_구리근무자'!$F$6:$F$20005
Name 구리_종료: '출력_구리근무자'!$G$6:$G$20005
Name 인턴위치_이번: '출력_인턴현황'!$G$3
Name 인턴위치_다음: '출력_인턴현황'!$I$3
Name 인턴위치_기준월: '출력_인턴현황'!$K$2
Name 인턴위치_전월: '출력_인턴현황'!$M$2
Name 인턴위치_익월: '출력_인턴현황'!$N$2

Sheet 사용안내
A1: 전공의·인턴 파견 모니터링 사용 안내 (Microsoft 365 · Excel 2021용, 인원 제한 없음)
A3: [시트 구분] — 탭 색: 파랑=입력, 초록=출력(자동, 입력 금지), 회색=설정
A4: • 입력_기본자료 / 입력_인턴근무계획 / 입력_전공의명단: 엑셀 '표'. 표 바로 아래(또는 첫 자료 행)에 붙여넣으면 표가 자동으로 늘어나고 초록 머리글 계산 열도 자동으로 채워집니다.
A5: • 입력_구리근무자명단: 구리병원 파일의 시트를 A1에 양식 그대로 붙여넣는 시트(병합 셀이 있어 표가 아님). 2만 행·ZZ열까지 읽습니다.
A6: • 출력_서울급여 / 출력_구리근무자 / 출력_요약 / 출력_인턴현황: 대상 수만큼 자동으로 펼쳐지는 목록(동적 배열). 셀을 지우거나 아래에 입력하지 마세요(#SPILL! 오류).
A7: • 설정_코드표: 병원·진료과·인턴구분·약칭 목록(표)과 설정값(급여 기준월·15일 기준).
A8: • 입력_월별근무지: 전월·익월(또는 어느 달이든) 근무병원을 사람별로 직접 입력하는 표. 자동 판정보다 우선합니다.
A9: • 출력_기관명단: 전월·급여 기준월·익월 3개월의 전원 기관(근무병원·급여지급병원) — 시간외근무 판정 파일의 입력_기관명단에 값으로 붙여넣는 용도
A11: [붙여넣는 방법]
A12: • 기본자료: A2부터 (머리글 순서: 현재근무 여부·사번·이름·수련과목·연차·근무지·수련개시일·전공의등록번호·의사면허번호·성별·생년월일·비고). 날짜는 20260301 형식도 됩니다.
A13: • 인턴근무계획: B3부터 자료 행(순번·이름·사번·월 6칸·비고). 학기가 바뀌면 2행의 월 머리글(9월~2월 등)도 바꿔 적으세요. 비고 2026.03 = 2026-03-01 입사.
A14: • 구리 근무자명단: 구리병원 파일의 시트를 A1에 양식 그대로(1~2행 제목, 3행 머리글, 4행부터 자료). 날짜는 'YYYY.MM.DD' 글자도 됩니다.
... A39: • 개인정보(생년월일·면허번호 등)가 포함되므로 파일 암호 설정과 접근 권한 관리를 권장합니다.

Sheet 입력_기본자료
A1: 현재근무 여부 | B1: 사번 | C1: 이름 | D1: 수련과목 | E1: 연차 | F1: 근무지 | G1: 수련개시일 | H1: 전공의등록번호 | I1: 의사면허번호 | J1: 성별 | K1: 생년월일 | L1: 비고 | M1: 사번키
A2: 재직 | B2: 2261212 | C2: 김ㅇㅇ | D2: 가정의학과 | E2: 레지던트1 | F2: 서울 | G2: 20260301 | H2: 11-1111 | I2: 111111 | J2: 여 | K2: 19999999 | M2: =IF(TRIM(기본자료표[[#This Row],[사번]]&"")="","","S|"&TRIM(기본자료표[[#This Row],[사번]]&""))
A3: 재직 | B3: 2261213 | C3: 이ㅇㅇ | D3: 내과 | E3: 레지던트2 | F3: 서울 | G3: 20250301 | H3: 11-1112 | I3: 111112 | J3: 남 | K3: 19950702 | M3: =IF(TRIM(기본자료표[[#This Row],[사번]]&"")="","","S|"&TRIM(기본자료표[[#This Row],[사번]]&""))
A4: 재직 | B4: 2261214 | C4: 박ㅇㅇ | D4: 내과 | E4: 레지던트3 | F4: 서울 | G4: 20240301 | H4: 21-1111 | I4: 111113 | J4: 여 | K4: 19970125 | M4: =IF(TRIM(기본자료표[[#This Row],[사번]]&"")="","","S|"&TRIM(기본자료표[[#This Row],[사번]]&""))
A5: 재직 | B5: 2261215 | C5: 최ㅇㅇ | D5: 산부인과 | E5: 레지던트3 | F5: 서울 | G5: 20240301 | H5: 11-1114 | I5: 111114 | J5: 남 | K5: 19961109 | M5: =IF(TRIM(기본자료표[[#This Row],[사번]]&"")="","","S|"&TRIM(기본자료표[[#This Row],[사번]]&""))
A6: 재직 | B6: 2261216 | C6: 정ㅇㅇ | D6: 마취통증의학과 | E6: 레지던트2 | F6: 구리 | G6: 20250301 | H6: 11-1115 | I6: 111115 | J6: 여 | K6: 19980530 | M6: =IF(TRIM(기본자료표[[#This Row],[사번]]&"")="","","S|"&TRIM(기본자료표[[#This Row],[사번]]&""))
A7: 재직 | B7: 222222 | C7: 김ㅇㅇ | D7: 인턴 | E7: 인턴 | F7: 서울 | G7: 20260301 | H7: 22-2222 | I7: 222222 | J7: 여 | K7: 19990101 | M7: =IF(TRIM(기본자료표[[#This Row],[사번]]&"")="","","S|"&TRIM(기본자료표[[#This Row],[사번]]&""))
A8: 재직 | B8: 222223 | C8: 이ㅇㅇ | D8: 인턴 | E8: 인턴 | F8: 서울 | G8: 20260301 | H8: 22-2223 | I8: 222223 | J8: 남 | K8: 19990202 | M8: =IF(TRIM(기본자료표[[#This Row],[사번]]&"")="","","S|"&TRIM(기본자료표[[#This Row],[사번]]&""))
A9: 재직 | B9: 222224 | C9: 박ㅇㅇ | D9: 인턴 | E9: 인턴 | F9: 구리 | G9: 20260301 | H9: 22-2224 | I9: 222224 | J9: 남 | K9: 19990303 | M9: =IF(TRIM(기본자료표[[#This Row],[사번]]&"")="","","S|"&TRIM(기본자료표[[#This Row],[사번]]&""))

Sheet 입력_인턴근무계획
B1: 2026년도 하반기 인턴근무계획표(9~2월)
B2: 순번 | C2: 이름 | D2: 사번 | E2: 9월 | F2: 10월 | G2: 11월 | H2: 12월 | I2: 1월 | J2: 2월 | K2: 비고 | L2: 사번키 | M2: 정규화1 | N2: 정규화2 | O2: 정규화3 | P2: 정규화4 | Q2: 정규화5 | R2: 정규화6 | S2: 입사일(비고) | T2: 입력오류
B3: 1 | C3: 김ㅇㅇ | D3: 222222 | E3: 구리 안과 | F3: 구리 내과 | G3: 서울 핵방 | H3: 서울 재활의학과 | I3: 제주 산부 | J3: 서울 소아과 | K3: 2026.03 | L3: =IF(TRIM(인턴계획표[[#This Row],[사번]]&"")="","","S|"&TRIM(인턴계획표[[#This Row],[사번]]&"")) | M3: =_xlfn.LET(_xlpm.v_r,TRIM(INDEX(인턴계획표[#This Row],1,4)&""),_xlpm.v_t1,IFERROR(LEFT(_xlpm.v_r,FIND(" ",_xlpm.v_r)-1),""),_xlpm.v_t2,TRIM(RIGHT(SUBSTITUTE(_xlpm.v_r," ",REPT(" ",60)),60)),_xlpm.v_h,_xlfn.XLOOKUP(_xlpm.v_t1,병원약칭표[표기],병원약칭표[정식 병원],""),_xlpm.v_d,_xlfn.XLOOKUP(_xlpm.v_t2,과약칭표[약칭],과약칭표[정식 명칭],""),IF(_xlpm.v_r="","",IF(OR(_xlpm.v_t1="",_xlpm.v_h="",_xlpm.v_d=""),"⚠"&_xlpm.v_r,_xlpm.v_h&" "&_xlpm.v_d))) | N3: =_xlfn.LET(_xlpm.v_r,TRIM(INDEX(인턴계획표[#This Row],1,5)&""),_xlpm.v_t1,IFERROR(LEFT(_xlpm.v_r,FIND(" ",_xlpm.v_r)-1),""),_xlpm.v_t2,TRIM(RIGHT(SUBSTITUTE(_xlpm.v_r," ",REPT(" ",60)),60)),_xlpm.v_h,_xlfn.XLOOKUP(_xlpm.v_t1,병원약칭표[표기],병원약칭표[정식 병원],""),_xlpm.v_d,_xlfn.XLOOKUP(_xlpm.v_t2,과약칭표[약칭],과약칭표[정식 명칭],""),IF(_xlpm.v_r="","",IF(OR(_xlpm.v_t1="",_xlpm.v_h="",_xlpm.v_d=""),"⚠"&_xlpm.v_r,_xlpm.v_h&" "&_xlpm.v_d))) | O3: =_xlfn.LET(_xlpm.v_r,TRIM(INDEX(인턴계획표[#This Row],1,6)&""),_xlpm.v_t1,IFERROR(LEFT(_xlpm.v_r,FIND(" ",_xlpm.v_r)-1),""),_xlpm.v_t2,TRIM(RIGHT(SUBSTITUTE(_xlpm.v_r," ",REPT(" ",60)),60)),_xlpm.v_h,_xlfn.XLOOKUP(_xlpm.v_t1,병원약칭표[표기],병원약칭표[정식 병원],""),_xlpm.v_d,_xlfn.XLOOKUP(_xlpm.v_t2,과약칭표[약칭],과약칭표[정식 명칭],""),IF(_xlpm.v_r="","",IF(OR(_xlpm.v_t1="",_xlpm.v_h="",_xlpm.v_d=""),"⚠"&_xlpm.v_r,_xlpm.v_h&" "&_xlpm.v_d))) | P3: =_xlfn.LET(_xlpm.v_r,TRIM(INDEX(인턴계획표[#This Row],1,7)&""),_xlpm.v_t1,IFERROR(LEFT(_xlpm.v_r,FIND(" ",_xlpm.v_r)-1),""),_xlpm.v_t2,TRIM(RIGHT(SUBSTITUTE(_xlpm.v_r," ",REPT(" ",60)),60)),_xlpm.v_h,_xlfn.XLOOKUP(_xlpm.v_t1,병원약칭표[표기],병원약칭표[정식 병원],""),_xlpm.v_d,_xlfn.XLOOKUP(_xlpm.v_t2,과약칭표[약칭],과약칭표[정식 명칭],""),IF(_xlpm.v_r="","",IF(OR(_xlpm.v_t1="",_xlpm.v_h="",_xlpm.v_d=""),"⚠"&_xlpm.v_r,_xlpm.v_h&" "&_xlpm.v_d))) | Q3: =_xlfn.LET(_xlpm.v_r,TRIM(INDEX(인턴계획표[#This Row],1,8)&""),_xlpm.v_t1,IFERROR(LEFT(_xlpm.v_r,FIND(" ",_xlpm.v_r)-1),""),_xlpm.v_t2,TRIM(RIGHT(SUBSTITUTE(_xlpm.v_r," ",REPT(" ",60)),60)),_xlpm.v_h,_xlfn.XLOOKUP(_xlpm.v_t1,병원약칭표[표기],병원약칭표[정식 병원],""),_xlpm.v_d,_xlfn.XLOOKUP(_xlpm.v_t2,과약칭표[약칭],과약칭표[정식 명칭],""),IF(_xlpm.v_r="","",IF(OR(_xlpm.v_t1="",_xlpm.v_h="",_xlpm.v_d=""),"⚠"&_xlpm.v_r,_xlpm.v_h&" "&_xlpm.v_d))) | R3: =_xlfn.LET(_xlpm.v_r,TRIM(INDEX(인턴계획표[#This Row],1,9)&""),_xlpm.v_t1,IFERROR(LEFT(_xlpm.v_r,FIND(" ",_xlpm.v_r)-1),""),_xlpm.v_t2,TRIM(RIGHT(SUBSTITUTE(_xlpm.v_r," ",REPT(" ",60)),60)),_xlpm.v_h,_xlfn.XLOOKUP(_xlpm.v_t1,병원약칭표[표기],병원약칭표[정식 병원],""),_xlpm.v_d,_xlfn.XLOOKUP(_xlpm.v_t2,과약칭표[약칭],과약칭표[정식 명칭],""),IF(_xlpm.v_r="","",IF(OR(_xlpm.v_t1="",_xlpm.v_h="",_xlpm.v_d=""),"⚠"&_xlpm.v_r,_xlpm.v_h&" "&_xlpm.v_d))) | S3: =_xlfn.LET(_xlpm.v_k,INDEX(인턴계획표[#This Row],1,10)&"",_xlpm.v_v,IFERROR(VALUE(_xlpm.v_k),""),_xlpm.v_m,IFERROR(ROUND((_xlpm.v_v-INT(_xlpm.v_v))*100,0),0),IF(_xlpm.v_k="","",IF(AND(ISNUMBER(_xlpm.v_v),_xlpm.v_m>=1,_xlpm.v_m<=12,IFERROR(INT(_xlpm.v_v),0)>=1900),DATE(INT(_xlpm.v_v),_xlpm.v_m,1),_xlpm.v_k))) | T3: =COUNTIF(인턴계획표[[#This Row],[정규화1]:[정규화6]],"⚠*")
B4: 2 | C4: 이ㅇㅇ | D4: 222223 | E4: 서울 내과 | F4: 서울 외과 | G4: 구리 통합 | H4: 인천 산부인과 | I4: 제주 에스중앙 내과 | J4: 서울 가정의학과 | K4: 2026.03 | L4: =IF(TRIM(인턴계획표[[#This Row],[사번]]&"")="","","S|"&TRIM(인턴계획표[[#This Row],[사번]]&"")) | M4: =_xlfn.LET(_xlpm.v_r,TRIM(INDEX(인턴계획표[#This Row],1,4)&""),_xlpm.v_t1,IFERROR(LEFT(_xlpm.v_r,FIND(" ",_xlpm.v_r)-1),""),_xlpm.v_t2,TRIM(RIGHT(SUBSTITUTE(_xlpm.v_r," ",REPT(" ",60)),60)),_xlpm.v_h,_xlfn.XLOOKUP(_xlpm.v_t1,병원약칭표[표기],병원약칭표[정식 병원],""),_xlpm.v_d,_xlfn.XLOOKUP(_xlpm.v_t2,과약칭표[약칭],과약칭표[정식 명칭],""),IF(_xlpm.v_r="","",IF(OR(_xlpm.v_t1="",_xlpm.v_h="",_xlpm.v_d=""),"⚠"&_xlpm.v_r,_xlpm.v_h&" "&_xlpm.v_d))) | N4: =_xlfn.LET(_xlpm.v_r,TRIM(INDEX(인턴계획표[#This Row],1,5)&""),_xlpm.v_t1,IFERROR(LEFT(_xlpm.v_r,FIND(" ",_xlpm.v_r)-1),""),_xlpm.v_t2,TRIM(RIGHT(SUBSTITUTE(_xlpm.v_r," ",REPT(" ",60)),60)),_xlpm.v_h,_xlfn.XLOOKUP(_xlpm.v_t1,병원약칭표[표기],병원약칭표[정식 병원],""),_xlpm.v_d,_xlfn.XLOOKUP(_xlpm.v_t2,과약칭표[약칭],과약칭표[정식 명칭],""),IF(_xlpm.v_r="","",IF(OR(_xlpm.v_t1="",_xlpm.v_h="",_xlpm.v_d=""),"⚠"&_xlpm.v_r,_xlpm.v_h&" "&_xlpm.v_d))) | O4: =_xlfn.LET(_xlpm.v_r,TRIM(INDEX(인턴계획표[#This Row],1,6)&""),_xlpm.v_t1,IFERROR(LEFT(_xlpm.v_r,FIND(" ",_xlpm.v_r)-1),""),_xlpm.v_t2,TRIM(RIGHT(SUBSTITUTE(_xlpm.v_r," ",REPT(" ",60)),60)),_xlpm.v_h,_xlfn.XLOOKUP(_xlpm.v_t1,병원약칭표[표기],병원약칭표[정식 병원],""),_xlpm.v_d,_xlfn.XLOOKUP(_xlpm.v_t2,과약칭표[약칭],과약칭표[정식 명칭],""),IF(_xlpm.v_r="","",IF(OR(_xlpm.v_t1="",_xlpm.v_h="",_xlpm.v_d=""),"⚠"&_xlpm.v_r,_xlpm.v_h&" "&_xlpm.v_d))) | P4: =_xlfn.LET(_xlpm.v_r,TRIM(INDEX(인턴계획표[#This Row],1,7)&""),_xlpm.v_t1,IFERROR(LEFT(_xlpm.v_r,FIND(" ",_xlpm.v_r)-1),""),_xlpm.v_t2,TRIM(RIGHT(SUBSTITUTE(_xlpm.v_r," ",REPT(" ",60)),60)),_xlpm.v_h,_xlfn.XLOOKUP(_xlpm.v_t1,병원약칭표[표기],병원약칭표[정식 병원],""),_xlpm.v_d,_xlfn.XLOOKUP(_xlpm.v_t2,과약칭표[약칭],과약칭표[정식 명칭],""),IF(_xlpm.v_r="","",IF(OR(_xlpm.v_t1="",_xlpm.v_h="",_xlpm.v_d=""),"⚠"&_xlpm.v_r,_xlpm.v_h&" "&_xlpm.v_d))) | Q4: =_xlfn.LET(_xlpm.v_r,TRIM(INDEX(인턴계획표[#This Row],1,8)&""),_xlpm.v_t1,IFERROR(LEFT(_xlpm.v_r,FIND(" ",_xlpm.v_r)-1),""),_xlpm.v_t2,TRIM(RIGHT(SUBSTITUTE(_xlpm.v_r," ",REPT(" ",60)),60)),_xlpm.v_h,_xlfn.XLOOKUP(_xlpm.v_t1,병원약칭표[표기],병원약칭표[정식 병원],""),_xlpm.v_d,_xlfn.XLOOKUP(_xlpm.v_t2,과약칭표[약칭],과약칭표[정식 명칭],""),IF(_xlpm.v_r="","",IF(OR(_xlpm.v_t1="",_xlpm.v_h="",_xlpm.v_d=""),"⚠"&_xlpm.v_r,_xlpm.v_h&" "&_xlpm.v_d))) | R4: =_xlfn.LET(_xlpm.v_r,TRIM(INDEX(인턴계획표[#This Row],1,9)&""),_xlpm.v_t1,IFERROR(LEFT(_xlpm.v_r,FIND(" ",_xlpm.v_r)-1),""),_xlpm.v_t2,TRIM(RIGHT(SUBSTITUTE(_xlpm.v_r," ",REPT(" ",60)),60)),_xlpm.v_h,_xlfn.XLOOKUP(_xlpm.v_t1,병원약칭표[표기],병원약칭표[정식 병원],""),_xlpm.v_d,_xlfn.XLOOKUP(_xlpm.v_t2,과약칭표[약칭],과약칭표[정식 명칭],""),IF(_xlpm.v_r="","",IF(OR(_xlpm.v_t1="",_xlpm.v_h="",_xlpm.v_d=""),"⚠"&_xlpm.v_r,_xlpm.v_h&" "&_xlpm.v_d))) | S4: =_xlfn.LET(_xlpm.v_k,INDEX(인턴계획표[#This Row],1,10)&"",_xlpm.v_v,IFERROR(VALUE(_xlpm.v_k),""),_xlpm.v_m,IFERROR(ROUND((_xlpm.v_v-INT(_xlpm.v_v))*100,0),0),IF(_xlpm.v_k="","",IF(AND(ISNUMBER(_xlpm.v_v),_xlpm.v_m>=1,_xlpm.v_m<=12,IFERROR(INT(_xlpm.v_v),0)>=1900),DATE(INT(_xlpm.v_v),_xlpm.v_m,1),_xlpm.v_k))) | T4: =COUNTIF(인턴계획표[[#This Row],[정규화1]:[정규화6]],"⚠*")
B5: 3 | C5: 박ㅇㅇ | D5: 222224 | E5: 제주 외과 | F5: 서울 내과 | G5: 서울 응급 | H5: 구리 직피 | I5: 서울 정영 | J5: 제주 산부 | K5: 2026.03 | L5: =IF(TRIM(인턴계획표[[#This Row],[사번]]&"")="","","S|"&TRIM(인턴계획표[[#This Row],[사번]]&"")) | M5: =_xlfn.LET(_xlpm.v_r,TRIM(INDEX(인턴계획표[#This Row],1,4)&""),_xlpm.v_t1,IFERROR(LEFT(_xlpm.v_r,FIND(" ",_xlpm.v_r)-1),""),_xlpm.v_t2,TRIM(RIGHT(SUBSTITUTE(_xlpm.v_r," ",REPT(" ",60)),60)),_xlpm.v_h,_xlfn.XLOOKUP(_xlpm.v_t1,병원약칭표[표기],병원약칭표[정식 병원],""),_xlpm.v_d,_xlfn.XLOOKUP(_xlpm.v_t2,과약칭표[약칭],과약칭표[정식 명칭],""),IF(_xlpm.v_r="","",IF(OR(_xlpm.v_t1="",_xlpm.v_h="",_xlpm.v_d=""),"⚠"&_xlpm.v_r,_xlpm.v_h&" "&_xlpm.v_d))) | N5: =_xlfn.LET(_xlpm.v_r,TRIM(INDEX(인턴계획표[#This Row],1,5)&""),_xlpm.v_t1,IFERROR(LEFT(_xlpm.v_r,FIND(" ",_xlpm.v_r)-1),""),_xlpm.v_t2,TRIM(RIGHT(SUBSTITUTE(_xlpm.v_r," ",REPT(" ",60)),60)),_xlpm.v_h,_xlfn.XLOOKUP(_xlpm.v_t1,병원약칭표[표기],병원약칭표[정식 병원],""),_xlpm.v_d,_xlfn.XLOOKUP(_xlpm.v_t2,과약칭표[약칭],과약칭표[정식 명칭],""),IF(_xlpm.v_r="","",IF(OR(_xlpm.v_t1="",_xlpm.v_h="",_xlpm.v_d=""),"⚠"&_xlpm.v_r,_xlpm.v_h&" "&_xlpm.v_d))) | O5: =_xlfn.LET(_xlpm.v_r,TRIM(INDEX(인턴계획표[#This Row],1,6)&""),_xlpm.v_t1,IFERROR(LEFT(_xlpm.v_r,FIND(" ",_xlpm.v_r)-1),""),_xlpm.v_t2,TRIM(RIGHT(SUBSTITUTE(_xlpm.v_r," ",REPT(" ",60)),60)),_xlpm.v_h,_xlfn.XLOOKUP(_xlpm.v_t1,병원약칭표[표기],병원약칭표[정식 병원],""),_xlpm.v_d,_xlfn.XLOOKUP(_xlpm.v_t2,과약칭표[약칭],과약칭표[정식 명칭],""),IF(_xlpm.v_r="","",IF(OR(_xlpm.v_t1="",_xlpm.v_h="",_xlpm.v_d=""),"⚠"&_xlpm.v_r,_xlpm.v_h&" "&_xlpm.v_d))) | P5: =_xlfn.LET(_xlpm.v_r,TRIM(INDEX(인턴계획표[#This Row],1,7)&""),_xlpm.v_t1,IFERROR(LEFT(_xlpm.v_r,FIND(" ",_xlpm.v_r)-1),""),_xlpm.v_t2,TRIM(RIGHT(SUBSTITUTE(_xlpm.v_r," ",REPT(" ",60)),60)),_xlpm.v_h,_xlfn.XLOOKUP(_xlpm.v_t1,병원약칭표[표기],병원약칭표[정식 병원],""),_xlpm.v_d,_xlfn.XLOOKUP(_xlpm.v_t2,과약칭표[약칭],과약칭표[정식 명칭],""),IF(_xlpm.v_r="","",IF(OR(_xlpm.v_t1="",_xlpm.v_h="",_xlpm.v_d=""),"⚠"&_xlpm.v_r,_xlpm.v_h&" "&_xlpm.v_d))) | Q5: =_xlfn.LET(_xlpm.v_r,TRIM(INDEX(인턴계획표[#This Row],1,8)&""),_xlpm.v_t1,IFERROR(LEFT(_xlpm.v_r,FIND(" ",_xlpm.v_r)-1),""),_xlpm.v_t2,TRIM(RIGHT(SUBSTITUTE(_xlpm.v_r," ",REPT(" ",60)),60)),_xlpm.v_h,_xlfn.XLOOKUP(_xlpm.v_t1,병원약칭표[표기],병원약칭표[정식 병원],""),_xlpm.v_d,_xlfn.XLOOKUP(_xlpm.v_t2,과약칭표[약칭],과약칭표[정식 명칭],""),IF(_xlpm.v_r="","",IF(OR(_xlpm.v_t1="",_xlpm.v_h="",_xlpm.v_d=""),"⚠"&_xlpm.v_r,_xlpm.v_h&" "&_xlpm.v_d))) | R5: =_xlfn.LET(_xlpm.v_r,TRIM(INDEX(인턴계획표[#This Row],1,9)&""),_xlpm.v_t1,IFERROR(LEFT(_xlpm.v_r,FIND(" ",_xlpm.v_r)-1),""),_xlpm.v_t2,TRIM(RIGHT(SUBSTITUTE(_xlpm.v_r," ",REPT(" ",60)),60)),_xlpm.v_h,_xlfn.XLOOKUP(_xlpm.v_t1,병원약칭표[표기],병원약칭표[정식 병원],""),_xlpm.v_d,_xlfn.XLOOKUP(_xlpm.v_t2,과약칭표[약칭],과약칭표[정식 명칭],""),IF(_xlpm.v_r="","",IF(OR(_xlpm.v_t1="",_xlpm.v_h="",_xlpm.v_d=""),"⚠"&_xlpm.v_r,_xlpm.v_h&" "&_xlpm.v_d))) | S5: =_xlfn.LET(_xlpm.v_k,INDEX(인턴계획표[#This Row],1,10)&"",_xlpm.v_v,IFERROR(VALUE(_xlpm.v_k),""),_xlpm.v_m,IFERROR(ROUND((_xlpm.v_v-INT(_xlpm.v_v))*100,0),0),IF(_xlpm.v_k="","",IF(AND(ISNUMBER(_xlpm.v_v),_xlpm.v_m>=1,_xlpm.v_m<=12,IFERROR(INT(_xlpm.v_v),0)>=1900),DATE(INT(_xlpm.v_v),_xlpm.v_m,1),_xlpm.v_k))) | T5: =COUNTIF(인턴계획표[[#This Row],[정규화1]:[정규화6]],"⚠*")

Sheet 입력_구리근무자명단
A1: 전공의(모.자 파견) 근무자 명단
A2: 2026년도
A3: 소속 | B3: 년차 | C3: 2026년9월 근무예정자 | D3: 9월 근무자 | E3: 근무 시작일자 (시작일자 작성) | F3: 근무 종료일자 (종료일자 작성) | G3: 9월 휴가 스케줄 (휴가일 작성) | H3: 비고 | I3: 2026년10월 근무예정자 | J3: 10월 근무자 | K3: 근무 시작일자 (시작일자 작성) | L3: 근무 종료일자 (종료일자 작성) | M3: 10월 휴가 스케줄 (휴가일 작성) | N3: 비고 | O3: 2026년11월 근무예정자 | P3: 11월 근무자 | Q3: 근무 시작일자 (시작일자 작성) | R3: 근무 종료일자 (종료일자 작성) | S3: 11월 휴가 스케줄 (휴가일 작성) | T3: 비고 | U3: 2026년12월 근무예정자 | V3: 12월 근무자 | W3: 근무 시작일자 (시작일자 작성) | X3: 근무 종료일자 (종료일자 작성) | Y3: 12월 휴가 스케줄 (휴가일 작성) | Z3: 비고 | AA3: 2027년1월 근무예정자 | AB3: 1월 근무자 | AC3: 근무 시작일자 (시작일자 작성) | AD3: 근무 종료일자 (종료일자 작성) | AE3: 1월 휴가 스케줄 (휴가일 작성) | AF3: 비고 | AG3: 2027년2월 근무예정자 | AH3: 2월 근무자 | AI3: 근무 시작일자 (시작일자 작성) | AJ3: 근무 종료일자 (종료일자 작성) | AK3: 2월 휴가 스케줄 (휴가일 작성) | AL3: 비고 | AM3: 2027년3월 근무예정자 | AN3: 3월 근무자 | AO3: 근무 시작일자 (시작일자 작성) | AP3: 근무 종료일자 (종료일자 작성) | AQ3: 3월 휴가 스케줄 (휴가일 작성) | AR3: 비고 | AS3: 2027년4월 근무예정자 | AT3: 4월 근무자 | AU3: 근무 시작일자 (시작일자 작성) | AV3: 근무 종료일자 (종료일자 작성) | AW3: 4월 휴가 스케줄 (휴가일 작성) | AX3: 비고 | AY3: 2027년5월 근무예정자 | AZ3: 5월 근무자 | BA3: 근무 시작일자 (시작일자 작성) | BB3: 근무 종료일자 (종료일자 작성) | BC3: 5월 휴가 스케줄 (휴가일 작성) | BD3: 비고 | BE3: 2027년6월 근무예정자 | BF3: 6월 근무자 | BG3: 근무 시작일자 (시작일자 작성) | BH3: 근무 종료일자 (종료일자 작성) | BI3: 6월 휴가 스케줄 (휴가일 작성) | BJ3: 비고 | BK3: 2027년7월 근무예정자 | BL3: 7월 근무자 | BM3: 근무 시작일자 (시작일자 작성) | BN3: 근무 종료일자 (종료일자 작성) | BO3: 7월 휴가 스케줄 (휴가일 작성) | BP3: 비고 | BQ3: 2027년8월 근무예정자 | BR3: 8월 근무자 | BS3: 근무 시작일자 (시작일자 작성) | BT3: 근무 종료일자 (종료일자 작성) | BU3: 8월 휴가 스케줄 (휴가일 작성) | BV3: 비고
A4: 내과 | B4: 3 | C4: 박ㅇㅇ | I4: 박ㅇㅇ | J4: 박ㅇㅇ | K4: 2026.10.01 | L4: 2026.10.31
A5: 가정의학과 | B5: 1 | I5: 김ㅇㅇ | J5: 김ㅇㅇ | K5: 2026.10.21 | L5: 2026.10.31
A6: 마취통증의학과 | B6: 2 | C6: 정ㅇㅇ | H6: 구리독자 | I6: 정ㅇㅇ | J6: 정ㅇㅇ | K6: 2026.10.01 | L6: 2026.10.17 | N6: 구리독자
A7: 외과 | B7: 1 | C7: 홍ㅇㅇ | H7: 구리독자 | I7: 홍ㅇㅇ | J7: 홍ㅇㅇ | K7: 2026.10.01 | L7: 2026.10.31 | N7: 구리독자
A8: 수련교육부 | B8: 인턴 | I8: 김ㅇㅇ | J8: 김ㅇㅇ | K8: 2026.10.01 | L8: 2026.10.31

Sheet 입력_전공의명단
A1: 번호 | B1: 사번 | C1: 이름 | D1: 성별 | E1: 생년월일 | F1: 수련과목 | G1: 연차 | H1: 근무지 | I1: 수련개시일 | J1: 전공의등록번호 | K1: 의사면허번호 | L1: 재직여부 | M1: 입사장소 | N1: 현재 근무병원 | O1: 현재 진료과 | P1: 구리 근무 시작일(기준월) | Q1: 구리 근무 종료일(기준월) | R1: 구리독자 | S1: 서울 근무일(기준월) | T1: 구리 근무일(기준월) | U1: 급여지급병원(기준월) | V1: 급여 판정 근거 | W1: 점검 | X1: 비고 | Y1: 전월 근무병원 | Z1: 전월 급여지급병원 | AA1: 전월 근거 | AB1: 익월 근무병원 | AC1: 익월 급여지급병원 | AD1: 익월 근거 | AE1: 기본자료행 | AF1: 이름|과 | AG1: 인턴계획행 | AH1: 인턴 이번달 | AI1: 인턴 기준월 | AJ1: 인턴 전월 | AK1: 인턴 익월 | AL1: 직접행(기준월) | AM1: 직접행(전월) | AN1: 직접행(익월) | AO1: 소속병원 | AP1: 기준월 근무병원 | AQ1: 구리행 | AR1: 구리명단 근무일 | AS1: 구리 근무 중
A2: =ROW()-ROW(명단표[#Headers]) | B2: 2261212 | C2: =IF(명단표[[#This Row],[기본자료행]]="","",IF(INDEX(기본자료표[이름],명단표[[#This Row],[기본자료행]])="","",INDEX(기본자료표[이름],명단표[[#This Row],[기본자료행]]))) | D2: =IF(명단표[[#This Row],[기본자료행]]="","",IF(INDEX(기본자료표[성별],명단표[[#This Row],[기본자료행]])="","",INDEX(기본자료표[성별],명단표[[#This Row],[기본자료행]]))) | E2: =IF(명단표[[#This Row],[기본자료행]]="","",_xlfn.LET(_xlpm.v_x,INDEX(기본자료표[생년월일],명단표[[#This Row],[기본자료행]]),IF(_xlpm.v_x="","",IF(NOT(ISNUMBER(_xlpm.v_x)),_xlpm.v_x&"",IF(_xlpm.v_x<1000000,_xlpm.v_x,IF(AND(_xlpm.v_x>=10000101,INT(MOD(_xlpm.v_x,10000)/100)>=1,INT(MOD(_xlpm.v_x,10000)/100)<=12,MOD(_xlpm.v_x,100)>=1,MOD(_xlpm.v_x,100)<=31),DATE(INT(_xlpm.v_x/10000),INT(MOD(_xlpm.v_x,10000)/100),MOD(_xlpm.v_x,100)),_xlpm.v_x&"")))))) | F2: =IF(명단표[[#This Row],[기본자료행]]="","",IF(INDEX(기본자료표[수련과목],명단표[[#This Row],[기본자료행]])="","",INDEX(기본자료표[수련과목],명단표[[#This Row],[기본자료행]]))) | G2: =IF(명단표[[#This Row],[기본자료행]]="","",IF(INDEX(기본자료표[연차],명단표[[#This Row],[기본자료행]])="","",INDEX(기본자료표[연차],명단표[[#This Row],[기본자료행]]))) | H2: =IF(명단표[[#This Row],[기본자료행]]="","",IF(INDEX(기본자료표[근무지],명단표[[#This Row],[기본자료행]])="","",INDEX(기본자료표[근무지],명단표[[#This Row],[기본자료행]]))) | I2: =IF(명단표[[#This Row],[기본자료행]]="","",_xlfn.LET(_xlpm.v_x,INDEX(기본자료표[수련개시일],명단표[[#This Row],[기본자료행]]),IF(_xlpm.v_x="","",IF(NOT(ISNUMBER(_xlpm.v_x)),_xlpm.v_x&"",IF(_xlpm.v_x<1000000,_xlpm.v_x,IF(AND(_xlpm.v_x>=10000101,INT(MOD(_xlpm.v_x,10000)/100)>=1,INT(MOD(_xlpm.v_x,10000)/100)<=12,MOD(_xlpm.v_x,100)>=1,MOD(_xlpm.v_x,100)<=31),DATE(INT(_xlpm.v_x/10000),INT(MOD(_xlpm.v_x,10000)/100),MOD(_xlpm.v_x,100)),_xlpm.v_x&"")))))) | J2: =IF(명단표[[#This Row],[기본자료행]]="","",IF(INDEX(기본자료표[전공의등록번호],명단표[[#This Row],[기본자료행]])="","",INDEX(기본자료표[전공의등록번호],명단표[[#This Row],[기본자료행]]))) | K2: =IF(명단표[[#This Row],[기본자료행]]="","",IF(INDEX(기본자료표[의사면허번호],명단표[[#This Row],[기본자료행]])="","",INDEX(기본자료표[의사면허번호],명단표[[#This Row],[기본자료행]]))) | L2: =IF(명단표[[#This Row],[기본자료행]]="","",IF(INDEX(기본자료표[현재근무 여부],명단표[[#This Row],[기본자료행]])="","",INDEX(기본자료표[현재근무 여부],명단표[[#This Row],[기본자료행]]))) | M2: 서울병원 | N2: =IF(NOT(TRIM(명단표[[#This Row],[사번]]&"")<>""),"",IF(AND(명단표[[#This Row],[인턴 이번달]]<>"",LEFT(명단표[[#This Row],[인턴 이번달]],1)<>"⚠"),LEFT(명단표[[#This Row],[인턴 이번달]],FIND(" ",명단표[[#This Row],[인턴 이번달]])-1),IF(명단표[[#This Row],[구리 근무 중]]="Y","구리병원",IF(명단표[[#This Row],[근무지]]="","",_xlfn.XLOOKUP(TRIM(명단표[[#This Row],[근무지]]&""),병원약칭표[표기],병원약칭표[정식 병원],명단표[[#This Row],[근무지]]&""))))) | O2: =IF(NOT(TRIM(명단표[[#This Row],[사번]]&"")<>""),"",IF(AND(명단표[[#This Row],[인턴 이번달]]<>"",LEFT(명단표[[#This Row],[인턴 이번달]],1)<>"⚠"),MID(명단표[[#This Row],[인턴 이번달]],FIND(" ",명단표[[#This Row],[인턴 이번달]])+1,60),IF(명단표[[#This Row],[수련과목]]="","",IF(명단표[[#This Row],[수련과목]]="인턴","수련교육부(인턴)",명단표[[#This Row],[수련과목]])))) | P2: =IF(명단표[[#This Row],[구리행]]="","",INDEX(구리_시작,명단표[[#This Row],[구리행]])) | Q2: =IF(명단표[[#This Row],[구리행]]="","",INDEX(구리_종료,명단표[[#This Row],[구리행]])) | R2: =IF(명단표[[#This Row],[구리행]]="","",INDEX(구리_독자,명단표[[#This Row],[구리행]])) | S2: =IF(NOT(TRIM(명단표[[#This Row],[사번]]&"")<>""),"",IF(명단표[[#This Row],[구리행]]<>"",MAX(0,DAY(EOMONTH(급여기준월,0))-N(명단표[[#This Row],[구리명단 근무일]])),IF(명단표[[#This Row],[기준월 근무병원]]="서울병원",DAY(EOMONTH(급여기준월,0)),0))) | T2: =IF(NOT(TRIM(명단표[[#This Row],[사번]]&"")<>""),"",IF(명단표[[#This Row],[구리행]]<>"",N(명단표[[#This Row],[구리명단 근무일]]),IF(명단표[[#This Row],[기준월 근무병원]]="구리병원",DAY(EOMONTH(급여기준월,0)),0))) | U2: =IF(NOT(TRIM(명단표[[#This Row],[사번]]&"")<>""),"",IF(명단표[[#This Row],[직접행(기준월)]]<>"",INDEX(월별근무지표[적용 급여병원],명단표[[#This Row],[직접행(기준월)]]),IF(명단표[[#This Row],[기준월 근무병원]]="","",IF(명단표[[#This Row],[구리행]]="",명단표[[#This Row],[기준월 근무병원]],IF(AND(명단표[[#This Row],[서울 근무일(기준월)]]>=판정기준일,명단표[[#This Row],[구리 근무일(기준월)]]<판정기준일),"서울병원",IF(AND(명단표[[#This Row],[구리 근무일(기준월)]]>=판정기준일,명단표[[#This Row],[서울 근무일(기준월)]]<판정기준일),"구리병원","⚠15일 판정불가(서울 "&명단표[[#This Row],[서울 근무일(기준월)]]&"일/구리 "&명단표[[#This Row],[구리 근무일(기준월)]]&"일)")))))) | V2: =IF(OR(NOT(TRIM(명단표[[#This Row],[사번]]&"")<>""),명단표[[#This Row],[급여지급병원(기준월)]]=""),"",IF(명단표[[#This Row],[직접행(기준월)]]<>"","직접 입력(입력_월별근무지)"&IF(INDEX(월별근무지표[비고],명단표[[#This Row],[직접행(기준월)]])&""="",""," — "&INDEX(월별근무지표[비고],명단표[[#This Row],[직접행(기준월)]])),IF(명단표[[#This Row],[구리행]]<>"","서울 "&명단표[[#This Row],[서울 근무일(기준월)]]&"일 / 구리 "&명단표[[#This Row],[구리 근무일(기준월)]]&"일 (구리 근무자명단) → 15일 이상 근무 병원 지급",IF(AND(명단표[[#This Row],[인턴 기준월]]<>"",LEFT(명단표[[#This Row],[인턴 기준월]],1)<>"⚠"),"인턴 근무계획 → 그 달 근무병원 지급","구리 근무자명단에 없음 → 소속병원 지급")))) | W2: =IF(NOT(TRIM(명단표[[#This Row],[사번]]&"")<>""),"",IF(명단표[[#This Row],[기본자료행]]="","기본자료에 없는 사번",IF(COUNTIF(명단표[사번],명단표[[#This Row],[사번]])>1,"중복 사번",IF(명단표[[#This Row],[소속병원]]="","소속(입사장소) 입력",IF(LEFT(명단표[[#This Row],[급여지급병원(기준월)]],1)="⚠","서울·구리 15일 판정 불가(양쪽 모두 이상/미만)",IF(IF(명단표[[#This Row],[인턴계획행]]="",0,N(INDEX(인턴계획표[입력오류],명단표[[#This Row],[인턴계획행]])))>0,"인턴계획 입력오류 확인",IF(AND(명단표[[#This Row],[구리행]]="",COUNTIF(구리_이름,명단표[[#This Row],[이름]])>0),"구리 근무자명단 연결 확인(동명이인·과 불일치)","정상"))))))) | X2: 예시 데이터 | Y2: =IF(NOT(TRIM(명단표[[#This Row],[사번]]&"")<>""),"",IF(명단표[[#This Row],[직접행(전월)]]<>"",INDEX(월별근무지표[근무병원],명단표[[#This Row],[직접행(전월)]]),IF(AND(명단표[[#This Row],[인턴 전월]]<>"",LEFT(명단표[[#This Row],[인턴 전월]],1)<>"⚠"),LEFT(명단표[[#This Row],[인턴 전월]],FIND(" ",명단표[[#This Row],[인턴 전월]])-1),명단표[[#This Row],[소속병원]]))) | Z2: =IF(NOT(TRIM(명단표[[#This Row],[사번]]&"")<>""),"",IF(명단표[[#This Row],[직접행(전월)]]<>"",INDEX(월별근무지표[적용 급여병원],명단표[[#This Row],[직접행(전월)]]),명단표[[#This Row],[전월 근무병원]])) | AA2: =IF(NOT(TRIM(명단표[[#This Row],[사번]]&"")<>""),"",IF(명단표[[#This Row],[직접행(전월)]]<>"","직접 입력(입력_월별근무지)"&IF(INDEX(월별근무지표[비고],명단표[[#This Row],[직접행(전월)]])&""="",""," — "&INDEX(월별근무지표[비고],명단표[[#This Row],[직접행(전월)]])),IF(AND(명단표[[#This Row],[인턴 전월]]<>"",LEFT(명단표[[#This Row],[인턴 전월]],1)<>"⚠"),"인턴 근무계획 → 그 달 근무병원",IF(명단표[[#This Row],[구리행]]<>"","⚠자동(소속병원) — 급여 기준월에 구리 근무, 직접 입력 확인","자동(소속병원) — 구리 근무자명단 미반영")))) | AB2: =IF(NOT(TRIM(명단표[[#This Row],[사번]]&"")<>""),"",IF(명단표[[#This Row],[직접행(익월)]]<>"",INDEX(월별근무지표[근무병원],명단표[[#This Row],[직접행(익월)]]),IF(AND(명단표[[#This Row],[인턴 익월]]<>"",LEFT(명단표[[#This Row],[인턴 익월]],1)<>"⚠"),LEFT(명단표[[#This Row],[인턴 익월]],FIND(" ",명단표[[#This Row],[인턴 익월]])-1),명단표[[#This Row],[소속병원]]))) | AC2: =IF(NOT(TRIM(명단표[[#This Row],[사번]]&"")<>""),"",IF(명단표[[#This Row],[직접행(익월)]]<>"",INDEX(월별근무지표[적용 급여병원],명단표[[#This Row],[직접행(익월)]]),명단표[[#This Row],[익월 근무병원]])) | AD2: =IF(NOT(TRIM(명단표[[#This Row],[사번]]&"")<>""),"",IF(명단표[[#This Row],[직접행(익월)]]<>"","직접 입력(입력_월별근무지)"&IF(INDEX(월별근무지표[비고],명단표[[#This Row],[직접행(익월)]])&""="",""," — "&INDEX(월별근무지표[비고],명단표[[#This Row],[직접행(익월)]])),IF(AND(명단표[[#This Row],[인턴 익월]]<>"",LEFT(명단표[[#This Row],[인턴 익월]],1)<>"⚠"),"인턴 근무계획 → 그 달 근무병원",IF(명단표[[#This Row],[구리행]]<>"","⚠자동(소속병원) — 급여 기준월에 구리 근무, 직접 입력 확인","자동(소속병원) — 구리 근무자명단 미반영")))) | AE2: =IF(NOT(TRIM(명단표[[#This Row],[사번]]&"")<>""),"",IFERROR(_xlfn.XMATCH("S|"&TRIM(명단표[[#This Row],[사번]]&""),기본자료표[사번키]),"")) | AF2: =IF(명단표[[#This Row],[이름]]="","",명단표[[#This Row],[이름]]&"|"&명단표[[#This Row],[수련과목]]) | AG2: =IF(NOT(TRIM(명단표[[#This Row],[사번]]&"")<>""),"",IFERROR(_xlfn.XMATCH("S|"&TRIM(명단표[[#This Row],[사번]]&""),인턴계획표[사번키]),"")) | AH2: =IF(OR(명단표[[#This Row],[인턴계획행]]="",인턴위치_이번=""),"",INDEX(인턴계획표[[정규화1]:[정규화6]],명단표[[#This Row],[인턴계획행]],인턴위치_이번)&"") | AI2: =IF(OR(명단표[[#This Row],[인턴계획행]]="",인턴위치_기준월=""),"",INDEX(인턴계획표[[정규화1]:[정규화6]],명단표[[#This Row],[인턴계획행]],인턴위치_기준월)&"") | AJ2: =IF(OR(명단표[[#This Row],[인턴계획행]]="",인턴위치_전월=""),"",INDEX(인턴계획표[[정규화1]:[정규화6]],명단표[[#This Row],[인턴계획행]],인턴위치_전월)&"") | AK2: =IF(OR(명단표[[#This Row],[인턴계획행]]="",인턴위치_익월=""),"",INDEX(인턴계획표[[정규화1]:[정규화6]],명단표[[#This Row],[인턴계획행]],인턴위치_익월)&"") | AL2: =IF(NOT(TRIM(명단표[[#This Row],[사번]]&"")<>""),"",IFERROR(_xlfn.XMATCH("S|"&TRIM(명단표[[#This Row],[사번]]&"")&"|"&기준월키,월별근무지표[키]),"")) | AM2: =IF(NOT(TRIM(명단표[[#This Row],[사번]]&"")<>""),"",IFERROR(_xlfn.XMATCH("S|"&TRIM(명단표[[#This Row],[사번]]&"")&"|"&전월키,월별근무지표[키]),"")) | AN2: =IF(NOT(TRIM(명단표[[#This Row],[사번]]&"")<>""),"",IFERROR(_xlfn.XMATCH("S|"&TRIM(명단표[[#This Row],[사번]]&"")&"|"&익월키,월별근무지표[키]),"")) | AO2: =IF(NOT(TRIM(명단표[[#This Row],[사번]]&"")<>""),"",IF(명단표[[#This Row],[입사장소]]<>"",명단표[[#This Row],[입사장소]],IF(명단표[[#This Row],[구리독자]]="구리독자","구리병원",IF(명단표[[#This Row],[근무지]]="","",_xlfn.XLOOKUP(TRIM(명단표[[#This Row],[근무지]]&""),병원약칭표[표기],병원약칭표[정식 병원],명단표[[#This Row],[근무지]]&""))))) | AP2: =IF(NOT(TRIM(명단표[[#This Row],[사번]]&"")<>""),"",IF(명단표[[#This Row],[직접행(기준월)]]<>"",INDEX(월별근무지표[근무병원],명단표[[#This Row],[직접행(기준월)]]),IF(AND(명단표[[#This Row],[인턴 기준월]]<>"",LEFT(명단표[[#This Row],[인턴 기준월]],1)<>"⚠"),LEFT(명단표[[#This Row],[인턴 기준월]],FIND(" ",명단표[[#This Row],[인턴 기준월]])-1),명단표[[#This Row],[소속병원]]))) | AQ2: =IF(명단표[[#This Row],[이름]]="","",_xlfn.LET(_xlpm.v_a,_xlfn.XMATCH(명단표[[#This Row],[이름|과]],구리_키),IF(ISNUMBER(_xlpm.v_a),_xlpm.v_a,IF(AND(COUNTIF(구리_이름,명단표[[#This Row],[이름]])=1,COUNTIF(명단표[이름],명단표[[#This Row],[이름]])=1),_xlfn.XMATCH(명단표[[#This Row],[이름]],구리_이름),"")))) | AR2: =IF(명단표[[#This Row],[구리행]]="","",INDEX(구리_근무일,명단표[[#This Row],[구리행]])) | AS2: =IF(명단표[[#This Row],[구리행]]="","",_xlfn.LET(_xlpm.v_s,IFERROR(DATEVALUE(명단표[[#This Row],[구리 근무 시작일(기준월)]]),""),_xlpm.v_e,IFERROR(DATEVALUE(명단표[[#This Row],[구리 근무 종료일(기준월)]]),""),IF(AND(ISNUMBER(_xlpm.v_s),ISNUMBER(_xlpm.v_e)),IF(AND(TODAY()>=_xlpm.v_s,TODAY()<=_xlpm.v_e),"Y",""),"")))
A3: =ROW()-ROW(명단표[#Headers]) | B3: 2261213 | C3: =IF(명단표[[#This Row],[기본자료행]]="","",IF(INDEX(기본자료표[이름],명단표[[#This Row],[기본자료행]])="","",INDEX(기본자료표[이름],명단표[[#This Row],[기본자료행]]))) | D3: =IF(명단표[[#This Row],[기본자료행]]="","",IF(INDEX(기본자료표[성별],명단표[[#This Row],[기본자료행]])="","",INDEX(기본자료표[성별],명단표[[#This Row],[기본자료행]]))) | E3: =IF(명단표[[#This Row],[기본자료행]]="","",_xlfn.LET(_xlpm.v_x,INDEX(기본자료표[생년월일],명단표[[#This Row],[기본자료행]]),IF(_xlpm.v_x="","",IF(NOT(ISNUMBER(_xlpm.v_x)),_xlpm.v_x&"",IF(_xlpm.v_x<1000000,_xlpm.v_x,IF(AND(_xlpm.v_x>=10000101,INT(MOD(_xlpm.v_x,10000)/100)>=1,INT(MOD(_xlpm.v_x,10000)/100)<=12,MOD(_xlpm.v_x,100)>=1,MOD(_xlpm.v_x,100)<=31),DATE(INT(_xlpm.v_x/10000),INT(MOD(_xlpm.v_x,10000)/100),MOD(_xlpm.v_x,100)),_xlpm.v_x&"")))))) | F3: =IF(명단표[[#This Row],[기본자료행]]="","",IF(INDEX(기본자료표[수련과목],명단표[[#This Row],[기본자료행]])="","",INDEX(기본자료표[수련과목],명단표[[#This Row],[기본자료행]]))) | G3: =IF(명단표[[#This Row],[기본자료행]]="","",IF(INDEX(기본자료표[연차],명단표[[#This Row],[기본자료행]])="","",INDEX(기본자료표[연차],명단표[[#This Row],[기본자료행]]))) | H3: =IF(명단표[[#This Row],[기본자료행]]="","",IF(INDEX(기본자료표[근무지],명단표[[#This Row],[기본자료행]])="","",INDEX(기본자료표[근무지],명단표[[#This Row],[기본자료행]]))) | I3: =IF(명단표[[#This Row],[기본자료행]]="","",_xlfn.LET(_xlpm.v_x,INDEX(기본자료표[수련개시일],명단표[[#This Row],[기본자료행]]),IF(_xlpm.v_x="","",IF(NOT(ISNUMBER(_xlpm.v_x)),_xlpm.v_x&"",IF(_xlpm.v_x<1000000,_xlpm.v_x,IF(AND(_xlpm.v_x>=10000101,INT(MOD(_xlpm.v_x,10000)/100)>=1,INT(MOD(_xlpm.v_x,10000)/100)<=12,MOD(_xlpm.v_x,100)>=1,MOD(_xlpm.v_x,100)<=31),DATE(INT(_xlpm.v_x/10000),INT(MOD(_xlpm.v_x,10000)/100),MOD(_xlpm.v_x,100)),_xlpm.v_x&"")))))) | J3: =IF(명단표[[#This Row],[기본자료행]]="","",IF(INDEX(기본자료표[전공의등록번호],명단표[[#This Row],[기본자료행]])="","",INDEX(기본자료표[전공의등록번호],명단표[[#This Row],[기본자료행]]))) | K3: =IF(명단표[[#This Row],[기본자료행]]="","",IF(INDEX(기본자료표[의사면허번호],명단표[[#This Row],[기본자료행]])="","",INDEX(기본자료표[의사면허번호],명단표[[#This Row],[기본자료행]]))) | L3: =IF(명단표[[#This Row],[기본자료행]]="","",IF(INDEX(기본자료표[현재근무 여부],명단표[[#This Row],[기본자료행]])="","",INDEX(기본자료표[현재근무 여부],명단표[[#This Row],[기본자료행]]))) | M3: 서울병원 | N3: =IF(NOT(TRIM(명단표[[#This Row],[사번]]&"")<>""),"",IF(AND(명단표[[#This Row],[인턴 이번달]]<>"",LEFT(명단표[[#This Row],[인턴 이번달]],1)<>"⚠"),LEFT(명단표[[#This Row],[인턴 이번달]],FIND(" ",명단표[[#This Row],[인턴 이번달]])-1),IF(명단표[[#This Row],[구리 근무 중]]="Y","구리병원",IF(명단표[[#This Row],[근무지]]="","",_xlfn.XLOOKUP(TRIM(명단표[[#This Row],[근무지]]&""),병원약칭표[표기],병원약칭표[정식 병원],명단표[[#This Row],[근무지]]&""))))) | O3: =IF(NOT(TRIM(명단표[[#This Row],[사번]]&"")<>""),"",IF(AND(명단표[[#This Row],[인턴 이번달]]<>"",LEFT(명단표[[#This Row],[인턴 이번달]],1)<>"⚠"),MID(명단표[[#This Row],[인턴 이번달]],FIND(" ",명단표[[#This Row],[인턴 이번달]])+1,60),IF(명단표[[#This Row],[수련과목]]="","",IF(명단표[[#This Row],[수련과목]]="인턴","수련교육부(인턴)",명단표[[#This Row],[수련과목]])))) | P3: =IF(명단표[[#This Row],[구리행]]="","",INDEX(구리_시작,명단표[[#This Row],[구리행]])) | Q3: =IF(명단표[[#This Row],[구리행]]="","",INDEX(구리_종료,명단표[[#This Row],[구리행]])) | R3: =IF(명단표[[#This Row],[구리행]]="","",INDEX(구리_독자,명단표[[#This Row],[구리행]])) | S3: =IF(NOT(TRIM(명단표[[#This Row],[사번]]&"")<>""),"",IF(명단표[[#This Row],[구리행]]<>"",MAX(0,DAY(EOMONTH(급여기준월,0))-N(명단표[[#This Row],[구리명단 근무일]])),IF(명단표[[#This Row],[기준월 근무병원]]="서울병원",DAY(EOMONTH(급여기준월,0)),0))) | T3: =IF(NOT(TRIM(명단표[[#This Row],[사번]]&"")<>""),"",IF(명단표[[#This Row],[구리행]]<>"",N(명단표[[#This Row],[구리명단 근무일]]),IF(명단표[[#This Row],[기준월 근무병원]]="구리병원",DAY(EOMONTH(급여기준월,0)),0))) | U3: =IF(NOT(TRIM(명단표[[#This Row],[사번]]&"")<>""),"",IF(명단표[[#This Row],[직접행(기준월)]]<>"",INDEX(월별근무지표[적용 급여병원],명단표[[#This Row],[직접행(기준월)]]),IF(명단표[[#This Row],[기준월 근무병원]]="","",IF(명단표[[#This Row],[구리행]]="",명단표[[#This Row],[기준월 근무병원]],IF(AND(명단표[[#This Row],[서울 근무일(기준월)]]>=판정기준일,명단표[[#This Row],[구리 근무일(기준월)]]<판정기준일),"서울병원",IF(AND(명단표[[#This Row],[구리 근무일(기준월)]]>=판정기준일,명단표[[#This Row],[서울 근무일(기준월)]]<판정기준일),"구리병원","⚠15일 판정불가(서울 "&명단표[[#This Row],[서울 근무일(기준월)]]&"일/구리 "&명단표[[#This Row],[구리 근무일(기준월)]]&"일)")))))) | V3: =IF(OR(NOT(TRIM(명단표[[#This Row],[사번]]&"")<>""),명단표[[#This Row],[급여지급병원(기준월)]]=""),"",IF(명단표[[#This Row],[직접행(기준월)]]<>"","직접 입력(입력_월별근무지)"&IF(INDEX(월별근무지표[비고],명단표[[#This Row],[직접행(기준월)]])&""="",""," — "&INDEX(월별근무지표[비고],명단표[[#This Row],[직접행(기준월)]])),IF(명단표[[#This Row],[구리행]]<>"","서울 "&명단표[[#This Row],[서울 근무일(기준월)]]&"일 / 구리 "&명단표[[#This Row],[구리 근무일(기준월)]]&"일 (구리 근무자명단) → 15일 이상 근무 병원 지급",IF(AND(명단표[[#This Row],[인턴 기준월]]<>"",LEFT(명단표[[#This Row],[인턴 기준월]],1)<>"⚠"),"인턴 근무계획 → 그 달 근무병원 지급","구리 근무자명단에 없음 → 소속병원 지급")))) | W3: =IF(NOT(TRIM(명단표[[#This Row],[사번]]&"")<>""),"",IF(명단표[[#This Row],[기본자료행]]="","기본자료에 없는 사번",IF(COUNTIF(명단표[사번],명단표[[#This Row],[사번]])>1,"중복 사번",IF(명단표[[#This Row],[소속병원]]="","소속(입사장소) 입력",IF(LEFT(명단표[[#This Row],[급여지급병원(기준월)]],1)="⚠","서울·구리 15일 판정 불가(양쪽 모두 이상/미만)",IF(IF(명단표[[#This Row],[인턴계획행]]="",0,N(INDEX(인턴계획표[입력오류],명단표[[#This Row],[인턴계획행]])))>0,"인턴계획 입력오류 확인",IF(AND(명단표[[#This Row],[구리행]]="",COUNTIF(구리_이름,명단표[[#This Row],[이름]])>0),"구리 근무자명단 연결 확인(동명이인·과 불일치)","정상"))))))) | X3: 예시 데이터 | Y3: =IF(NOT(TRIM(명단표[[#This Row],[사번]]&"")<>""),"",IF(명단표[[#This Row],[직접행(전월)]]<>"",INDEX(월별근무지표[근무병원],명단표[[#This Row],[직접행(전월)]]),IF(AND(명단표[[#This Row],[인턴 전월]]<>"",LEFT(명단표[[#This Row],[인턴 전월]],1)<>"⚠"),LEFT(명단표[[#This Row],[인턴 전월]],FIND(" ",명단표[[#This Row],[인턴 전월]])-1),명단표[[#This Row],[소속병원]]))) | Z3: =IF(NOT(TRIM(명단표[[#This Row],[사번]]&"")<>""),"",IF(명단표[[#This Row],[직접행(전월)]]<>"",INDEX(월별근무지표[적용 급여병원],명단표[[#This Row],[직접행(전월)]]),명단표[[#This Row],[전월 근무병원]])) | AA3: =IF(NOT(TRIM(명단표[[#This Row],[사번]]&"")<>""),"",IF(명단표[[#This Row],[직접행(전월)]]<>"","직접 입력(입력_월별근무지)"&IF(INDEX(월별근무지표[비고],명단표[[#This Row],[직접행(전월)]])&""="",""," — "&INDEX(월별근무지표[비고],명단표[[#This Row],[직접행(전월)]])),IF(AND(명단표[[#This Row],[인턴 전월]]<>"",LEFT(명단표[[#This Row],[인턴 전월]],1)<>"⚠"),"인턴 근무계획 → 그 달 근무병원",IF(명단표[[#This Row],[구리행]]<>"","⚠자동(소속병원) — 급여 기준월에 구리 근무, 직접 입력 확인","자동(소속병원) — 구리 근무자명단 미반영")))) | AB3: =IF(NOT(TRIM(명단표[[#This Row],[사번]]&"")<>""),"",IF(명단표[[#This Row],[직접행(익월)]]<>"",INDEX(월별근무지표[근무병원],명단표[[#This Row],[직접행(익월)]]),IF(AND(명단표[[#This Row],[인턴 익월]]<>"",LEFT(명단표[[#This Row],[인턴 익월]],1)<>"⚠"),LEFT(명단표[[#This Row],[인턴 익월]],FIND(" ",명단표[[#This Row],[인턴 익월]])-1),명단표[[#This Row],[소속병원]]))) | AC3: =IF(NOT(TRIM(명단표[[#This Row],[사번]]&"")<>""),"",IF(명단표[[#This Row],[직접행(익월)]]<>"",INDEX(월별근무지표[적용 급여병원],명단표[[#This Row],[직접행(익월)]]),명단표[[#This Row],[익월 근무병원]])) | AD3: =IF(NOT(TRIM(명단표[[#This Row],[사번]]&"")<>""),"",IF(명단표[[#This Row],[직접행(익월)]]<>"","직접 입력(입력_월별근무지)"&IF(INDEX(월별근무지표[비고],명단표[[#This Row],[직접행(익월)]])&""="",""," — "&INDEX(월별근무지표[비고],명단표[[#This Row],[직접행(익월)]])),IF(AND(명단표[[#This Row],[인턴 익월]]<>"",LEFT(명단표[[#This Row],[인턴 익월]],1)<>"⚠"),"인턴 근무계획 → 그 달 근무병원",IF(명단표[[#This Row],[구리행]]<>"","⚠자동(소속병원) — 급여 기준월에 구리 근무, 직접 입력 확인","자동(소속병원) — 구리 근무자명단 미반영")))) | AE3: =IF(NOT(TRIM(명단표[[#This Row],[사번]]&"")<>""),"",IFERROR(_xlfn.XMATCH("S|"&TRIM(명단표[[#This Row],[사번]]&""),기본자료표[사번키]),"")) | AF3: =IF(명단표[[#This Row],[이름]]="","",명단표[[#This Row],[이름]]&"|"&명단표[[#This Row],[수련과목]]) | AG3: =IF(NOT(TRIM(명단표[[#This Row],[사번]]&"")<>""),"",IFERROR(_xlfn.XMATCH("S|"&TRIM(명단표[[#This Row],[사번]]&""),인턴계획표[사번키]),"")) | AH3: =IF(OR(명단표[[#This Row],[인턴계획행]]="",인턴위치_이번=""),"",INDEX(인턴계획표[[정규화1]:[정규화6]],명단표[[#This Row],[인턴계획행]],인턴위치_이번)&"") | AI3: =IF(OR(명단표[[#This Row],[인턴계획행]]="",인턴위치_기준월=""),"",INDEX(인턴계획표[[정규화1]:[정규화6]],명단표[[#This Row],[인턴계획행]],인턴위치_기준월)&"") | AJ3: =IF(OR(명단표[[#This Row],[인턴계획행]]="",인턴위치_전월=""),"",INDEX(인턴계획표[[정규화1]:[정규화6]],명단표[[#This Row],[인턴계획행]],인턴위치_전월)&"") | AK3: =IF(OR(명단표[[#This Row],[인턴계획행]]="",인턴위치_익월=""),"",INDEX(인턴계획표[[정규화1]:[정규화6]],명단표[[#This Row],[인턴계획행]],인턴위치_익월)&"") | AL3: =IF(NOT(TRIM(명단표[[#This Row],[사번]]&"")<>""),"",IFERROR(_xlfn.XMATCH("S|"&TRIM(명단표[[#This Row],[사번]]&"")&"|"&기준월키,월별근무지표[키]),"")) | AM3: =IF(NOT(TRIM(명단표[[#This Row],[사번]]&"")<>""),"",IFERROR(_xlfn.XMATCH("S|"&TRIM(명단표[[#This Row],[사번]]&"")&"|"&전월키,월별근무지표[키]),"")) | AN3: =IF(NOT(TRIM(명단표[[#This Row],[사번]]&"")<>""),"",IFERROR(_xlfn.XMATCH("S|"&TRIM(명단표[[#This Row],[사번]]&"")&"|"&익월키,월별근무지표[키]),"")) | AO3: =IF(NOT(TRIM(명단표[[#This Row],[사번]]&"")<>""),"",IF(명단표[[#This Row],[입사장소]]<>"",명단표[[#This Row],[입사장소]],IF(명단표[[#This Row],[구리독자]]="구리독자","구리병원",IF(명단표[[#This Row],[근무지]]="","",_xlfn.XLOOKUP(TRIM(명단표[[#This Row],[근무지]]&""),병원약칭표[표기],병원약칭표[정식 병원],명단표[[#This Row],[근무지]]&""))))) | AP3: =IF(NOT(TRIM(명단표[[#This Row],[사번]]&"")<>""),"",IF(명단표[[#This Row],[직접행(기준월)]]<>"",INDEX(월별근무지표[근무병원],명단표[[#This Row],[직접행(기준월)]]),IF(AND(명단표[[#This Row],[인턴 기준월]]<>"",LEFT(명단표[[#This Row],[인턴 기준월]],1)<>"⚠"),LEFT(명단표[[#This Row],[인턴 기준월]],FIND(" ",명단표[[#This Row],[인턴 기준월]])-1),명단표[[#This Row],[소속병원]]))) | AQ3: =IF(명단표[[#This Row],[이름]]="","",_xlfn.LET(_xlpm.v_a,_xlfn.XMATCH(명단표[[#This Row],[이름|과]],구리_키),IF(ISNUMBER(_xlpm.v_a),_xlpm.v_a,IF(AND(COUNTIF(구리_이름,명단표[[#This Row],[이름]])=1,COUNTIF(명단표[이름],명단표[[#This Row],[이름]])=1),_xlfn.XMATCH(명단표[[#This Row],[이름]],구리_이름),"")))) | AR3: =IF(명단표[[#This Row],[구리행]]="","",INDEX(구리_근무일,명단표[[#This Row],[구리행]])) | AS3: =IF(명단표[[#This Row],[구리행]]="","",_xlfn.LET(_xlpm.v_s,IFERROR(DATEVALUE(명단표[[#This Row],[구리 근무 시작일(기준월)]]),""),_xlpm.v_e,IFERROR(DATEVALUE(명단표[[#This Row],[구리 근무 종료일(기준월)]]),""),IF(AND(ISNUMBER(_xlpm.v_s),ISNUMBER(_xlpm.v_e)),IF(AND(TODAY()>=_xlpm.v_s,TODAY()<=_xlpm.v_e),"Y",""),"")))
A4: =ROW()-ROW(명단표[#Headers]) | B4: 2261214 | C4: =IF(명단표[[#This Row],[기본자료행]]="","",IF(INDEX(기본자료표[이름],명단표[[#This Row],[기본자료행]])="","",INDEX(기본자료표[이름],명단표[[#This Row],[기본자료행]]))) | D4: =IF(명단표[[#This Row],[기본자료행]]="","",IF(INDEX(기본자료표[성별],명단표[[#This Row],[기본자료행]])="","",INDEX(기본자료표[성별],명단표[[#This Row],[기본자료행]]))) | E4: =IF(명단표[[#This Row],[기본자료행]]="","",_xlfn.LET(_xlpm.v_x,INDEX(기본자료표[생년월일],명단표[[#This Row],[기본자료행]]),IF(_xlpm.v_x="","",IF(NOT(ISNUMBER(_xlpm.v_x)),_xlpm.v_x&"",IF(_xlpm.v_x<1000000,_xlpm.v_x,IF(AND(_xlpm.v_x>=10000101,INT(MOD(_xlpm.v_x,10000)/100)>=1,INT(MOD(_xlpm.v_x,10000)/100)<=12,MOD(_xlpm.v_x,100)>=1,MOD(_xlpm.v_x,100)<=31),DATE(INT(_xlpm.v_x/10000),INT(MOD(_xlpm.v_x,10000)/100),MOD(_xlpm.v_x,100)),_xlpm.v_x&"")))))) | F4: =IF(명단표[[#This Row],[기본자료행]]="","",IF(INDEX(기본자료표[수련과목],명단표[[#This Row],[기본자료행]])="","",INDEX(기본자료표[수련과목],명단표[[#This Row],[기본자료행]]))) | G4: =IF(명단표[[#This Row],[기본자료행]]="","",IF(INDEX(기본자료표[연차],명단표[[#This Row],[기본자료행]])="","",INDEX(기본자료표[연차],명단표[[#This Row],[기본자료행]]))) | H4: =IF(명단표[[#This Row],[기본자료행]]="","",IF(INDEX(기본자료표[근무지],명단표[[#This Row],[기본자료행]])="","",INDEX(기본자료표[근무지],명단표[[#This Row],[기본자료행]]))) | I4: =IF(명단표[[#This Row],[기본자료행]]="","",_xlfn.LET(_xlpm.v_x,INDEX(기본자료표[수련개시일],명단표[[#This Row],[기본자료행]]),IF(_xlpm.v_x="","",IF(NOT(ISNUMBER(_xlpm.v_x)),_xlpm.v_x&"",IF(_xlpm.v_x<1000000,_xlpm.v_x,IF(AND(_xlpm.v_x>=10000101,INT(MOD(_xlpm.v_x,10000)/100)>=1,INT(MOD(_xlpm.v_x,10000)/100)<=12,MOD(_xlpm.v_x,100)>=1,MOD(_xlpm.v_x,100)<=31),DATE(INT(_xlpm.v_x/10000),INT(MOD(_xlpm.v_x,10000)/100),MOD(_xlpm.v_x,100)),_xlpm.v_x&"")))))) | J4: =IF(명단표[[#This Row],[기본자료행]]="","",IF(INDEX(기본자료표[전공의등록번호],명단표[[#This Row],[기본자료행]])="","",INDEX(기본자료표[전공의등록번호],명단표[[#This Row],[기본자료행]]))) | K4: =IF(명단표[[#This Row],[기본자료행]]="","",IF(INDEX(기본자료표[의사면허번호],명단표[[#This Row],[기본자료행]])="","",INDEX(기본자료표[의사면허번호],명단표[[#This Row],[기본자료행]]))) | L4: =IF(명단표[[#This Row],[기본자료행]]="","",IF(INDEX(기본자료표[현재근무 여부],명단표[[#This Row],[기본자료행]])="","",INDEX(기본자료표[현재근무 여부],명단표[[#This Row],[기본자료행]]))) | M4: 서울병원 | N4: =IF(NOT(TRIM(명단표[[#This Row],[사번]]&"")<>""),"",IF(AND(명단표[[#This Row],[인턴 이번달]]<>"",LEFT(명단표[[#This Row],[인턴 이번달]],1)<>"⚠"),LEFT(명단표[[#This Row],[인턴 이번달]],FIND(" ",명단표[[#This Row],[인턴 이번달]])-1),IF(명단표[[#This Row],[구리 근무 중]]="Y","구리병원",IF(명단표[[#This Row],[근무지]]="","",_xlfn.XLOOKUP(TRIM(명단표[[#This Row],[근무지]]&""),병원약칭표[표기],병원약칭표[정식 병원],명단표[[#This Row],[근무지]]&""))))) | O4: =IF(NOT(TRIM(명단표[[#This Row],[사번]]&"")<>""),"",IF(AND(명단표[[#This Row],[인턴 이번달]]<>"",LEFT(명단표[[#This Row],[인턴 이번달]],1)<>"⚠"),MID(명단표[[#This Row],[인턴 이번달]],FIND(" ",명단표[[#This Row],[인턴 이번달]])+1,60),IF(명단표[[#This Row],[수련과목]]="","",IF(명단표[[#This Row],[수련과목]]="인턴","수련교육부(인턴)",명단표[[#This Row],[수련과목]])))) | P4: =IF(명단표[[#This Row],[구리행]]="","",INDEX(구리_시작,명단표[[#This Row],[구리행]])) | Q4: =IF(명단표[[#This Row],[구리행]]="","",INDEX(구리_종료,명단표[[#This Row],[구리행]])) | R4: =IF(명단표[[#This Row],[구리행]]="","",INDEX(구리_독자,명단표[[#This Row],[구리행]])) | S4: =IF(NOT(TRIM(명단표[[#This Row],[사번]]&"")<>""),"",IF(명단표[[#This Row],[구리행]]<>"",MAX(0,DAY(EOMONTH(급여기준월,0))-N(명단표[[#This Row],[구리명단 근무일]])),IF(명단표[[#This Row],[기준월 근무병원]]="서울병원",DAY(EOMONTH(급여기준월,0)),0))) | T4: =IF(NOT(TRIM(명단표[[#This Row],[사번]]&"")<>""),"",IF(명단표[[#This Row],[구리행]]<>"",N(명단표[[#This Row],[구리명단 근무일]]),IF(명단표[[#This Row],[기준월 근무병원]]="구리병원",DAY(EOMONTH(급여기준월,0)),0))) | U4: =IF(NOT(TRIM(명단표[[#This Row],[사번]]&"")<>""),"",IF(명단표[[#This Row],[직접행(기준월)]]<>"",INDEX(월별근무지표[적용 급여병원],명단표[[#This Row],[직접행(기준월)]]),IF(명단표[[#This Row],[기준월 근무병원]]="","",IF(명단표[[#This Row],[구리행]]="",명단표[[#This Row],[기준월 근무병원]],IF(AND(명단표[[#This Row],[서울 근무일(기준월)]]>=판정기준일,명단표[[#This Row],[구리 근무일(기준월)]]<판정기준일),"서울병원",IF(AND(명단표[[#This Row],[구리 근무일(기준월)]]>=판정기준일,명단표[[#This Row],[서울 근무일(기준월)]]<판정기준일),"구리병원","⚠15일 판정불가(서울 "&명단표[[#This Row],[서울 근무일(기준월)]]&"일/구리 "&명단표[[#This Row],[구리 근무일(기준월)]]&"일)")))))) | V4: =IF(OR(NOT(TRIM(명단표[[#This Row],[사번]]&"")<>""),명단표[[#This Row],[급여지급병원(기준월)]]=""),"",IF(명단표[[#This Row],[직접행(기준월)]]<>"","직접 입력(입력_월별근무지)"&IF(INDEX(월별근무지표[비고],명단표[[#This Row],[직접행(기준월)]])&""="",""," — "&INDEX(월별근무지표[비고],명단표[[#This Row],[직접행(기준월)]])),IF(명단표[[#This Row],[구리행]]<>"","서울 "&명단표[[#This Row],[서울 근무일(기준월)]]&"일 / 구리 "&명단표[[#This Row],[구리 근무일(기준월)]]&"일 (구리 근무자명단) → 15일 이상 근무 병원 지급",IF(AND(명단표[[#This Row],[인턴 기준월]]<>"",LEFT(명단표[[#This Row],[인턴 기준월]],1)<>"⚠"),"인턴 근무계획 → 그 달 근무병원 지급","구리 근무자명단에 없음 → 소속병원 지급")))) | W4: =IF(NOT(TRIM(명단표[[#This Row],[사번]]&"")<>""),"",IF(명단표[[#This Row],[기본자료행]]="","기본자료에 없는 사번",IF(COUNTIF(명단표[사번],명단표[[#This Row],[사번]])>1,"중복 사번",IF(명단표[[#This Row],[소속병원]]="","소속(입사장소) 입력",IF(LEFT(명단표[[#This Row],[급여지급병원(기준월)]],1)="⚠","서울·구리 15일 판정 불가(양쪽 모두 이상/미만)",IF(IF(명단표[[#This Row],[인턴계획행]]="",0,N(INDEX(인턴계획표[입력오류],명단표[[#This Row],[인턴계획행]])))>0,"인턴계획 입력오류 확인",IF(AND(명단표[[#This Row],[구리행]]="",COUNTIF(구리_이름,명단표[[#This Row],[이름]])>0),"구리 근무자명단 연결 확인(동명이인·과 불일치)","정상"))))))) | X4: 예시 데이터 | Y4: =IF(NOT(TRIM(명단표[[#This Row],[사번]]&"")<>""),"",IF(명단표[[#This Row],[직접행(전월)]]<>"",INDEX(월별근무지표[근무병원],명단표[[#This Row],[직접행(전월)]]),IF(AND(명단표[[#This Row],[인턴 전월]]<>"",LEFT(명단표[[#This Row],[인턴 전월]],1)<>"⚠"),LEFT(명단표[[#This Row],[인턴 전월]],FIND(" ",명단표[[#This Row],[인턴 전월]])-1),명단표[[#This Row],[소속병원]]))) | Z4: =IF(NOT(TRIM(명단표[[#This Row],[사번]]&"")<>""),"",IF(명단표[[#This Row],[직접행(전월)]]<>"",INDEX(월별근무지표[적용 급여병원],명단표[[#This Row],[직접행(전월)]]),명단표[[#This Row],[전월 근무병원]])) | AA4: =IF(NOT(TRIM(명단표[[#This Row],[사번]]&"")<>""),"",IF(명단표[[#This Row],[직접행(전월)]]<>"","직접 입력(입력_월별근무지)"&IF(INDEX(월별근무지표[비고],명단표[[#This Row],[직접행(전월)]])&""="",""," — "&INDEX(월별근무지표[비고],명단표[[#This Row],[직접행(전월)]])),IF(AND(명단표[[#This Row],[인턴 전월]]<>"",LEFT(명단표[[#This Row],[인턴 전월]],1)<>"⚠"),"인턴 근무계획 → 그 달 근무병원",IF(명단표[[#This Row],[구리행]]<>"","⚠자동(소속병원) — 급여 기준월에 구리 근무, 직접 입력 확인","자동(소속병원) — 구리 근무자명단 미반영")))) | AB4: =IF(NOT(TRIM(명단표[[#This Row],[사번]]&"")<>""),"",IF(명단표[[#This Row],[직접행(익월)]]<>"",INDEX(월별근무지표[근무병원],명단표[[#This Row],[직접행(익월)]]),IF(AND(명단표[[#This Row],[인턴 익월]]<>"",LEFT(명단표[[#This Row],[인턴 익월]],1)<>"⚠"),LEFT(명단표[[#This Row],[인턴 익월]],FIND(" ",명단표[[#This Row],[인턴 익월]])-1),명단표[[#This Row],[소속병원]]))) | AC4: =IF(NOT(TRIM(명단표[[#This Row],[사번]]&"")<>""),"",IF(명단표[[#This Row],[직접행(익월)]]<>"",INDEX(월별근무지표[적용 급여병원],명단표[[#This Row],[직접행(익월)]]),명단표[[#This Row],[익월 근무병원]])) | AD4: =IF(NOT(TRIM(명단표[[#This Row],[사번]]&"")<>""),"",IF(명단표[[#This Row],[직접행(익월)]]<>"","직접 입력(입력_월별근무지)"&IF(INDEX(월별근무지표[비고],명단표[[#This Row],[직접행(익월)]])&""="",""," — "&INDEX(월별근무지표[비고],명단표[[#This Row],[직접행(익월)]])),IF(AND(명단표[[#This Row],[인턴 익월]]<>"",LEFT(명단표[[#This Row],[인턴 익월]],1)<>"⚠"),"인턴 근무계획 → 그 달 근무병원",IF(명단표[[#This Row],[구리행]]<>"","⚠자동(소속병원) — 급여 기준월에 구리 근무, 직접 입력 확인","자동(소속병원) — 구리 근무자명단 미반영")))) | AE4: =IF(NOT(TRIM(명단표[[#This Row],[사번]]&"")<>""),"",IFERROR(_xlfn.XMATCH("S|"&TRIM(명단표[[#This Row],[사번]]&""),기본자료표[사번키]),"")) | AF4: =IF(명단표[[#This Row],[이름]]="","",명단표[[#This Row],[이름]]&"|"&명단표[[#This Row],[수련과목]]) | AG4: =IF(NOT(TRIM(명단표[[#This Row],[사번]]&"")<>""),"",IFERROR(_xlfn.XMATCH("S|"&TRIM(명단표[[#This Row],[사번]]&""),인턴계획표[사번키]),"")) | AH4: =IF(OR(명단표[[#This Row],[인턴계획행]]="",인턴위치_이번=""),"",INDEX(인턴계획표[[정규화1]:[정규화6]],명단표[[#This Row],[인턴계획행]],인턴위치_이번)&"") | AI4: =IF(OR(명단표[[#This Row],[인턴계획행]]="",인턴위치_기준월=""),"",INDEX(인턴계획표[[정규화1]:[정규화6]],명단표[[#This Row],[인턴계획행]],인턴위치_기준월)&"") | AJ4: =IF(OR(명단표[[#This Row],[인턴계획행]]="",인턴위치_전월=""),"",INDEX(인턴계획표[[정규화1]:[정규화6]],명단표[[#This Row],[인턴계획행]],인턴위치_전월)&"") | AK4: =IF(OR(명단표[[#This Row],[인턴계획행]]="",인턴위치_익월=""),"",INDEX(인턴계획표[[정규화1]:[정규화6]],명단표[[#This Row],[인턴계획행]],인턴위치_익월)&"") | AL4: =IF(NOT(TRIM(명단표[[#This Row],[사번]]&"")<>""),"",IFERROR(_xlfn.XMATCH("S|"&TRIM(명단표[[#This Row],[사번]]&"")&"|"&기준월키,월별근무지표[키]),"")) | AM4: =IF(NOT(TRIM(명단표[[#This Row],[사번]]&"")<>""),"",IFERROR(_xlfn.XMATCH("S|"&TRIM(명단표[[#This Row],[사번]]&"")&"|"&전월키,월별근무지표[키]),"")) | AN4: =IF(NOT(TRIM(명단표[[#This Row],[사번]]&"")<>""),"",IFERROR(_xlfn.XMATCH("S|"&TRIM(명단표[[#This Row],[사번]]&"")&"|"&익월키,월별근무지표[키]),"")) | AO4: =IF(NOT(TRIM(명단표[[#This Row],[사번]]&"")<>""),"",IF(명단표[[#This Row],[입사장소]]<>"",명단표[[#This Row],[입사장소]],IF(명단표[[#This Row],[구리독자]]="구리독자","구리병원",IF(명단표[[#This Row],[근무지]]="","",_xlfn.XLOOKUP(TRIM(명단표[[#This Row],[근무지]]&""),병원약칭표[표기],병원약칭표[정식 병원],명단표[[#This Row],[근무지]]&""))))) | AP4: =IF(NOT(TRIM(명단표[[#This Row],[사번]]&"")<>""),"",IF(명단표[[#This Row],[직접행(기준월)]]<>"",INDEX(월별근무지표[근무병원],명단표[[#This Row],[직접행(기준월)]]),IF(AND(명단표[[#This Row],[인턴 기준월]]<>"",LEFT(명단표[[#This Row],[인턴 기준월]],1)<>"⚠"),LEFT(명단표[[#This Row],[인턴 기준월]],FIND(" ",명단표[[#This Row],[인턴 기준월]])-1),명단표[[#This Row],[소속병원]]))) | AQ4: =IF(명단표[[#This Row],[이름]]="","",_xlfn.LET(_xlpm.v_a,_xlfn.XMATCH(명단표[[#This Row],[이름|과]],구리_키),IF(ISNUMBER(_xlpm.v_a),_xlpm.v_a,IF(AND(COUNTIF(구리_이름,명단표[[#This Row],[이름]])=1,COUNTIF(명단표[이름],명단표[[#This Row],[이름]])=1),_xlfn.XMATCH(명단표[[#This Row],[이름]],구리_이름),"")))) | AR4: =IF(명단표[[#This Row],[구리행]]="","",INDEX(구리_근무일,명단표[[#This Row],[구리행]])) | AS4: =IF(명단표[[#This Row],[구리행]]="","",_xlfn.LET(_xlpm.v_s,IFERROR(DATEVALUE(명단표[[#This Row],[구리 근무 시작일(기준월)]]),""),_xlpm.v_e,IFERROR(DATEVALUE(명단표[[#This Row],[구리 근무 종료일(기준월)]]),""),IF(AND(ISNUMBER(_xlpm.v_s),ISNUMBER(_xlpm.v_e)),IF(AND(TODAY()>=_xlpm.v_s,TODAY()<=_xlpm.v_e),"Y",""),"")))
A5: =ROW()-ROW(명단표[#Headers]) | B5: 2261215 | C5: =IF(명단표[[#This Row],[기본자료행]]="","",IF(INDEX(기본자료표[이름],명단표[[#This Row],[기본자료행]])="","",INDEX(기본자료표[이름],명단표[[#This Row],[기본자료행]]))) | D5: =IF(명단표[[#This Row],[기본자료행]]="","",IF(INDEX(기본자료표[성별],명단표[[#This Row],[기본자료행]])="","",INDEX(기본자료표[성별],명단표[[#This Row],[기본자료행]]))) | E5: =IF(명단표[[#This Row],[기본자료행]]="","",_xlfn.LET(_xlpm.v_x,INDEX(기본자료표[생년월일],명단표[[#This Row],[기본자료행]]),IF(_xlpm.v_x="","",IF(NOT(ISNUMBER(_xlpm.v_x)),_xlpm.v_x&"",IF(_xlpm.v_x<1000000,_xlpm.v_x,IF(AND(_xlpm.v_x>=10000101,INT(MOD(_xlpm.v_x,10000)/100)>=1,INT(MOD(_xlpm.v_x,10000)/100)<=12,MOD(_xlpm.v_x,100)>=1,MOD(_xlpm.v_x,100)<=31),DATE(INT(_xlpm.v_x/10000),INT(MOD(_xlpm.v_x,10000)/100),MOD(_xlpm.v_x,100)),_xlpm.v_x&"")))))) | F5: =IF(명단표[[#This Row],[기본자료행]]="","",IF(INDEX(기본자료표[수련과목],명단표[[#This Row],[기본자료행]])="","",INDEX(기본자료표[수련과목],명단표[[#This Row],[기본자료행]]))) | G5: =IF(명단표[[#This Row],[기본자료행]]="","",IF(INDEX(기본자료표[연차],명단표[[#This Row],[기본자료행]])="","",INDEX(기본자료표[연차],명단표[[#This Row],[기본자료행]]))) | H5: =IF(명단표[[#This Row],[기본자료행]]="","",IF(INDEX(기본자료표[근무지],명단표[[#This Row],[기본자료행]])="","",INDEX(기본자료표[근무지],명단표[[#This Row],[기본자료행]]))) | I5: =IF(명단표[[#This Row],[기본자료행]]="","",_xlfn.LET(_xlpm.v_x,INDEX(기본자료표[수련개시일],명단표[[#This Row],[기본자료행]]),IF(_xlpm.v_x="","",IF(NOT(ISNUMBER(_xlpm.v_x)),_xlpm.v_x&"",IF(_xlpm.v_x<1000000,_xlpm.v_x,IF(AND(_xlpm.v_x>=10000101,INT(MOD(_xlpm.v_x,10000)/100)>=1,INT(MOD(_xlpm.v_x,10000)/100)<=12,MOD(_xlpm.v_x,100)>=1,MOD(_xlpm.v_x,100)<=31),DATE(INT(_xlpm.v_x/10000),INT(MOD(_xlpm.v_x,10000)/100),MOD(_xlpm.v_x,100)),_xlpm.v_x&"")))))) | J5: =IF(명단표[[#This Row],[기본자료행]]="","",IF(INDEX(기본자료표[전공의등록번호],명단표[[#This Row],[기본자료행]])="","",INDEX(기본자료표[전공의등록번호],명단표[[#This Row],[기본자료행]]))) | K5: =IF(명단표[[#This Row],[기본자료행]]="","",IF(INDEX(기본자료표[의사면허번호],명단표[[#This Row],[기본자료행]])="","",INDEX(기본자료표[의사면허번호],명단표[[#This Row],[기본자료행]]))) | L5: =IF(명단표[[#This Row],[기본자료행]]="","",IF(INDEX(기본자료표[현재근무 여부],명단표[[#This Row],[기본자료행]])="","",INDEX(기본자료표[현재근무 여부],명단표[[#This Row],[기본자료행]]))) | M5: 서울병원 | N5: =IF(NOT(TRIM(명단표[[#This Row],[사번]]&"")<>""),"",IF(AND(명단표[[#This Row],[인턴 이번달]]<>"",LEFT(명단표[[#This Row],[인턴 이번달]],1)<>"⚠"),LEFT(명단표[[#This Row],[인턴 이번달]],FIND(" ",명단표[[#This Row],[인턴 이번달]])-1),IF(명단표[[#This Row],[구리 근무 중]]="Y","구리병원",IF(명단표[[#This Row],[근무지]]="","",_xlfn.XLOOKUP(TRIM(명단표[[#This Row],[근무지]]&""),병원약칭표[표기],병원약칭표[정식 병원],명단표[[#This Row],[근무지]]&""))))) | O5: =IF(NOT(TRIM(명단표[[#This Row],[사번]]&"")<>""),"",IF(AND(명단표[[#This Row],[인턴 이번달]]<>"",LEFT(명단표[[#This Row],[인턴 이번달]],1)<>"⚠"),MID(명단표[[#This Row],[인턴 이번달]],FIND(" ",명단표[[#This Row],[인턴 이번달]])+1,60),IF(명단표[[#This Row],[수련과목]]="","",IF(명단표[[#This Row],[수련과목]]="인턴","수련교육부(인턴)",명단표[[#This Row],[수련과목]])))) | P5: =IF(명단표[[#This Row],[구리행]]="","",INDEX(구리_시작,명단표[[#This Row],[구리행]])) | Q5: =IF(명단표[[#This Row],[구리행]]="","",INDEX(구리_종료,명단표[[#This Row],[구리행]])) | R5: =IF(명단표[[#This Row],[구리행]]="","",INDEX(구리_독자,명단표[[#This Row],[구리행]])) | S5: =IF(NOT(TRIM(명단표[[#This Row],[사번]]&"")<>""),"",IF(명단표[[#This Row],[구리행]]<>"",MAX(0,DAY(EOMONTH(급여기준월,0))-N(명단표[[#This Row],[구리명단 근무일]])),IF(명단표[[#This Row],[기준월 근무병원]]="서울병원",DAY(EOMONTH(급여기준월,0)),0))) | T5: =IF(NOT(TRIM(명단표[[#This Row],[사번]]&"")<>""),"",IF(명단표[[#This Row],[구리행]]<>"",N(명단표[[#This Row],[구리명단 근무일]]),IF(명단표[[#This Row],[기준월 근무병원]]="구리병원",DAY(EOMONTH(급여기준월,0)),0))) | U5: =IF(NOT(TRIM(명단표[[#This Row],[사번]]&"")<>""),"",IF(명단표[[#This Row],[직접행(기준월)]]<>"",INDEX(월별근무지표[적용 급여병원],명단표[[#This Row],[직접행(기준월)]]),IF(명단표[[#This Row],[기준월 근무병원]]="","",IF(명단표[[#This Row],[구리행]]="",명단표[[#This Row],[기준월 근무병원]],IF(AND(명단표[[#This Row],[서울 근무일(기준월)]]>=판정기준일,명단표[[#This Row],[구리 근무일(기준월)]]<판정기준일),"서울병원",IF(AND(명단표[[#This Row],[구리 근무일(기준월)]]>=판정기준일,명단표[[#This Row],[서울 근무일(기준월)]]<판정기준일),"구리병원","⚠15일 판정불가(서울 "&명단표[[#This Row],[서울 근무일(기준월)]]&"일/구리 "&명단표[[#This Row],[구리 근무일(기준월)]]&"일)")))))) | V5: =IF(OR(NOT(TRIM(명단표[[#This Row],[사번]]&"")<>""),명단표[[#This Row],[급여지급병원(기준월)]]=""),"",IF(명단표[[#This Row],[직접행(기준월)]]<>"","직접 입력(입력_월별근무지)"&IF(INDEX(월별근무지표[비고],명단표[[#This Row],[직접행(기준월)]])&""="",""," — "&INDEX(월별근무지표[비고],명단표[[#This Row],[직접행(기준월)]])),IF(명단표[[#This Row],[구리행]]<>"","서울 "&명단표[[#This Row],[서울 근무일(기준월)]]&"일 / 구리 "&명단표[[#This Row],[구리 근무일(기준월)]]&"일 (구리 근무자명단) → 15일 이상 근무 병원 지급",IF(AND(명단표[[#This Row],[인턴 기준월]]<>"",LEFT(명단표[[#This Row],[인턴 기준월]],1)<>"⚠"),"인턴 근무계획 → 그 달 근무병원 지급","구리 근무자명단에 없음 → 소속병원 지급")))) | W5: =IF(NOT(TRIM(명단표[[#This Row],[사번]]&"")<>""),"",IF(명단표[[#This Row],[기본자료행]]="","기본자료에 없는 사번",IF(COUNTIF(명단표[사번],명단표[[#This Row],[사번]])>1,"중복 사번",IF(명단표[[#This Row],[소속병원]]="","소속(입사장소) 입력",IF(LEFT(명단표[[#This Row],[급여지급병원(기준월)]],1)="⚠","서울·구리 15일 판정 불가(양쪽 모두 이상/미만)",IF(IF(명단표[[#This Row],[인턴계획행]]="",0,N(INDEX(인턴계획표[입력오류],명단표[[#This Row],[인턴계획행]])))>0,"인턴계획 입력오류 확인",IF(AND(명단표[[#This Row],[구리행]]="",COUNTIF(구리_이름,명단표[[#This Row],[이름]])>0),"구리 근무자명단 연결 확인(동명이인·과 불일치)","정상"))))))) | X5: 예시 데이터 | Y5: =IF(NOT(TRIM(명단표[[#This Row],[사번]]&"")<>""),"",IF(명단표[[#This Row],[직접행(전월)]]<>"",INDEX(월별근무지표[근무병원],명단표[[#This Row],[직접행(전월)]]),IF(AND(명단표[[#This Row],[인턴 전월]]<>"",LEFT(명단표[[#This Row],[인턴 전월]],1)<>"⚠"),LEFT(명단표[[#This Row],[인턴 전월]],FIND(" ",명단표[[#This Row],[인턴 전월]])-1),명단표[[#This Row],[소속병원]]))) | Z5: =IF(NOT(TRIM(명단표[[#This Row],[사번]]&"")<>""),"",IF(명단표[[#This Row],[직접행(전월)]]<>"",INDEX(월별근무지표[적용 급여병원],명단표[[#This Row],[직접행(전월)]]),명단표[[#This Row],[전월 근무병원]])) | AA5: =IF(NOT(TRIM(명단표[[#This Row],[사번]]&"")<>""),"",IF(명단표[[#This Row],[직접행(전월)]]<>"","직접 입력(입력_월별근무지)"&IF(INDEX(월별근무지표[비고],명단표[[#This Row],[직접행(전월)]])&""="",""," — "&INDEX(월별근무지표[비고],명단표[[#This Row],[직접행(전월)]])),IF(AND(명단표[[#This Row],[인턴 전월]]<>"",LEFT(명단표[[#This Row],[인턴 전월]],1)<>"⚠"),"인턴 근무계획 → 그 달 근무병원",IF(명단표[[#This Row],[구리행]]<>"","⚠자동(소속병원) — 급여 기준월에 구리 근무, 직접 입력 확인","자동(소속병원) — 구리 근무자명단 미반영")))) | AB5: =IF(NOT(TRIM(명단표[[#This Row],[사번]]&"")<>""),"",IF(명단표[[#This Row],[직접행(익월)]]<>"",INDEX(월별근무지표[근무병원],명단표[[#This Row],[직접행(익월)]]),IF(AND(명단표[[#This Row],[인턴 익월]]<>"",LEFT(명단표[[#This Row],[인턴 익월]],1)<>"⚠"),LEFT(명단표[[#This Row],[인턴 익월]],FIND(" ",명단표[[#This Row],[인턴 익월]])-1),명단표[[#This Row],[소속병원]]))) | AC5: =IF(NOT(TRIM(명단표[[#This Row],[사번]]&"")<>""),"",IF(명단표[[#This Row],[직접행(익월)]]<>"",INDEX(월별근무지표[적용 급여병원],명단표[[#This Row],[직접행(익월)]]),명단표[[#This Row],[익월 근무병원]])) | AD5: =IF(NOT(TRIM(명단표[[#This Row],[사번]]&"")<>""),"",IF(명단표[[#This Row],[직접행(익월)]]<>"","직접 입력(입력_월별근무지)"&IF(INDEX(월별근무지표[비고],명단표[[#This Row],[직접행(익월)]])&""="",""," — "&INDEX(월별근무지표[비고],명단표[[#This Row],[직접행(익월)]])),IF(AND(명단표[[#This Row],[인턴 익월]]<>"",LEFT(명단표[[#This Row],[인턴 익월]],1)<>"⚠"),"인턴 근무계획 → 그 달 근무병원",IF(명단표[[#This Row],[구리행]]<>"","⚠자동(소속병원) — 급여 기준월에 구리 근무, 직접 입력 확인","자동(소속병원) — 구리 근무자명단 미반영")))) | AE5: =IF(NOT(TRIM(명단표[[#This Row],[사번]]&"")<>""),"",IFERROR(_xlfn.XMATCH("S|"&TRIM(명단표[[#This Row],[사번]]&""),기본자료표[사번키]),"")) | AF5: =IF(명단표[[#This Row],[이름]]="","",명단표[[#This Row],[이름]]&"|"&명단표[[#This Row],[수련과목]]) | AG5: =IF(NOT(TRIM(명단표[[#This Row],[사번]]&"")<>""),"",IFERROR(_xlfn.XMATCH("S|"&TRIM(명단표[[#This Row],[사번]]&""),인턴계획표[사번키]),"")) | AH5: =IF(OR(명단표[[#This Row],[인턴계획행]]="",인턴위치_이번=""),"",INDEX(인턴계획표[[정규화1]:[정규화6]],명단표[[#This Row],[인턴계획행]],인턴위치_이번)&"") | AI5: =IF(OR(명단표[[#This Row],[인턴계획행]]="",인턴위치_기준월=""),"",INDEX(인턴계획표[[정규화1]:[정규화6]],명단표[[#This Row],[인턴계획행]],인턴위치_기준월)&"") | AJ5: =IF(OR(명단표[[#This Row],[인턴계획행]]="",인턴위치_전월=""),"",INDEX(인턴계획표[[정규화1]:[정규화6]],명단표[[#This Row],[인턴계획행]],인턴위치_전월)&"") | AK5: =IF(OR(명단표[[#This Row],[인턴계획행]]="",인턴위치_익월=""),"",INDEX(인턴계획표[[정규화1]:[정규화6]],명단표[[#This Row],[인턴계획행]],인턴위치_익월)&"") | AL5: =IF(NOT(TRIM(명단표[[#This Row],[사번]]&"")<>""),"",IFERROR(_xlfn.XMATCH("S|"&TRIM(명단표[[#This Row],[사번]]&"")&"|"&기준월키,월별근무지표[키]),"")) | AM5: =IF(NOT(TRIM(명단표[[#This Row],[사번]]&"")<>""),"",IFERROR(_xlfn.XMATCH("S|"&TRIM(명단표[[#This Row],[사번]]&"")&"|"&전월키,월별근무지표[키]),"")) | AN5: =IF(NOT(TRIM(명단표[[#This Row],[사번]]&"")<>""),"",IFERROR(_xlfn.XMATCH("S|"&TRIM(명단표[[#This Row],[사번]]&"")&"|"&익월키,월별근무지표[키]),"")) | AO5: =IF(NOT(TRIM(명단표[[#This Row],[사번]]&"")<>""),"",IF(명단표[[#This Row],[입사장소]]<>"",명단표[[#This Row],[입사장소]],IF(명단표[[#This Row],[구리독자]]="구리독자","구리병원",IF(명단표[[#This Row],[근무지]]="","",_xlfn.XLOOKUP(TRIM(명단표[[#This Row],[근무지]]&""),병원약칭표[표기],병원약칭표[정식 병원],명단표[[#This Row],[근무지]]&""))))) | AP5: =IF(NOT(TRIM(명단표[[#This Row],[사번]]&"")<>""),"",IF(명단표[[#This Row],[직접행(기준월)]]<>"",INDEX(월별근무지표[근무병원],명단표[[#This Row],[직접행(기준월)]]),IF(AND(명단표[[#This Row],[인턴 기준월]]<>"",LEFT(명단표[[#This Row],[인턴 기준월]],1)<>"⚠"),LEFT(명단표[[#This Row],[인턴 기준월]],FIND(" ",명단표[[#This Row],[인턴 기준월]])-1),명단표[[#This Row],[소속병원]]))) | AQ5: =IF(명단표[[#This Row],[이름]]="","",_xlfn.LET(_xlpm.v_a,_xlfn.XMATCH(명단표[[#This Row],[이름|과]],구리_키),IF(ISNUMBER(_xlpm.v_a),_xlpm.v_a,IF(AND(COUNTIF(구리_이름,명단표[[#This Row],[이름]])=1,COUNTIF(명단표[이름],명단표[[#This Row],[이름]])=1),_xlfn.XMATCH(명단표[[#This Row],[이름]],구리_이름),"")))) | AR5: =IF(명단표[[#This Row],[구리행]]="","",INDEX(구리_근무일,명단표[[#This Row],[구리행]])) | AS5: =IF(명단표[[#This Row],[구리행]]="","",_xlfn.LET(_xlpm.v_s,IFERROR(DATEVALUE(명단표[[#This Row],[구리 근무 시작일(기준월)]]),""),_xlpm.v_e,IFERROR(DATEVALUE(명단표[[#This Row],[구리 근무 종료일(기준월)]]),""),IF(AND(ISNUMBER(_xlpm.v_s),ISNUMBER(_xlpm.v_e)),IF(AND(TODAY()>=_xlpm.v_s,TODAY()<=_xlpm.v_e),"Y",""),"")))
